package georgetsak.opcraft.common.block;

import georgetsak.opcraft.common.registry.OPBlocks;
import net.minecraft.block.Block;
import net.minecraft.init.Blocks;
import net.minecraft.util.math.BlockPos;
import net.minecraft.world.World;

public class GenerateDome {

    public void setBlock(World world, int x, int y, int z, Block blockToCreate) {

        Block blockAtCoords = world.getBlockState(new BlockPos(x, y, z)).getBlock();

        if (blockToCreate == OPBlocks.BlockLawDome && blockAtCoords == Blocks.AIR) {
            world.setBlockState(new BlockPos(x, y, z), blockToCreate.getDefaultState());
        }

        if(blockToCreate == Blocks.AIR && blockAtCoords == OPBlocks.BlockLawDome){
            world.setBlockState(new BlockPos(x, y, z), blockToCreate.getDefaultState());
        }

    }

    public boolean generate(World world, int i, int j, int k, boolean destroy) {
        Block block = OPBlocks.BlockLawDome;

        if(destroy){
            block = Blocks.AIR;
        }

        this.setBlock(world, i + 5, j + 13, k + 17, block);
        this.setBlock(world, i + 5, j + 13, k + 18, block);
        this.setBlock(world, i + 5, j + 13, k + 19, block);
        this.setBlock(world, i + 5, j + 13, k + 20, block);
        this.setBlock(world, i + 5, j + 13, k + 21, block);
        this.setBlock(world, i + 5, j + 14, k + 16, block);
        this.setBlock(world, i + 5, j + 14, k + 17, block);
        this.setBlock(world, i + 5, j + 14, k + 18, block);
        this.setBlock(world, i + 5, j + 14, k + 19, block);
        this.setBlock(world, i + 5, j + 14, k + 20, block);
        this.setBlock(world, i + 5, j + 14, k + 21, block);
        this.setBlock(world, i + 5, j + 14, k + 22, block);
        this.setBlock(world, i + 5, j + 15, k + 15, block);
        this.setBlock(world, i + 5, j + 15, k + 16, block);
        this.setBlock(world, i + 5, j + 15, k + 17, block);
        this.setBlock(world, i + 5, j + 15, k + 18, block);
        this.setBlock(world, i + 5, j + 15, k + 19, block);
        this.setBlock(world, i + 5, j + 15, k + 20, block);
        this.setBlock(world, i + 5, j + 15, k + 21, block);
        this.setBlock(world, i + 5, j + 15, k + 22, block);
        this.setBlock(world, i + 5, j + 15, k + 23, block);
        this.setBlock(world, i + 5, j + 16, k + 15, block);
        this.setBlock(world, i + 5, j + 16, k + 16, block);
        this.setBlock(world, i + 5, j + 16, k + 17, block);
        this.setBlock(world, i + 5, j + 16, k + 18, block);
        this.setBlock(world, i + 5, j + 16, k + 19, block);
        this.setBlock(world, i + 5, j + 16, k + 20, block);
        this.setBlock(world, i + 5, j + 16, k + 21, block);
        this.setBlock(world, i + 5, j + 16, k + 22, block);
        this.setBlock(world, i + 5, j + 16, k + 23, block);
        this.setBlock(world, i + 5, j + 17, k + 16, block);
        this.setBlock(world, i + 5, j + 17, k + 17, block);
        this.setBlock(world, i + 5, j + 17, k + 18, block);
        this.setBlock(world, i + 5, j + 17, k + 19, block);
        this.setBlock(world, i + 5, j + 17, k + 20, block);
        this.setBlock(world, i + 5, j + 17, k + 21, block);
        this.setBlock(world, i + 5, j + 17, k + 22, block);
        this.setBlock(world, i + 5, j + 18, k + 17, block);
        this.setBlock(world, i + 5, j + 18, k + 18, block);
        this.setBlock(world, i + 5, j + 18, k + 19, block);
        this.setBlock(world, i + 5, j + 18, k + 20, block);
        this.setBlock(world, i + 5, j + 18, k + 21, block);
        this.setBlock(world, i + 6, j + 10, k + 17, block);
        this.setBlock(world, i + 6, j + 10, k + 18, block);
        this.setBlock(world, i + 6, j + 10, k + 19, block);
        this.setBlock(world, i + 6, j + 10, k + 20, block);
        this.setBlock(world, i + 6, j + 10, k + 21, block);
        this.setBlock(world, i + 6, j + 11, k + 15, block);
        this.setBlock(world, i + 6, j + 11, k + 16, block);
        this.setBlock(world, i + 6, j + 11, k + 17, block);
        this.setBlock(world, i + 6, j + 11, k + 18, block);
        this.setBlock(world, i + 6, j + 11, k + 19, block);
        this.setBlock(world, i + 6, j + 11, k + 20, block);
        this.setBlock(world, i + 6, j + 11, k + 21, block);
        this.setBlock(world, i + 6, j + 11, k + 22, block);
        this.setBlock(world, i + 6, j + 11, k + 23, block);
        this.setBlock(world, i + 6, j + 12, k + 14, block);
        this.setBlock(world, i + 6, j + 12, k + 15, block);
        this.setBlock(world, i + 6, j + 12, k + 16, block);
        this.setBlock(world, i + 6, j + 12, k + 17, block);
        this.setBlock(world, i + 6, j + 12, k + 18, block);
        this.setBlock(world, i + 6, j + 12, k + 19, block);
        this.setBlock(world, i + 6, j + 12, k + 20, block);
        this.setBlock(world, i + 6, j + 12, k + 21, block);
        this.setBlock(world, i + 6, j + 12, k + 22, block);
        this.setBlock(world, i + 6, j + 12, k + 23, block);
        this.setBlock(world, i + 6, j + 12, k + 24, block);
        this.setBlock(world, i + 6, j + 13, k + 13, block);
        this.setBlock(world, i + 6, j + 13, k + 14, block);
        this.setBlock(world, i + 6, j + 13, k + 15, block);
        this.setBlock(world, i + 6, j + 13, k + 16, block);
        this.setBlock(world, i + 6, j + 13, k + 22, block);
        this.setBlock(world, i + 6, j + 13, k + 23, block);
        this.setBlock(world, i + 6, j + 13, k + 24, block);
        this.setBlock(world, i + 6, j + 13, k + 25, block);
        this.setBlock(world, i + 6, j + 14, k + 12, block);
        this.setBlock(world, i + 6, j + 14, k + 13, block);
        this.setBlock(world, i + 6, j + 14, k + 14, block);
        this.setBlock(world, i + 6, j + 14, k + 15, block);
        this.setBlock(world, i + 6, j + 14, k + 23, block);
        this.setBlock(world, i + 6, j + 14, k + 24, block);
        this.setBlock(world, i + 6, j + 14, k + 25, block);
        this.setBlock(world, i + 6, j + 14, k + 26, block);
        this.setBlock(world, i + 6, j + 15, k + 12, block);
        this.setBlock(world, i + 6, j + 15, k + 13, block);
        this.setBlock(world, i + 6, j + 15, k + 14, block);
        this.setBlock(world, i + 6, j + 15, k + 24, block);
        this.setBlock(world, i + 6, j + 15, k + 25, block);
        this.setBlock(world, i + 6, j + 15, k + 26, block);
        this.setBlock(world, i + 6, j + 16, k + 12, block);
        this.setBlock(world, i + 6, j + 16, k + 13, block);
        this.setBlock(world, i + 6, j + 16, k + 14, block);
        this.setBlock(world, i + 6, j + 16, k + 24, block);
        this.setBlock(world, i + 6, j + 16, k + 25, block);
        this.setBlock(world, i + 6, j + 16, k + 26, block);
        this.setBlock(world, i + 6, j + 17, k + 12, block);
        this.setBlock(world, i + 6, j + 17, k + 13, block);
        this.setBlock(world, i + 6, j + 17, k + 14, block);
        this.setBlock(world, i + 6, j + 17, k + 15, block);
        this.setBlock(world, i + 6, j + 17, k + 23, block);
        this.setBlock(world, i + 6, j + 17, k + 24, block);
        this.setBlock(world, i + 6, j + 17, k + 25, block);
        this.setBlock(world, i + 6, j + 17, k + 26, block);
        this.setBlock(world, i + 6, j + 18, k + 13, block);
        this.setBlock(world, i + 6, j + 18, k + 14, block);
        this.setBlock(world, i + 6, j + 18, k + 15, block);
        this.setBlock(world, i + 6, j + 18, k + 16, block);
        this.setBlock(world, i + 6, j + 18, k + 22, block);
        this.setBlock(world, i + 6, j + 18, k + 23, block);
        this.setBlock(world, i + 6, j + 18, k + 24, block);
        this.setBlock(world, i + 6, j + 18, k + 25, block);
        this.setBlock(world, i + 6, j + 19, k + 14, block);
        this.setBlock(world, i + 6, j + 19, k + 15, block);
        this.setBlock(world, i + 6, j + 19, k + 16, block);
        this.setBlock(world, i + 6, j + 19, k + 17, block);
        this.setBlock(world, i + 6, j + 19, k + 18, block);
        this.setBlock(world, i + 6, j + 19, k + 19, block);
        this.setBlock(world, i + 6, j + 19, k + 20, block);
        this.setBlock(world, i + 6, j + 19, k + 21, block);
        this.setBlock(world, i + 6, j + 19, k + 22, block);
        this.setBlock(world, i + 6, j + 19, k + 23, block);
        this.setBlock(world, i + 6, j + 19, k + 24, block);
        this.setBlock(world, i + 6, j + 20, k + 15, block);
        this.setBlock(world, i + 6, j + 20, k + 16, block);
        this.setBlock(world, i + 6, j + 20, k + 17, block);
        this.setBlock(world, i + 6, j + 20, k + 18, block);
        this.setBlock(world, i + 6, j + 20, k + 19, block);
        this.setBlock(world, i + 6, j + 20, k + 20, block);
        this.setBlock(world, i + 6, j + 20, k + 21, block);
        this.setBlock(world, i + 6, j + 20, k + 22, block);
        this.setBlock(world, i + 6, j + 20, k + 23, block);
        this.setBlock(world, i + 6, j + 21, k + 17, block);
        this.setBlock(world, i + 6, j + 21, k + 18, block);
        this.setBlock(world, i + 6, j + 21, k + 19, block);
        this.setBlock(world, i + 6, j + 21, k + 20, block);
        this.setBlock(world, i + 6, j + 21, k + 21, block);
        this.setBlock(world, i + 7, j + 8, k + 19, block);
        this.setBlock(world, i + 7, j + 9, k + 15, block);
        this.setBlock(world, i + 7, j + 9, k + 16, block);
        this.setBlock(world, i + 7, j + 9, k + 17, block);
        this.setBlock(world, i + 7, j + 9, k + 18, block);
        this.setBlock(world, i + 7, j + 9, k + 19, block);
        this.setBlock(world, i + 7, j + 9, k + 20, block);
        this.setBlock(world, i + 7, j + 9, k + 21, block);
        this.setBlock(world, i + 7, j + 9, k + 22, block);
        this.setBlock(world, i + 7, j + 9, k + 23, block);
        this.setBlock(world, i + 7, j + 10, k + 13, block);
        this.setBlock(world, i + 7, j + 10, k + 14, block);
        this.setBlock(world, i + 7, j + 10, k + 15, block);
        this.setBlock(world, i + 7, j + 10, k + 16, block);
        this.setBlock(world, i + 7, j + 10, k + 22, block);
        this.setBlock(world, i + 7, j + 10, k + 23, block);
        this.setBlock(world, i + 7, j + 10, k + 24, block);
        this.setBlock(world, i + 7, j + 10, k + 25, block);
        this.setBlock(world, i + 7, j + 11, k + 12, block);
        this.setBlock(world, i + 7, j + 11, k + 13, block);
        this.setBlock(world, i + 7, j + 11, k + 14, block);
        this.setBlock(world, i + 7, j + 11, k + 24, block);
        this.setBlock(world, i + 7, j + 11, k + 25, block);
        this.setBlock(world, i + 7, j + 11, k + 26, block);
        this.setBlock(world, i + 7, j + 12, k + 11, block);
        this.setBlock(world, i + 7, j + 12, k + 12, block);
        this.setBlock(world, i + 7, j + 12, k + 13, block);
        this.setBlock(world, i + 7, j + 12, k + 25, block);
        this.setBlock(world, i + 7, j + 12, k + 26, block);
        this.setBlock(world, i + 7, j + 12, k + 27, block);
        this.setBlock(world, i + 7, j + 13, k + 11, block);
        this.setBlock(world, i + 7, j + 13, k + 12, block);
        this.setBlock(world, i + 7, j + 13, k + 26, block);
        this.setBlock(world, i + 7, j + 13, k + 27, block);
        this.setBlock(world, i + 7, j + 14, k + 10, block);
        this.setBlock(world, i + 7, j + 14, k + 11, block);
        this.setBlock(world, i + 7, j + 14, k + 27, block);
        this.setBlock(world, i + 7, j + 14, k + 28, block);
        this.setBlock(world, i + 7, j + 15, k + 10, block);
        this.setBlock(world, i + 7, j + 15, k + 11, block);
        this.setBlock(world, i + 7, j + 15, k + 27, block);
        this.setBlock(world, i + 7, j + 15, k + 28, block);
        this.setBlock(world, i + 7, j + 16, k + 10, block);
        this.setBlock(world, i + 7, j + 16, k + 11, block);
        this.setBlock(world, i + 7, j + 16, k + 27, block);
        this.setBlock(world, i + 7, j + 16, k + 28, block);
        this.setBlock(world, i + 7, j + 17, k + 10, block);
        this.setBlock(world, i + 7, j + 17, k + 11, block);
        this.setBlock(world, i + 7, j + 17, k + 27, block);
        this.setBlock(world, i + 7, j + 17, k + 28, block);
        this.setBlock(world, i + 7, j + 18, k + 11, block);
        this.setBlock(world, i + 7, j + 18, k + 12, block);
        this.setBlock(world, i + 7, j + 18, k + 26, block);
        this.setBlock(world, i + 7, j + 18, k + 27, block);
        this.setBlock(world, i + 7, j + 19, k + 11, block);
        this.setBlock(world, i + 7, j + 19, k + 12, block);
        this.setBlock(world, i + 7, j + 19, k + 13, block);
        this.setBlock(world, i + 7, j + 19, k + 25, block);
        this.setBlock(world, i + 7, j + 19, k + 26, block);
        this.setBlock(world, i + 7, j + 19, k + 27, block);
        this.setBlock(world, i + 7, j + 20, k + 12, block);
        this.setBlock(world, i + 7, j + 20, k + 13, block);
        this.setBlock(world, i + 7, j + 20, k + 14, block);
        this.setBlock(world, i + 7, j + 20, k + 24, block);
        this.setBlock(world, i + 7, j + 20, k + 25, block);
        this.setBlock(world, i + 7, j + 20, k + 26, block);
        this.setBlock(world, i + 7, j + 21, k + 13, block);
        this.setBlock(world, i + 7, j + 21, k + 14, block);
        this.setBlock(world, i + 7, j + 21, k + 15, block);
        this.setBlock(world, i + 7, j + 21, k + 16, block);
        this.setBlock(world, i + 7, j + 21, k + 22, block);
        this.setBlock(world, i + 7, j + 21, k + 23, block);
        this.setBlock(world, i + 7, j + 21, k + 24, block);
        this.setBlock(world, i + 7, j + 21, k + 25, block);
        this.setBlock(world, i + 7, j + 22, k + 15, block);
        this.setBlock(world, i + 7, j + 22, k + 16, block);
        this.setBlock(world, i + 7, j + 22, k + 17, block);
        this.setBlock(world, i + 7, j + 22, k + 18, block);
        this.setBlock(world, i + 7, j + 22, k + 19, block);
        this.setBlock(world, i + 7, j + 22, k + 20, block);
        this.setBlock(world, i + 7, j + 22, k + 21, block);
        this.setBlock(world, i + 7, j + 22, k + 22, block);
        this.setBlock(world, i + 7, j + 22, k + 23, block);
        this.setBlock(world, i + 7, j + 23, k + 19, block);
        this.setBlock(world, i + 8, j + 7, k + 17, block);
        this.setBlock(world, i + 8, j + 7, k + 18, block);
        this.setBlock(world, i + 8, j + 7, k + 19, block);
        this.setBlock(world, i + 8, j + 7, k + 20, block);
        this.setBlock(world, i + 8, j + 7, k + 21, block);
        this.setBlock(world, i + 8, j + 8, k + 14, block);
        this.setBlock(world, i + 8, j + 8, k + 15, block);
        this.setBlock(world, i + 8, j + 8, k + 16, block);
        this.setBlock(world, i + 8, j + 8, k + 17, block);
        this.setBlock(world, i + 8, j + 8, k + 18, block);
        this.setBlock(world, i + 8, j + 8, k + 20, block);
        this.setBlock(world, i + 8, j + 8, k + 21, block);
        this.setBlock(world, i + 8, j + 8, k + 22, block);
        this.setBlock(world, i + 8, j + 8, k + 23, block);
        this.setBlock(world, i + 8, j + 8, k + 24, block);
        this.setBlock(world, i + 8, j + 9, k + 12, block);
        this.setBlock(world, i + 8, j + 9, k + 13, block);
        this.setBlock(world, i + 8, j + 9, k + 14, block);
        this.setBlock(world, i + 8, j + 9, k + 24, block);
        this.setBlock(world, i + 8, j + 9, k + 25, block);
        this.setBlock(world, i + 8, j + 9, k + 26, block);
        this.setBlock(world, i + 8, j + 10, k + 11, block);
        this.setBlock(world, i + 8, j + 10, k + 12, block);
        this.setBlock(world, i + 8, j + 10, k + 26, block);
        this.setBlock(world, i + 8, j + 10, k + 27, block);
        this.setBlock(world, i + 8, j + 11, k + 10, block);
        this.setBlock(world, i + 8, j + 11, k + 11, block);
        this.setBlock(world, i + 8, j + 11, k + 27, block);
        this.setBlock(world, i + 8, j + 11, k + 28, block);
        this.setBlock(world, i + 8, j + 12, k + 10, block);
        this.setBlock(world, i + 8, j + 12, k + 28, block);
        this.setBlock(world, i + 8, j + 13, k + 9, block);
        this.setBlock(world, i + 8, j + 13, k + 10, block);
        this.setBlock(world, i + 8, j + 13, k + 28, block);
        this.setBlock(world, i + 8, j + 13, k + 29, block);
        this.setBlock(world, i + 8, j + 14, k + 9, block);
        this.setBlock(world, i + 8, j + 14, k + 29, block);
        this.setBlock(world, i + 8, j + 15, k + 9, block);
        this.setBlock(world, i + 8, j + 15, k + 29, block);
        this.setBlock(world, i + 8, j + 16, k + 9, block);
        this.setBlock(world, i + 8, j + 16, k + 29, block);
        this.setBlock(world, i + 8, j + 17, k + 9, block);
        this.setBlock(world, i + 8, j + 17, k + 29, block);
        this.setBlock(world, i + 8, j + 18, k + 9, block);
        this.setBlock(world, i + 8, j + 18, k + 10, block);
        this.setBlock(world, i + 8, j + 18, k + 28, block);
        this.setBlock(world, i + 8, j + 18, k + 29, block);
        this.setBlock(world, i + 8, j + 19, k + 10, block);
        this.setBlock(world, i + 8, j + 19, k + 28, block);
        this.setBlock(world, i + 8, j + 20, k + 10, block);
        this.setBlock(world, i + 8, j + 20, k + 11, block);
        this.setBlock(world, i + 8, j + 20, k + 27, block);
        this.setBlock(world, i + 8, j + 20, k + 28, block);
        this.setBlock(world, i + 8, j + 21, k + 11, block);
        this.setBlock(world, i + 8, j + 21, k + 12, block);
        this.setBlock(world, i + 8, j + 21, k + 26, block);
        this.setBlock(world, i + 8, j + 21, k + 27, block);
        this.setBlock(world, i + 8, j + 22, k + 12, block);
        this.setBlock(world, i + 8, j + 22, k + 13, block);
        this.setBlock(world, i + 8, j + 22, k + 14, block);
        this.setBlock(world, i + 8, j + 22, k + 24, block);
        this.setBlock(world, i + 8, j + 22, k + 25, block);
        this.setBlock(world, i + 8, j + 22, k + 26, block);
        this.setBlock(world, i + 8, j + 23, k + 14, block);
        this.setBlock(world, i + 8, j + 23, k + 15, block);
        this.setBlock(world, i + 8, j + 23, k + 16, block);
        this.setBlock(world, i + 8, j + 23, k + 17, block);
        this.setBlock(world, i + 8, j + 23, k + 18, block);
        this.setBlock(world, i + 8, j + 23, k + 20, block);
        this.setBlock(world, i + 8, j + 23, k + 21, block);
        this.setBlock(world, i + 8, j + 23, k + 22, block);
        this.setBlock(world, i + 8, j + 23, k + 23, block);
        this.setBlock(world, i + 8, j + 23, k + 24, block);
        this.setBlock(world, i + 8, j + 24, k + 17, block);
        this.setBlock(world, i + 8, j + 24, k + 18, block);
        this.setBlock(world, i + 8, j + 24, k + 19, block);
        this.setBlock(world, i + 8, j + 24, k + 20, block);
        this.setBlock(world, i + 8, j + 24, k + 21, block);
        this.setBlock(world, i + 9, j + 6, k + 17, block);
        this.setBlock(world, i + 9, j + 6, k + 18, block);
        this.setBlock(world, i + 9, j + 6, k + 19, block);
        this.setBlock(world, i + 9, j + 6, k + 20, block);
        this.setBlock(world, i + 9, j + 6, k + 21, block);
        this.setBlock(world, i + 9, j + 7, k + 13, block);
        this.setBlock(world, i + 9, j + 7, k + 14, block);
        this.setBlock(world, i + 9, j + 7, k + 15, block);
        this.setBlock(world, i + 9, j + 7, k + 16, block);
        this.setBlock(world, i + 9, j + 7, k + 22, block);
        this.setBlock(world, i + 9, j + 7, k + 23, block);
        this.setBlock(world, i + 9, j + 7, k + 24, block);
        this.setBlock(world, i + 9, j + 7, k + 25, block);
        this.setBlock(world, i + 9, j + 8, k + 12, block);
        this.setBlock(world, i + 9, j + 8, k + 13, block);
        this.setBlock(world, i + 9, j + 8, k + 25, block);
        this.setBlock(world, i + 9, j + 8, k + 26, block);
        this.setBlock(world, i + 9, j + 9, k + 10, block);
        this.setBlock(world, i + 9, j + 9, k + 11, block);
        this.setBlock(world, i + 9, j + 9, k + 27, block);
        this.setBlock(world, i + 9, j + 9, k + 28, block);
        this.setBlock(world, i + 9, j + 10, k + 9, block);
        this.setBlock(world, i + 9, j + 10, k + 10, block);
        this.setBlock(world, i + 9, j + 10, k + 28, block);
        this.setBlock(world, i + 9, j + 10, k + 29, block);
        this.setBlock(world, i + 9, j + 11, k + 9, block);
        this.setBlock(world, i + 9, j + 11, k + 29, block);
        this.setBlock(world, i + 9, j + 12, k + 8, block);
        this.setBlock(world, i + 9, j + 12, k + 9, block);
        this.setBlock(world, i + 9, j + 12, k + 29, block);
        this.setBlock(world, i + 9, j + 12, k + 30, block);
        this.setBlock(world, i + 9, j + 13, k + 8, block);
        this.setBlock(world, i + 9, j + 13, k + 30, block);
        this.setBlock(world, i + 9, j + 14, k + 8, block);
        this.setBlock(world, i + 9, j + 14, k + 30, block);
        this.setBlock(world, i + 9, j + 15, k + 7, block);
        this.setBlock(world, i + 9, j + 15, k + 8, block);
        this.setBlock(world, i + 9, j + 15, k + 30, block);
        this.setBlock(world, i + 9, j + 15, k + 31, block);
        this.setBlock(world, i + 9, j + 16, k + 7, block);
        this.setBlock(world, i + 9, j + 16, k + 8, block);
        this.setBlock(world, i + 9, j + 16, k + 30, block);
        this.setBlock(world, i + 9, j + 16, k + 31, block);
        this.setBlock(world, i + 9, j + 17, k + 8, block);
        this.setBlock(world, i + 9, j + 17, k + 30, block);
        this.setBlock(world, i + 9, j + 18, k + 8, block);
        this.setBlock(world, i + 9, j + 18, k + 30, block);
        this.setBlock(world, i + 9, j + 19, k + 8, block);
        this.setBlock(world, i + 9, j + 19, k + 9, block);
        this.setBlock(world, i + 9, j + 19, k + 29, block);
        this.setBlock(world, i + 9, j + 19, k + 30, block);
        this.setBlock(world, i + 9, j + 20, k + 9, block);
        this.setBlock(world, i + 9, j + 20, k + 29, block);
        this.setBlock(world, i + 9, j + 21, k + 9, block);
        this.setBlock(world, i + 9, j + 21, k + 10, block);
        this.setBlock(world, i + 9, j + 21, k + 28, block);
        this.setBlock(world, i + 9, j + 21, k + 29, block);
        this.setBlock(world, i + 9, j + 22, k + 10, block);
        this.setBlock(world, i + 9, j + 22, k + 11, block);
        this.setBlock(world, i + 9, j + 22, k + 27, block);
        this.setBlock(world, i + 9, j + 22, k + 28, block);
        this.setBlock(world, i + 9, j + 23, k + 12, block);
        this.setBlock(world, i + 9, j + 23, k + 13, block);
        this.setBlock(world, i + 9, j + 23, k + 25, block);
        this.setBlock(world, i + 9, j + 23, k + 26, block);
        this.setBlock(world, i + 9, j + 24, k + 13, block);
        this.setBlock(world, i + 9, j + 24, k + 14, block);
        this.setBlock(world, i + 9, j + 24, k + 15, block);
        this.setBlock(world, i + 9, j + 24, k + 16, block);
        this.setBlock(world, i + 9, j + 24, k + 22, block);
        this.setBlock(world, i + 9, j + 24, k + 23, block);
        this.setBlock(world, i + 9, j + 24, k + 24, block);
        this.setBlock(world, i + 9, j + 24, k + 25, block);
        this.setBlock(world, i + 9, j + 25, k + 17, block);
        this.setBlock(world, i + 9, j + 25, k + 18, block);
        this.setBlock(world, i + 9, j + 25, k + 19, block);
        this.setBlock(world, i + 9, j + 25, k + 20, block);
        this.setBlock(world, i + 9, j + 25, k + 21, block);
        this.setBlock(world, i + 10, j + 5, k + 17, block);
        this.setBlock(world, i + 10, j + 5, k + 18, block);
        this.setBlock(world, i + 10, j + 5, k + 19, block);
        this.setBlock(world, i + 10, j + 5, k + 20, block);
        this.setBlock(world, i + 10, j + 5, k + 21, block);
        this.setBlock(world, i + 10, j + 6, k + 14, block);
        this.setBlock(world, i + 10, j + 6, k + 15, block);
        this.setBlock(world, i + 10, j + 6, k + 16, block);
        this.setBlock(world, i + 10, j + 6, k + 22, block);
        this.setBlock(world, i + 10, j + 6, k + 23, block);
        this.setBlock(world, i + 10, j + 6, k + 24, block);
        this.setBlock(world, i + 10, j + 7, k + 12, block);
        this.setBlock(world, i + 10, j + 7, k + 13, block);
        this.setBlock(world, i + 10, j + 7, k + 25, block);
        this.setBlock(world, i + 10, j + 7, k + 26, block);
        this.setBlock(world, i + 10, j + 8, k + 10, block);
        this.setBlock(world, i + 10, j + 8, k + 11, block);
        this.setBlock(world, i + 10, j + 8, k + 27, block);
        this.setBlock(world, i + 10, j + 8, k + 28, block);
        this.setBlock(world, i + 10, j + 9, k + 9, block);
        this.setBlock(world, i + 10, j + 9, k + 29, block);
        this.setBlock(world, i + 10, j + 10, k + 8, block);
        this.setBlock(world, i + 10, j + 10, k + 30, block);
        this.setBlock(world, i + 10, j + 11, k + 8, block);
        this.setBlock(world, i + 10, j + 11, k + 30, block);
        this.setBlock(world, i + 10, j + 12, k + 7, block);
        this.setBlock(world, i + 10, j + 12, k + 31, block);
        this.setBlock(world, i + 10, j + 13, k + 7, block);
        this.setBlock(world, i + 10, j + 13, k + 31, block);
        this.setBlock(world, i + 10, j + 14, k + 6, block);
        this.setBlock(world, i + 10, j + 14, k + 7, block);
        this.setBlock(world, i + 10, j + 14, k + 31, block);
        this.setBlock(world, i + 10, j + 14, k + 32, block);
        this.setBlock(world, i + 10, j + 15, k + 6, block);
        this.setBlock(world, i + 10, j + 15, k + 32, block);
        this.setBlock(world, i + 10, j + 16, k + 6, block);
        this.setBlock(world, i + 10, j + 16, k + 32, block);
        this.setBlock(world, i + 10, j + 17, k + 6, block);
        this.setBlock(world, i + 10, j + 17, k + 7, block);
        this.setBlock(world, i + 10, j + 17, k + 31, block);
        this.setBlock(world, i + 10, j + 17, k + 32, block);
        this.setBlock(world, i + 10, j + 18, k + 7, block);
        this.setBlock(world, i + 10, j + 18, k + 31, block);
        this.setBlock(world, i + 10, j + 19, k + 7, block);
        this.setBlock(world, i + 10, j + 19, k + 31, block);
        this.setBlock(world, i + 10, j + 20, k + 8, block);
        this.setBlock(world, i + 10, j + 20, k + 30, block);
        this.setBlock(world, i + 10, j + 21, k + 8, block);
        this.setBlock(world, i + 10, j + 21, k + 30, block);
        this.setBlock(world, i + 10, j + 22, k + 9, block);
        this.setBlock(world, i + 10, j + 22, k + 29, block);
        this.setBlock(world, i + 10, j + 23, k + 10, block);
        this.setBlock(world, i + 10, j + 23, k + 11, block);
        this.setBlock(world, i + 10, j + 23, k + 27, block);
        this.setBlock(world, i + 10, j + 23, k + 28, block);
        this.setBlock(world, i + 10, j + 24, k + 12, block);
        this.setBlock(world, i + 10, j + 24, k + 13, block);
        this.setBlock(world, i + 10, j + 24, k + 25, block);
        this.setBlock(world, i + 10, j + 24, k + 26, block);
        this.setBlock(world, i + 10, j + 25, k + 14, block);
        this.setBlock(world, i + 10, j + 25, k + 15, block);
        this.setBlock(world, i + 10, j + 25, k + 16, block);
        this.setBlock(world, i + 10, j + 25, k + 22, block);
        this.setBlock(world, i + 10, j + 25, k + 23, block);
        this.setBlock(world, i + 10, j + 25, k + 24, block);
        this.setBlock(world, i + 10, j + 26, k + 17, block);
        this.setBlock(world, i + 10, j + 26, k + 18, block);
        this.setBlock(world, i + 10, j + 26, k + 19, block);
        this.setBlock(world, i + 10, j + 26, k + 20, block);
        this.setBlock(world, i + 10, j + 26, k + 21, block);
        this.setBlock(world, i + 11, j + 5, k + 14, block);
        this.setBlock(world, i + 11, j + 5, k + 15, block);
        this.setBlock(world, i + 11, j + 5, k + 16, block);
        this.setBlock(world, i + 11, j + 5, k + 17, block);
        this.setBlock(world, i + 11, j + 5, k + 18, block);
        this.setBlock(world, i + 11, j + 5, k + 19, block);
        this.setBlock(world, i + 11, j + 5, k + 20, block);
        this.setBlock(world, i + 11, j + 5, k + 21, block);
        this.setBlock(world, i + 11, j + 5, k + 22, block);
        this.setBlock(world, i + 11, j + 5, k + 23, block);
        this.setBlock(world, i + 11, j + 5, k + 24, block);
        this.setBlock(world, i + 11, j + 6, k + 12, block);
        this.setBlock(world, i + 11, j + 6, k + 13, block);
        this.setBlock(world, i + 11, j + 6, k + 25, block);
        this.setBlock(world, i + 11, j + 6, k + 26, block);
        this.setBlock(world, i + 11, j + 7, k + 10, block);
        this.setBlock(world, i + 11, j + 7, k + 11, block);
        this.setBlock(world, i + 11, j + 7, k + 27, block);
        this.setBlock(world, i + 11, j + 7, k + 28, block);
        this.setBlock(world, i + 11, j + 8, k + 9, block);
        this.setBlock(world, i + 11, j + 8, k + 29, block);
        this.setBlock(world, i + 11, j + 9, k + 8, block);
        this.setBlock(world, i + 11, j + 9, k + 30, block);
        this.setBlock(world, i + 11, j + 10, k + 7, block);
        this.setBlock(world, i + 11, j + 10, k + 31, block);
        this.setBlock(world, i + 11, j + 11, k + 7, block);
        this.setBlock(world, i + 11, j + 11, k + 31, block);
        this.setBlock(world, i + 11, j + 12, k + 6, block);
        this.setBlock(world, i + 11, j + 12, k + 32, block);
        this.setBlock(world, i + 11, j + 13, k + 6, block);
        this.setBlock(world, i + 11, j + 13, k + 32, block);
        this.setBlock(world, i + 11, j + 14, k + 6, block);
        this.setBlock(world, i + 11, j + 14, k + 32, block);
        this.setBlock(world, i + 11, j + 15, k + 5, block);
        this.setBlock(world, i + 11, j + 15, k + 33, block);
        this.setBlock(world, i + 11, j + 16, k + 5, block);
        this.setBlock(world, i + 11, j + 16, k + 33, block);
        this.setBlock(world, i + 11, j + 17, k + 6, block);
        this.setBlock(world, i + 11, j + 17, k + 32, block);
        this.setBlock(world, i + 11, j + 18, k + 6, block);
        this.setBlock(world, i + 11, j + 18, k + 32, block);
        this.setBlock(world, i + 11, j + 19, k + 6, block);
        this.setBlock(world, i + 11, j + 19, k + 32, block);
        this.setBlock(world, i + 11, j + 20, k + 7, block);
        this.setBlock(world, i + 11, j + 20, k + 31, block);
        this.setBlock(world, i + 11, j + 21, k + 7, block);
        this.setBlock(world, i + 11, j + 21, k + 31, block);
        this.setBlock(world, i + 11, j + 22, k + 8, block);
        this.setBlock(world, i + 11, j + 22, k + 30, block);
        this.setBlock(world, i + 11, j + 23, k + 9, block);
        this.setBlock(world, i + 11, j + 23, k + 29, block);
        this.setBlock(world, i + 11, j + 24, k + 10, block);
        this.setBlock(world, i + 11, j + 24, k + 11, block);
        this.setBlock(world, i + 11, j + 24, k + 27, block);
        this.setBlock(world, i + 11, j + 24, k + 28, block);
        this.setBlock(world, i + 11, j + 25, k + 12, block);
        this.setBlock(world, i + 11, j + 25, k + 13, block);
        this.setBlock(world, i + 11, j + 25, k + 25, block);
        this.setBlock(world, i + 11, j + 25, k + 26, block);
        this.setBlock(world, i + 11, j + 26, k + 14, block);
        this.setBlock(world, i + 11, j + 26, k + 15, block);
        this.setBlock(world, i + 11, j + 26, k + 16, block);
        this.setBlock(world, i + 11, j + 26, k + 17, block);
        this.setBlock(world, i + 11, j + 26, k + 18, block);
        this.setBlock(world, i + 11, j + 26, k + 19, block);
        this.setBlock(world, i + 11, j + 26, k + 20, block);
        this.setBlock(world, i + 11, j + 26, k + 21, block);
        this.setBlock(world, i + 11, j + 26, k + 22, block);
        this.setBlock(world, i + 11, j + 26, k + 23, block);
        this.setBlock(world, i + 11, j + 26, k + 24, block);
        this.setBlock(world, i + 12, j + 4, k + 15, block);
        this.setBlock(world, i + 12, j + 4, k + 16, block);
        this.setBlock(world, i + 12, j + 4, k + 17, block);
        this.setBlock(world, i + 12, j + 4, k + 18, block);
        this.setBlock(world, i + 12, j + 4, k + 19, block);
        this.setBlock(world, i + 12, j + 4, k + 20, block);
        this.setBlock(world, i + 12, j + 4, k + 21, block);
        this.setBlock(world, i + 12, j + 4, k + 22, block);
        this.setBlock(world, i + 12, j + 4, k + 23, block);
        this.setBlock(world, i + 12, j + 5, k + 12, block);
        this.setBlock(world, i + 12, j + 5, k + 13, block);
        this.setBlock(world, i + 12, j + 5, k + 14, block);
        this.setBlock(world, i + 12, j + 5, k + 24, block);
        this.setBlock(world, i + 12, j + 5, k + 25, block);
        this.setBlock(world, i + 12, j + 5, k + 26, block);
        this.setBlock(world, i + 12, j + 6, k + 10, block);
        this.setBlock(world, i + 12, j + 6, k + 11, block);
        this.setBlock(world, i + 12, j + 6, k + 27, block);
        this.setBlock(world, i + 12, j + 6, k + 28, block);
        this.setBlock(world, i + 12, j + 7, k + 9, block);
        this.setBlock(world, i + 12, j + 7, k + 29, block);
        this.setBlock(world, i + 12, j + 8, k + 8, block);
        this.setBlock(world, i + 12, j + 8, k + 30, block);
        this.setBlock(world, i + 12, j + 9, k + 7, block);
        this.setBlock(world, i + 12, j + 9, k + 31, block);
        this.setBlock(world, i + 12, j + 10, k + 6, block);
        this.setBlock(world, i + 12, j + 10, k + 32, block);
        this.setBlock(world, i + 12, j + 11, k + 6, block);
        this.setBlock(world, i + 12, j + 11, k + 32, block);
        this.setBlock(world, i + 12, j + 12, k + 5, block);
        this.setBlock(world, i + 12, j + 12, k + 33, block);
        this.setBlock(world, i + 12, j + 13, k + 5, block);
        this.setBlock(world, i + 12, j + 13, k + 33, block);
        this.setBlock(world, i + 12, j + 14, k + 5, block);
        this.setBlock(world, i + 12, j + 14, k + 33, block);
        this.setBlock(world, i + 12, j + 15, k + 5, block);
        this.setBlock(world, i + 12, j + 15, k + 33, block);
        this.setBlock(world, i + 12, j + 16, k + 5, block);
        this.setBlock(world, i + 12, j + 16, k + 33, block);
        this.setBlock(world, i + 12, j + 17, k + 5, block);
        this.setBlock(world, i + 12, j + 17, k + 33, block);
        this.setBlock(world, i + 12, j + 18, k + 5, block);
        this.setBlock(world, i + 12, j + 18, k + 33, block);
        this.setBlock(world, i + 12, j + 19, k + 5, block);
        this.setBlock(world, i + 12, j + 19, k + 33, block);
        this.setBlock(world, i + 12, j + 20, k + 6, block);
        this.setBlock(world, i + 12, j + 20, k + 32, block);
        this.setBlock(world, i + 12, j + 21, k + 6, block);
        this.setBlock(world, i + 12, j + 21, k + 32, block);
        this.setBlock(world, i + 12, j + 22, k + 7, block);
        this.setBlock(world, i + 12, j + 22, k + 31, block);
        this.setBlock(world, i + 12, j + 23, k + 8, block);
        this.setBlock(world, i + 12, j + 23, k + 30, block);
        this.setBlock(world, i + 12, j + 24, k + 9, block);
        this.setBlock(world, i + 12, j + 24, k + 29, block);
        this.setBlock(world, i + 12, j + 25, k + 10, block);
        this.setBlock(world, i + 12, j + 25, k + 11, block);
        this.setBlock(world, i + 12, j + 25, k + 27, block);
        this.setBlock(world, i + 12, j + 25, k + 28, block);
        this.setBlock(world, i + 12, j + 26, k + 12, block);
        this.setBlock(world, i + 12, j + 26, k + 13, block);
        this.setBlock(world, i + 12, j + 26, k + 14, block);
        this.setBlock(world, i + 12, j + 26, k + 24, block);
        this.setBlock(world, i + 12, j + 26, k + 25, block);
        this.setBlock(world, i + 12, j + 26, k + 26, block);
        this.setBlock(world, i + 12, j + 27, k + 15, block);
        this.setBlock(world, i + 12, j + 27, k + 16, block);
        this.setBlock(world, i + 12, j + 27, k + 17, block);
        this.setBlock(world, i + 12, j + 27, k + 18, block);
        this.setBlock(world, i + 12, j + 27, k + 19, block);
        this.setBlock(world, i + 12, j + 27, k + 20, block);
        this.setBlock(world, i + 12, j + 27, k + 21, block);
        this.setBlock(world, i + 12, j + 27, k + 22, block);
        this.setBlock(world, i + 12, j + 27, k + 23, block);
        this.setBlock(world, i + 13, j + 3, k + 17, block);
        this.setBlock(world, i + 13, j + 3, k + 18, block);
        this.setBlock(world, i + 13, j + 3, k + 19, block);
        this.setBlock(world, i + 13, j + 3, k + 20, block);
        this.setBlock(world, i + 13, j + 3, k + 21, block);
        this.setBlock(world, i + 13, j + 4, k + 13, block);
        this.setBlock(world, i + 13, j + 4, k + 14, block);
        this.setBlock(world, i + 13, j + 4, k + 15, block);
        this.setBlock(world, i + 13, j + 4, k + 16, block);
        this.setBlock(world, i + 13, j + 4, k + 22, block);
        this.setBlock(world, i + 13, j + 4, k + 23, block);
        this.setBlock(world, i + 13, j + 4, k + 24, block);
        this.setBlock(world, i + 13, j + 4, k + 25, block);
        this.setBlock(world, i + 13, j + 5, k + 11, block);
        this.setBlock(world, i + 13, j + 5, k + 12, block);
        this.setBlock(world, i + 13, j + 5, k + 26, block);
        this.setBlock(world, i + 13, j + 5, k + 27, block);
        this.setBlock(world, i + 13, j + 6, k + 9, block);
        this.setBlock(world, i + 13, j + 6, k + 10, block);
        this.setBlock(world, i + 13, j + 6, k + 28, block);
        this.setBlock(world, i + 13, j + 6, k + 29, block);
        this.setBlock(world, i + 13, j + 7, k + 8, block);
        this.setBlock(world, i + 13, j + 7, k + 30, block);
        this.setBlock(world, i + 13, j + 8, k + 7, block);
        this.setBlock(world, i + 13, j + 8, k + 31, block);
        this.setBlock(world, i + 13, j + 9, k + 6, block);
        this.setBlock(world, i + 13, j + 9, k + 32, block);
        this.setBlock(world, i + 13, j + 10, k + 5, block);
        this.setBlock(world, i + 13, j + 10, k + 33, block);
        this.setBlock(world, i + 13, j + 11, k + 5, block);
        this.setBlock(world, i + 13, j + 11, k + 33, block);
        this.setBlock(world, i + 13, j + 12, k + 5, block);
        this.setBlock(world, i + 13, j + 12, k + 33, block);
        this.setBlock(world, i + 13, j + 13, k + 4, block);
        this.setBlock(world, i + 13, j + 13, k + 34, block);
        this.setBlock(world, i + 13, j + 14, k + 4, block);
        this.setBlock(world, i + 13, j + 14, k + 34, block);
        this.setBlock(world, i + 13, j + 15, k + 4, block);
        this.setBlock(world, i + 13, j + 15, k + 34, block);
        this.setBlock(world, i + 13, j + 16, k + 4, block);
        this.setBlock(world, i + 13, j + 16, k + 34, block);
        this.setBlock(world, i + 13, j + 17, k + 4, block);
        this.setBlock(world, i + 13, j + 17, k + 34, block);
        this.setBlock(world, i + 13, j + 18, k + 4, block);
        this.setBlock(world, i + 13, j + 18, k + 34, block);
        this.setBlock(world, i + 13, j + 19, k + 5, block);
        this.setBlock(world, i + 13, j + 19, k + 33, block);
        this.setBlock(world, i + 13, j + 20, k + 5, block);
        this.setBlock(world, i + 13, j + 20, k + 33, block);
        this.setBlock(world, i + 13, j + 21, k + 5, block);
        this.setBlock(world, i + 13, j + 21, k + 33, block);
        this.setBlock(world, i + 13, j + 22, k + 6, block);
        this.setBlock(world, i + 13, j + 22, k + 32, block);
        this.setBlock(world, i + 13, j + 23, k + 7, block);
        this.setBlock(world, i + 13, j + 23, k + 31, block);
        this.setBlock(world, i + 13, j + 24, k + 8, block);
        this.setBlock(world, i + 13, j + 24, k + 30, block);
        this.setBlock(world, i + 13, j + 25, k + 9, block);
        this.setBlock(world, i + 13, j + 25, k + 10, block);
        this.setBlock(world, i + 13, j + 25, k + 28, block);
        this.setBlock(world, i + 13, j + 25, k + 29, block);
        this.setBlock(world, i + 13, j + 26, k + 11, block);
        this.setBlock(world, i + 13, j + 26, k + 12, block);
        this.setBlock(world, i + 13, j + 26, k + 26, block);
        this.setBlock(world, i + 13, j + 26, k + 27, block);
        this.setBlock(world, i + 13, j + 27, k + 13, block);
        this.setBlock(world, i + 13, j + 27, k + 14, block);
        this.setBlock(world, i + 13, j + 27, k + 15, block);
        this.setBlock(world, i + 13, j + 27, k + 16, block);
        this.setBlock(world, i + 13, j + 27, k + 22, block);
        this.setBlock(world, i + 13, j + 27, k + 23, block);
        this.setBlock(world, i + 13, j + 27, k + 24, block);
        this.setBlock(world, i + 13, j + 27, k + 25, block);
        this.setBlock(world, i + 13, j + 28, k + 17, block);
        this.setBlock(world, i + 13, j + 28, k + 18, block);
        this.setBlock(world, i + 13, j + 28, k + 19, block);
        this.setBlock(world, i + 13, j + 28, k + 20, block);
        this.setBlock(world, i + 13, j + 28, k + 21, block);
        this.setBlock(world, i + 14, j + 3, k + 15, block);
        this.setBlock(world, i + 14, j + 3, k + 16, block);
        this.setBlock(world, i + 14, j + 3, k + 17, block);
        this.setBlock(world, i + 14, j + 3, k + 18, block);
        this.setBlock(world, i + 14, j + 3, k + 19, block);
        this.setBlock(world, i + 14, j + 3, k + 20, block);
        this.setBlock(world, i + 14, j + 3, k + 21, block);
        this.setBlock(world, i + 14, j + 3, k + 22, block);
        this.setBlock(world, i + 14, j + 3, k + 23, block);
        this.setBlock(world, i + 14, j + 4, k + 12, block);
        this.setBlock(world, i + 14, j + 4, k + 13, block);
        this.setBlock(world, i + 14, j + 4, k + 14, block);
        this.setBlock(world, i + 14, j + 4, k + 24, block);
        this.setBlock(world, i + 14, j + 4, k + 25, block);
        this.setBlock(world, i + 14, j + 4, k + 26, block);
        this.setBlock(world, i + 14, j + 5, k + 10, block);
        this.setBlock(world, i + 14, j + 5, k + 11, block);
        this.setBlock(world, i + 14, j + 5, k + 27, block);
        this.setBlock(world, i + 14, j + 5, k + 28, block);
        this.setBlock(world, i + 14, j + 6, k + 8, block);
        this.setBlock(world, i + 14, j + 6, k + 9, block);
        this.setBlock(world, i + 14, j + 6, k + 29, block);
        this.setBlock(world, i + 14, j + 6, k + 30, block);
        this.setBlock(world, i + 14, j + 7, k + 7, block);
        this.setBlock(world, i + 14, j + 7, k + 31, block);
        this.setBlock(world, i + 14, j + 8, k + 6, block);
        this.setBlock(world, i + 14, j + 8, k + 32, block);
        this.setBlock(world, i + 14, j + 9, k + 5, block);
        this.setBlock(world, i + 14, j + 9, k + 33, block);
        this.setBlock(world, i + 14, j + 10, k + 5, block);
        this.setBlock(world, i + 14, j + 10, k + 33, block);
        this.setBlock(world, i + 14, j + 11, k + 4, block);
        this.setBlock(world, i + 14, j + 11, k + 34, block);
        this.setBlock(world, i + 14, j + 12, k + 4, block);
        this.setBlock(world, i + 14, j + 12, k + 34, block);
        this.setBlock(world, i + 14, j + 13, k + 4, block);
        this.setBlock(world, i + 14, j + 13, k + 34, block);
        this.setBlock(world, i + 14, j + 14, k + 3, block);
        this.setBlock(world, i + 14, j + 14, k + 35, block);
        this.setBlock(world, i + 14, j + 15, k + 3, block);
        this.setBlock(world, i + 14, j + 15, k + 35, block);
        this.setBlock(world, i + 14, j + 16, k + 3, block);
        this.setBlock(world, i + 14, j + 16, k + 35, block);
        this.setBlock(world, i + 14, j + 17, k + 3, block);
        this.setBlock(world, i + 14, j + 17, k + 35, block);
        this.setBlock(world, i + 14, j + 18, k + 4, block);
        this.setBlock(world, i + 14, j + 18, k + 34, block);
        this.setBlock(world, i + 14, j + 19, k + 4, block);
        this.setBlock(world, i + 14, j + 19, k + 34, block);
        this.setBlock(world, i + 14, j + 20, k + 4, block);
        this.setBlock(world, i + 14, j + 20, k + 34, block);
        this.setBlock(world, i + 14, j + 21, k + 5, block);
        this.setBlock(world, i + 14, j + 21, k + 33, block);
        this.setBlock(world, i + 14, j + 22, k + 5, block);
        this.setBlock(world, i + 14, j + 22, k + 33, block);
        this.setBlock(world, i + 14, j + 23, k + 6, block);
        this.setBlock(world, i + 14, j + 23, k + 32, block);
        this.setBlock(world, i + 14, j + 24, k + 7, block);
        this.setBlock(world, i + 14, j + 24, k + 31, block);
        this.setBlock(world, i + 14, j + 25, k + 8, block);
        this.setBlock(world, i + 14, j + 25, k + 9, block);
        this.setBlock(world, i + 14, j + 25, k + 29, block);
        this.setBlock(world, i + 14, j + 25, k + 30, block);
        this.setBlock(world, i + 14, j + 26, k + 10, block);
        this.setBlock(world, i + 14, j + 26, k + 11, block);
        this.setBlock(world, i + 14, j + 26, k + 27, block);
        this.setBlock(world, i + 14, j + 26, k + 28, block);
        this.setBlock(world, i + 14, j + 27, k + 12, block);
        this.setBlock(world, i + 14, j + 27, k + 13, block);
        this.setBlock(world, i + 14, j + 27, k + 14, block);
        this.setBlock(world, i + 14, j + 27, k + 24, block);
        this.setBlock(world, i + 14, j + 27, k + 25, block);
        this.setBlock(world, i + 14, j + 27, k + 26, block);
        this.setBlock(world, i + 14, j + 28, k + 15, block);
        this.setBlock(world, i + 14, j + 28, k + 16, block);
        this.setBlock(world, i + 14, j + 28, k + 17, block);
        this.setBlock(world, i + 14, j + 28, k + 18, block);
        this.setBlock(world, i + 14, j + 28, k + 19, block);
        this.setBlock(world, i + 14, j + 28, k + 20, block);
        this.setBlock(world, i + 14, j + 28, k + 21, block);
        this.setBlock(world, i + 14, j + 28, k + 22, block);
        this.setBlock(world, i + 14, j + 28, k + 23, block);
        this.setBlock(world, i + 15, j + 2, k + 18, block);
        this.setBlock(world, i + 15, j + 2, k + 19, block);
        this.setBlock(world, i + 15, j + 2, k + 20, block);
        this.setBlock(world, i + 15, j + 3, k + 13, block);
        this.setBlock(world, i + 15, j + 3, k + 14, block);
        this.setBlock(world, i + 15, j + 3, k + 15, block);
        this.setBlock(world, i + 15, j + 3, k + 16, block);
        this.setBlock(world, i + 15, j + 3, k + 17, block);
        this.setBlock(world, i + 15, j + 3, k + 21, block);
        this.setBlock(world, i + 15, j + 3, k + 22, block);
        this.setBlock(world, i + 15, j + 3, k + 23, block);
        this.setBlock(world, i + 15, j + 3, k + 24, block);
        this.setBlock(world, i + 15, j + 3, k + 25, block);
        this.setBlock(world, i + 15, j + 4, k + 11, block);
        this.setBlock(world, i + 15, j + 4, k + 12, block);
        this.setBlock(world, i + 15, j + 4, k + 26, block);
        this.setBlock(world, i + 15, j + 4, k + 27, block);
        this.setBlock(world, i + 15, j + 5, k + 9, block);
        this.setBlock(world, i + 15, j + 5, k + 10, block);
        this.setBlock(world, i + 15, j + 5, k + 28, block);
        this.setBlock(world, i + 15, j + 5, k + 29, block);
        this.setBlock(world, i + 15, j + 6, k + 8, block);
        this.setBlock(world, i + 15, j + 6, k + 30, block);
        this.setBlock(world, i + 15, j + 7, k + 7, block);
        this.setBlock(world, i + 15, j + 7, k + 31, block);
        this.setBlock(world, i + 15, j + 8, k + 6, block);
        this.setBlock(world, i + 15, j + 8, k + 32, block);
        this.setBlock(world, i + 15, j + 9, k + 5, block);
        this.setBlock(world, i + 15, j + 9, k + 33, block);
        this.setBlock(world, i + 15, j + 10, k + 4, block);
        this.setBlock(world, i + 15, j + 10, k + 34, block);
        this.setBlock(world, i + 15, j + 11, k + 4, block);
        this.setBlock(world, i + 15, j + 11, k + 34, block);
        this.setBlock(world, i + 15, j + 12, k + 3, block);
        this.setBlock(world, i + 15, j + 12, k + 35, block);
        this.setBlock(world, i + 15, j + 13, k + 3, block);
        this.setBlock(world, i + 15, j + 13, k + 35, block);
        this.setBlock(world, i + 15, j + 14, k + 3, block);
        this.setBlock(world, i + 15, j + 14, k + 35, block);
        this.setBlock(world, i + 15, j + 15, k + 3, block);
        this.setBlock(world, i + 15, j + 15, k + 35, block);
        this.setBlock(world, i + 15, j + 16, k + 3, block);
        this.setBlock(world, i + 15, j + 16, k + 35, block);
        this.setBlock(world, i + 15, j + 17, k + 3, block);
        this.setBlock(world, i + 15, j + 17, k + 35, block);
        this.setBlock(world, i + 15, j + 18, k + 3, block);
        this.setBlock(world, i + 15, j + 18, k + 35, block);
        this.setBlock(world, i + 15, j + 19, k + 3, block);
        this.setBlock(world, i + 15, j + 19, k + 35, block);
        this.setBlock(world, i + 15, j + 20, k + 4, block);
        this.setBlock(world, i + 15, j + 20, k + 34, block);
        this.setBlock(world, i + 15, j + 21, k + 4, block);
        this.setBlock(world, i + 15, j + 21, k + 34, block);
        this.setBlock(world, i + 15, j + 22, k + 5, block);
        this.setBlock(world, i + 15, j + 22, k + 33, block);
        this.setBlock(world, i + 15, j + 23, k + 6, block);
        this.setBlock(world, i + 15, j + 23, k + 32, block);
        this.setBlock(world, i + 15, j + 24, k + 7, block);
        this.setBlock(world, i + 15, j + 24, k + 31, block);
        this.setBlock(world, i + 15, j + 25, k + 8, block);
        this.setBlock(world, i + 15, j + 25, k + 30, block);
        this.setBlock(world, i + 15, j + 26, k + 9, block);
        this.setBlock(world, i + 15, j + 26, k + 10, block);
        this.setBlock(world, i + 15, j + 26, k + 28, block);
        this.setBlock(world, i + 15, j + 26, k + 29, block);
        this.setBlock(world, i + 15, j + 27, k + 11, block);
        this.setBlock(world, i + 15, j + 27, k + 12, block);
        this.setBlock(world, i + 15, j + 27, k + 26, block);
        this.setBlock(world, i + 15, j + 27, k + 27, block);
        this.setBlock(world, i + 15, j + 28, k + 13, block);
        this.setBlock(world, i + 15, j + 28, k + 14, block);
        this.setBlock(world, i + 15, j + 28, k + 15, block);
        this.setBlock(world, i + 15, j + 28, k + 16, block);
        this.setBlock(world, i + 15, j + 28, k + 17, block);
        this.setBlock(world, i + 15, j + 28, k + 21, block);
        this.setBlock(world, i + 15, j + 28, k + 22, block);
        this.setBlock(world, i + 15, j + 28, k + 23, block);
        this.setBlock(world, i + 15, j + 28, k + 24, block);
        this.setBlock(world, i + 15, j + 28, k + 25, block);
        this.setBlock(world, i + 15, j + 29, k + 18, block);
        this.setBlock(world, i + 15, j + 29, k + 19, block);
        this.setBlock(world, i + 15, j + 29, k + 20, block);
        this.setBlock(world, i + 16, j + 2, k + 15, block);
        this.setBlock(world, i + 16, j + 2, k + 16, block);
        this.setBlock(world, i + 16, j + 2, k + 17, block);
        this.setBlock(world, i + 16, j + 2, k + 18, block);
        this.setBlock(world, i + 16, j + 2, k + 19, block);
        this.setBlock(world, i + 16, j + 2, k + 20, block);
        this.setBlock(world, i + 16, j + 2, k + 21, block);
        this.setBlock(world, i + 16, j + 2, k + 22, block);
        this.setBlock(world, i + 16, j + 2, k + 23, block);
        this.setBlock(world, i + 16, j + 3, k + 12, block);
        this.setBlock(world, i + 16, j + 3, k + 13, block);
        this.setBlock(world, i + 16, j + 3, k + 14, block);
        this.setBlock(world, i + 16, j + 3, k + 24, block);
        this.setBlock(world, i + 16, j + 3, k + 25, block);
        this.setBlock(world, i + 16, j + 3, k + 26, block);
        this.setBlock(world, i + 16, j + 4, k + 10, block);
        this.setBlock(world, i + 16, j + 4, k + 11, block);
        this.setBlock(world, i + 16, j + 4, k + 27, block);
        this.setBlock(world, i + 16, j + 4, k + 28, block);
        this.setBlock(world, i + 16, j + 5, k + 8, block);
        this.setBlock(world, i + 16, j + 5, k + 9, block);
        this.setBlock(world, i + 16, j + 5, k + 29, block);
        this.setBlock(world, i + 16, j + 5, k + 30, block);
        this.setBlock(world, i + 16, j + 6, k + 7, block);
        this.setBlock(world, i + 16, j + 6, k + 31, block);
        this.setBlock(world, i + 16, j + 7, k + 6, block);
        this.setBlock(world, i + 16, j + 7, k + 32, block);
        this.setBlock(world, i + 16, j + 8, k + 5, block);
        this.setBlock(world, i + 16, j + 8, k + 33, block);
        this.setBlock(world, i + 16, j + 9, k + 4, block);
        this.setBlock(world, i + 16, j + 9, k + 34, block);
        this.setBlock(world, i + 16, j + 10, k + 4, block);
        this.setBlock(world, i + 16, j + 10, k + 34, block);
        this.setBlock(world, i + 16, j + 11, k + 3, block);
        this.setBlock(world, i + 16, j + 11, k + 35, block);
        this.setBlock(world, i + 16, j + 12, k + 3, block);
        this.setBlock(world, i + 16, j + 12, k + 35, block);
        this.setBlock(world, i + 16, j + 13, k + 3, block);
        this.setBlock(world, i + 16, j + 13, k + 35, block);
        this.setBlock(world, i + 16, j + 14, k + 2, block);
        this.setBlock(world, i + 16, j + 14, k + 36, block);
        this.setBlock(world, i + 16, j + 15, k + 2, block);
        this.setBlock(world, i + 16, j + 15, k + 36, block);
        this.setBlock(world, i + 16, j + 16, k + 2, block);
        this.setBlock(world, i + 16, j + 16, k + 36, block);
        this.setBlock(world, i + 16, j + 17, k + 2, block);
        this.setBlock(world, i + 16, j + 17, k + 36, block);
        this.setBlock(world, i + 16, j + 18, k + 3, block);
        this.setBlock(world, i + 16, j + 18, k + 35, block);
        this.setBlock(world, i + 16, j + 19, k + 3, block);
        this.setBlock(world, i + 16, j + 19, k + 35, block);
        this.setBlock(world, i + 16, j + 20, k + 3, block);
        this.setBlock(world, i + 16, j + 20, k + 35, block);
        this.setBlock(world, i + 16, j + 21, k + 4, block);
        this.setBlock(world, i + 16, j + 21, k + 34, block);
        this.setBlock(world, i + 16, j + 22, k + 4, block);
        this.setBlock(world, i + 16, j + 22, k + 34, block);
        this.setBlock(world, i + 16, j + 23, k + 5, block);
        this.setBlock(world, i + 16, j + 23, k + 33, block);
        this.setBlock(world, i + 16, j + 24, k + 6, block);
        this.setBlock(world, i + 16, j + 24, k + 32, block);
        this.setBlock(world, i + 16, j + 25, k + 7, block);
        this.setBlock(world, i + 16, j + 25, k + 31, block);
        this.setBlock(world, i + 16, j + 26, k + 8, block);
        this.setBlock(world, i + 16, j + 26, k + 9, block);
        this.setBlock(world, i + 16, j + 26, k + 29, block);
        this.setBlock(world, i + 16, j + 26, k + 30, block);
        this.setBlock(world, i + 16, j + 27, k + 10, block);
        this.setBlock(world, i + 16, j + 27, k + 11, block);
        this.setBlock(world, i + 16, j + 27, k + 27, block);
        this.setBlock(world, i + 16, j + 27, k + 28, block);
        this.setBlock(world, i + 16, j + 28, k + 12, block);
        this.setBlock(world, i + 16, j + 28, k + 13, block);
        this.setBlock(world, i + 16, j + 28, k + 14, block);
        this.setBlock(world, i + 16, j + 28, k + 24, block);
        this.setBlock(world, i + 16, j + 28, k + 25, block);
        this.setBlock(world, i + 16, j + 28, k + 26, block);
        this.setBlock(world, i + 16, j + 29, k + 15, block);
        this.setBlock(world, i + 16, j + 29, k + 16, block);
        this.setBlock(world, i + 16, j + 29, k + 17, block);
        this.setBlock(world, i + 16, j + 29, k + 18, block);
        this.setBlock(world, i + 16, j + 29, k + 19, block);
        this.setBlock(world, i + 16, j + 29, k + 20, block);
        this.setBlock(world, i + 16, j + 29, k + 21, block);
        this.setBlock(world, i + 16, j + 29, k + 22, block);
        this.setBlock(world, i + 16, j + 29, k + 23, block);
        this.setBlock(world, i + 17, j + 2, k + 14, block);
        this.setBlock(world, i + 17, j + 2, k + 15, block);
        this.setBlock(world, i + 17, j + 2, k + 16, block);
        this.setBlock(world, i + 17, j + 2, k + 17, block);
        this.setBlock(world, i + 17, j + 2, k + 18, block);
        this.setBlock(world, i + 17, j + 2, k + 19, block);
        this.setBlock(world, i + 17, j + 2, k + 20, block);
        this.setBlock(world, i + 17, j + 2, k + 21, block);
        this.setBlock(world, i + 17, j + 2, k + 22, block);
        this.setBlock(world, i + 17, j + 2, k + 23, block);
        this.setBlock(world, i + 17, j + 2, k + 24, block);
        this.setBlock(world, i + 17, j + 3, k + 11, block);
        this.setBlock(world, i + 17, j + 3, k + 12, block);
        this.setBlock(world, i + 17, j + 3, k + 13, block);
        this.setBlock(world, i + 17, j + 3, k + 25, block);
        this.setBlock(world, i + 17, j + 3, k + 26, block);
        this.setBlock(world, i + 17, j + 3, k + 27, block);
        this.setBlock(world, i + 17, j + 4, k + 9, block);
        this.setBlock(world, i + 17, j + 4, k + 10, block);
        this.setBlock(world, i + 17, j + 4, k + 28, block);
        this.setBlock(world, i + 17, j + 4, k + 29, block);
        this.setBlock(world, i + 17, j + 5, k + 8, block);
        this.setBlock(world, i + 17, j + 5, k + 30, block);
        this.setBlock(world, i + 17, j + 6, k + 7, block);
        this.setBlock(world, i + 17, j + 6, k + 31, block);
        this.setBlock(world, i + 17, j + 7, k + 5, block);
        this.setBlock(world, i + 17, j + 7, k + 6, block);
        this.setBlock(world, i + 17, j + 7, k + 32, block);
        this.setBlock(world, i + 17, j + 7, k + 33, block);
        this.setBlock(world, i + 17, j + 8, k + 5, block);
        this.setBlock(world, i + 17, j + 8, k + 33, block);
        this.setBlock(world, i + 17, j + 9, k + 4, block);
        this.setBlock(world, i + 17, j + 9, k + 34, block);
        this.setBlock(world, i + 17, j + 10, k + 3, block);
        this.setBlock(world, i + 17, j + 10, k + 35, block);
        this.setBlock(world, i + 17, j + 11, k + 3, block);
        this.setBlock(world, i + 17, j + 11, k + 35, block);
        this.setBlock(world, i + 17, j + 12, k + 3, block);
        this.setBlock(world, i + 17, j + 12, k + 35, block);
        this.setBlock(world, i + 17, j + 13, k + 2, block);
        this.setBlock(world, i + 17, j + 13, k + 36, block);
        this.setBlock(world, i + 17, j + 14, k + 2, block);
        this.setBlock(world, i + 17, j + 14, k + 36, block);
        this.setBlock(world, i + 17, j + 15, k + 2, block);
        this.setBlock(world, i + 17, j + 15, k + 36, block);
        this.setBlock(world, i + 17, j + 16, k + 2, block);
        this.setBlock(world, i + 17, j + 16, k + 36, block);
        this.setBlock(world, i + 17, j + 17, k + 2, block);
        this.setBlock(world, i + 17, j + 17, k + 36, block);
        this.setBlock(world, i + 17, j + 18, k + 2, block);
        this.setBlock(world, i + 17, j + 18, k + 36, block);
        this.setBlock(world, i + 17, j + 19, k + 3, block);
        this.setBlock(world, i + 17, j + 19, k + 35, block);
        this.setBlock(world, i + 17, j + 20, k + 3, block);
        this.setBlock(world, i + 17, j + 20, k + 35, block);
        this.setBlock(world, i + 17, j + 21, k + 3, block);
        this.setBlock(world, i + 17, j + 21, k + 35, block);
        this.setBlock(world, i + 17, j + 22, k + 4, block);
        this.setBlock(world, i + 17, j + 22, k + 34, block);
        this.setBlock(world, i + 17, j + 23, k + 5, block);
        this.setBlock(world, i + 17, j + 23, k + 33, block);
        this.setBlock(world, i + 17, j + 24, k + 5, block);
        this.setBlock(world, i + 17, j + 24, k + 6, block);
        this.setBlock(world, i + 17, j + 24, k + 32, block);
        this.setBlock(world, i + 17, j + 24, k + 33, block);
        this.setBlock(world, i + 17, j + 25, k + 7, block);
        this.setBlock(world, i + 17, j + 25, k + 31, block);
        this.setBlock(world, i + 17, j + 26, k + 8, block);
        this.setBlock(world, i + 17, j + 26, k + 30, block);
        this.setBlock(world, i + 17, j + 27, k + 9, block);
        this.setBlock(world, i + 17, j + 27, k + 10, block);
        this.setBlock(world, i + 17, j + 27, k + 28, block);
        this.setBlock(world, i + 17, j + 27, k + 29, block);
        this.setBlock(world, i + 17, j + 28, k + 11, block);
        this.setBlock(world, i + 17, j + 28, k + 12, block);
        this.setBlock(world, i + 17, j + 28, k + 13, block);
        this.setBlock(world, i + 17, j + 28, k + 25, block);
        this.setBlock(world, i + 17, j + 28, k + 26, block);
        this.setBlock(world, i + 17, j + 28, k + 27, block);
        this.setBlock(world, i + 17, j + 29, k + 14, block);
        this.setBlock(world, i + 17, j + 29, k + 15, block);
        this.setBlock(world, i + 17, j + 29, k + 16, block);
        this.setBlock(world, i + 17, j + 29, k + 17, block);
        this.setBlock(world, i + 17, j + 29, k + 18, block);
        this.setBlock(world, i + 17, j + 29, k + 19, block);
        this.setBlock(world, i + 17, j + 29, k + 20, block);
        this.setBlock(world, i + 17, j + 29, k + 21, block);
        this.setBlock(world, i + 17, j + 29, k + 22, block);
        this.setBlock(world, i + 17, j + 29, k + 23, block);
        this.setBlock(world, i + 17, j + 29, k + 24, block);
        this.setBlock(world, i + 18, j + 2, k + 13, block);
        this.setBlock(world, i + 18, j + 2, k + 14, block);
        this.setBlock(world, i + 18, j + 2, k + 15, block);
        this.setBlock(world, i + 18, j + 2, k + 16, block);
        this.setBlock(world, i + 18, j + 2, k + 17, block);
        this.setBlock(world, i + 18, j + 2, k + 18, block);
        this.setBlock(world, i + 18, j + 2, k + 19, block);
        this.setBlock(world, i + 18, j + 2, k + 20, block);
        this.setBlock(world, i + 18, j + 2, k + 21, block);
        this.setBlock(world, i + 18, j + 2, k + 22, block);
        this.setBlock(world, i + 18, j + 2, k + 23, block);
        this.setBlock(world, i + 18, j + 2, k + 24, block);
        this.setBlock(world, i + 18, j + 2, k + 25, block);
        this.setBlock(world, i + 18, j + 3, k + 11, block);
        this.setBlock(world, i + 18, j + 3, k + 12, block);
        this.setBlock(world, i + 18, j + 3, k + 26, block);
        this.setBlock(world, i + 18, j + 3, k + 27, block);
        this.setBlock(world, i + 18, j + 4, k + 9, block);
        this.setBlock(world, i + 18, j + 4, k + 10, block);
        this.setBlock(world, i + 18, j + 4, k + 28, block);
        this.setBlock(world, i + 18, j + 4, k + 29, block);
        this.setBlock(world, i + 18, j + 5, k + 7, block);
        this.setBlock(world, i + 18, j + 5, k + 8, block);
        this.setBlock(world, i + 18, j + 5, k + 30, block);
        this.setBlock(world, i + 18, j + 5, k + 31, block);
        this.setBlock(world, i + 18, j + 6, k + 6, block);
        this.setBlock(world, i + 18, j + 6, k + 32, block);
        this.setBlock(world, i + 18, j + 7, k + 5, block);
        this.setBlock(world, i + 18, j + 7, k + 33, block);
        this.setBlock(world, i + 18, j + 8, k + 4, block);
        this.setBlock(world, i + 18, j + 8, k + 34, block);
        this.setBlock(world, i + 18, j + 9, k + 4, block);
        this.setBlock(world, i + 18, j + 9, k + 34, block);
        this.setBlock(world, i + 18, j + 10, k + 3, block);
        this.setBlock(world, i + 18, j + 10, k + 35, block);
        this.setBlock(world, i + 18, j + 11, k + 3, block);
        this.setBlock(world, i + 18, j + 11, k + 35, block);
        this.setBlock(world, i + 18, j + 12, k + 2, block);
        this.setBlock(world, i + 18, j + 12, k + 36, block);
        this.setBlock(world, i + 18, j + 13, k + 2, block);
        this.setBlock(world, i + 18, j + 13, k + 36, block);
        this.setBlock(world, i + 18, j + 14, k + 2, block);
        this.setBlock(world, i + 18, j + 14, k + 36, block);
        this.setBlock(world, i + 18, j + 15, k + 2, block);
        this.setBlock(world, i + 18, j + 15, k + 36, block);
        this.setBlock(world, i + 18, j + 16, k + 2, block);
        this.setBlock(world, i + 18, j + 16, k + 36, block);
        this.setBlock(world, i + 18, j + 17, k + 2, block);
        this.setBlock(world, i + 18, j + 17, k + 36, block);
        this.setBlock(world, i + 18, j + 18, k + 2, block);
        this.setBlock(world, i + 18, j + 18, k + 36, block);
        this.setBlock(world, i + 18, j + 19, k + 2, block);
        this.setBlock(world, i + 18, j + 19, k + 36, block);
        this.setBlock(world, i + 18, j + 20, k + 3, block);
        this.setBlock(world, i + 18, j + 20, k + 35, block);
        this.setBlock(world, i + 18, j + 21, k + 3, block);
        this.setBlock(world, i + 18, j + 21, k + 35, block);
        this.setBlock(world, i + 18, j + 22, k + 4, block);
        this.setBlock(world, i + 18, j + 22, k + 34, block);
        this.setBlock(world, i + 18, j + 23, k + 4, block);
        this.setBlock(world, i + 18, j + 23, k + 34, block);
        this.setBlock(world, i + 18, j + 24, k + 5, block);
        this.setBlock(world, i + 18, j + 24, k + 33, block);
        this.setBlock(world, i + 18, j + 25, k + 6, block);
        this.setBlock(world, i + 18, j + 25, k + 32, block);
        this.setBlock(world, i + 18, j + 26, k + 7, block);
        this.setBlock(world, i + 18, j + 26, k + 8, block);
        this.setBlock(world, i + 18, j + 26, k + 30, block);
        this.setBlock(world, i + 18, j + 26, k + 31, block);
        this.setBlock(world, i + 18, j + 27, k + 9, block);
        this.setBlock(world, i + 18, j + 27, k + 10, block);
        this.setBlock(world, i + 18, j + 27, k + 28, block);
        this.setBlock(world, i + 18, j + 27, k + 29, block);
        this.setBlock(world, i + 18, j + 28, k + 11, block);
        this.setBlock(world, i + 18, j + 28, k + 12, block);
        this.setBlock(world, i + 18, j + 28, k + 26, block);
        this.setBlock(world, i + 18, j + 28, k + 27, block);
        this.setBlock(world, i + 18, j + 29, k + 13, block);
        this.setBlock(world, i + 18, j + 29, k + 14, block);
        this.setBlock(world, i + 18, j + 29, k + 15, block);
        this.setBlock(world, i + 18, j + 29, k + 16, block);
        this.setBlock(world, i + 18, j + 29, k + 17, block);
        this.setBlock(world, i + 18, j + 29, k + 18, block);
        this.setBlock(world, i + 18, j + 29, k + 19, block);
        this.setBlock(world, i + 18, j + 29, k + 20, block);
        this.setBlock(world, i + 18, j + 29, k + 21, block);
        this.setBlock(world, i + 18, j + 29, k + 22, block);
        this.setBlock(world, i + 18, j + 29, k + 23, block);
        this.setBlock(world, i + 18, j + 29, k + 24, block);
        this.setBlock(world, i + 18, j + 29, k + 25, block);
        this.setBlock(world, i + 19, j + 1, k + 17, block);
        this.setBlock(world, i + 19, j + 1, k + 18, block);
        this.setBlock(world, i + 19, j + 1, k + 19, block);
        this.setBlock(world, i + 19, j + 1, k + 20, block);
        this.setBlock(world, i + 19, j + 1, k + 21, block);
        this.setBlock(world, i + 19, j + 2, k + 12, block);
        this.setBlock(world, i + 19, j + 2, k + 13, block);
        this.setBlock(world, i + 19, j + 2, k + 14, block);
        this.setBlock(world, i + 19, j + 2, k + 15, block);
        this.setBlock(world, i + 19, j + 2, k + 16, block);
        this.setBlock(world, i + 19, j + 2, k + 22, block);
        this.setBlock(world, i + 19, j + 2, k + 23, block);
        this.setBlock(world, i + 19, j + 2, k + 24, block);
        this.setBlock(world, i + 19, j + 2, k + 25, block);
        this.setBlock(world, i + 19, j + 2, k + 26, block);
        this.setBlock(world, i + 19, j + 3, k + 10, block);
        this.setBlock(world, i + 19, j + 3, k + 11, block);
        this.setBlock(world, i + 19, j + 3, k + 27, block);
        this.setBlock(world, i + 19, j + 3, k + 28, block);
        this.setBlock(world, i + 19, j + 4, k + 8, block);
        this.setBlock(world, i + 19, j + 4, k + 9, block);
        this.setBlock(world, i + 19, j + 4, k + 29, block);
        this.setBlock(world, i + 19, j + 4, k + 30, block);
        this.setBlock(world, i + 19, j + 5, k + 7, block);
        this.setBlock(world, i + 19, j + 5, k + 31, block);
        this.setBlock(world, i + 19, j + 6, k + 6, block);
        this.setBlock(world, i + 19, j + 6, k + 32, block);
        this.setBlock(world, i + 19, j + 7, k + 5, block);
        this.setBlock(world, i + 19, j + 7, k + 33, block);
        this.setBlock(world, i + 19, j + 8, k + 4, block);
        this.setBlock(world, i + 19, j + 8, k + 34, block);
        this.setBlock(world, i + 19, j + 9, k + 3, block);
        this.setBlock(world, i + 19, j + 9, k + 35, block);
        this.setBlock(world, i + 19, j + 10, k + 3, block);
        this.setBlock(world, i + 19, j + 10, k + 35, block);
        this.setBlock(world, i + 19, j + 11, k + 2, block);
        this.setBlock(world, i + 19, j + 11, k + 36, block);
        this.setBlock(world, i + 19, j + 12, k + 2, block);
        this.setBlock(world, i + 19, j + 12, k + 36, block);
        this.setBlock(world, i + 19, j + 13, k + 2, block);
        this.setBlock(world, i + 19, j + 13, k + 36, block);
        this.setBlock(world, i + 19, j + 14, k + 2, block);
        this.setBlock(world, i + 19, j + 14, k + 36, block);
        this.setBlock(world, i + 19, j + 15, k + 1, block);
        this.setBlock(world, i + 19, j + 15, k + 37, block);
        this.setBlock(world, i + 19, j + 16, k + 1, block);
        this.setBlock(world, i + 19, j + 16, k + 37, block);
        this.setBlock(world, i + 19, j + 17, k + 2, block);
        this.setBlock(world, i + 19, j + 17, k + 36, block);
        this.setBlock(world, i + 19, j + 18, k + 2, block);
        this.setBlock(world, i + 19, j + 18, k + 36, block);
        this.setBlock(world, i + 19, j + 19, k + 2, block);
        this.setBlock(world, i + 19, j + 19, k + 36, block);
        this.setBlock(world, i + 19, j + 20, k + 2, block);
        this.setBlock(world, i + 19, j + 20, k + 36, block);
        this.setBlock(world, i + 19, j + 21, k + 3, block);
        this.setBlock(world, i + 19, j + 21, k + 35, block);
        this.setBlock(world, i + 19, j + 22, k + 3, block);
        this.setBlock(world, i + 19, j + 22, k + 35, block);
        this.setBlock(world, i + 19, j + 23, k + 4, block);
        this.setBlock(world, i + 19, j + 23, k + 34, block);
        this.setBlock(world, i + 19, j + 24, k + 5, block);
        this.setBlock(world, i + 19, j + 24, k + 33, block);
        this.setBlock(world, i + 19, j + 25, k + 6, block);
        this.setBlock(world, i + 19, j + 25, k + 32, block);
        this.setBlock(world, i + 19, j + 26, k + 7, block);
        this.setBlock(world, i + 19, j + 26, k + 31, block);
        this.setBlock(world, i + 19, j + 27, k + 8, block);
        this.setBlock(world, i + 19, j + 27, k + 9, block);
        this.setBlock(world, i + 19, j + 27, k + 29, block);
        this.setBlock(world, i + 19, j + 27, k + 30, block);
        this.setBlock(world, i + 19, j + 28, k + 10, block);
        this.setBlock(world, i + 19, j + 28, k + 11, block);
        this.setBlock(world, i + 19, j + 28, k + 27, block);
        this.setBlock(world, i + 19, j + 28, k + 28, block);
        this.setBlock(world, i + 19, j + 29, k + 12, block);
        this.setBlock(world, i + 19, j + 29, k + 13, block);
        this.setBlock(world, i + 19, j + 29, k + 14, block);
        this.setBlock(world, i + 19, j + 29, k + 15, block);
        this.setBlock(world, i + 19, j + 29, k + 16, block);
        this.setBlock(world, i + 19, j + 29, k + 22, block);
        this.setBlock(world, i + 19, j + 29, k + 23, block);
        this.setBlock(world, i + 19, j + 29, k + 24, block);
        this.setBlock(world, i + 19, j + 29, k + 25, block);
        this.setBlock(world, i + 19, j + 29, k + 26, block);
        this.setBlock(world, i + 19, j + 30, k + 17, block);
        this.setBlock(world, i + 19, j + 30, k + 18, block);
        this.setBlock(world, i + 19, j + 30, k + 19, block);
        this.setBlock(world, i + 19, j + 30, k + 20, block);
        this.setBlock(world, i + 19, j + 30, k + 21, block);
        this.setBlock(world, i + 20, j + 1, k + 16, block);
        this.setBlock(world, i + 20, j + 1, k + 17, block);
        this.setBlock(world, i + 20, j + 1, k + 18, block);
        this.setBlock(world, i + 20, j + 1, k + 19, block);
        this.setBlock(world, i + 20, j + 1, k + 20, block);
        this.setBlock(world, i + 20, j + 1, k + 21, block);
        this.setBlock(world, i + 20, j + 1, k + 22, block);
        this.setBlock(world, i + 20, j + 2, k + 12, block);
        this.setBlock(world, i + 20, j + 2, k + 13, block);
        this.setBlock(world, i + 20, j + 2, k + 14, block);
        this.setBlock(world, i + 20, j + 2, k + 15, block);
        this.setBlock(world, i + 20, j + 2, k + 23, block);
        this.setBlock(world, i + 20, j + 2, k + 24, block);
        this.setBlock(world, i + 20, j + 2, k + 25, block);
        this.setBlock(world, i + 20, j + 2, k + 26, block);
        this.setBlock(world, i + 20, j + 3, k + 10, block);
        this.setBlock(world, i + 20, j + 3, k + 11, block);
        this.setBlock(world, i + 20, j + 3, k + 27, block);
        this.setBlock(world, i + 20, j + 3, k + 28, block);
        this.setBlock(world, i + 20, j + 4, k + 8, block);
        this.setBlock(world, i + 20, j + 4, k + 9, block);
        this.setBlock(world, i + 20, j + 4, k + 29, block);
        this.setBlock(world, i + 20, j + 4, k + 30, block);
        this.setBlock(world, i + 20, j + 5, k + 7, block);
        this.setBlock(world, i + 20, j + 5, k + 31, block);
        this.setBlock(world, i + 20, j + 6, k + 6, block);
        this.setBlock(world, i + 20, j + 6, k + 32, block);
        this.setBlock(world, i + 20, j + 7, k + 5, block);
        this.setBlock(world, i + 20, j + 7, k + 33, block);
        this.setBlock(world, i + 20, j + 8, k + 4, block);
        this.setBlock(world, i + 20, j + 8, k + 34, block);
        this.setBlock(world, i + 20, j + 9, k + 3, block);
        this.setBlock(world, i + 20, j + 9, k + 35, block);
        this.setBlock(world, i + 20, j + 10, k + 3, block);
        this.setBlock(world, i + 20, j + 10, k + 35, block);
        this.setBlock(world, i + 20, j + 11, k + 2, block);
        this.setBlock(world, i + 20, j + 11, k + 36, block);
        this.setBlock(world, i + 20, j + 12, k + 2, block);
        this.setBlock(world, i + 20, j + 12, k + 36, block);
        this.setBlock(world, i + 20, j + 13, k + 2, block);
        this.setBlock(world, i + 20, j + 13, k + 36, block);
        this.setBlock(world, i + 20, j + 14, k + 1, block);
        this.setBlock(world, i + 20, j + 14, k + 37, block);
        this.setBlock(world, i + 20, j + 15, k + 1, block);
        this.setBlock(world, i + 20, j + 15, k + 37, block);
        this.setBlock(world, i + 20, j + 16, k + 1, block);
        this.setBlock(world, i + 20, j + 16, k + 37, block);
        this.setBlock(world, i + 20, j + 17, k + 1, block);
        this.setBlock(world, i + 20, j + 17, k + 37, block);
        this.setBlock(world, i + 20, j + 18, k + 2, block);
        this.setBlock(world, i + 20, j + 18, k + 36, block);
        this.setBlock(world, i + 20, j + 19, k + 2, block);
        this.setBlock(world, i + 20, j + 19, k + 36, block);
        this.setBlock(world, i + 20, j + 20, k + 2, block);
        this.setBlock(world, i + 20, j + 20, k + 36, block);
        this.setBlock(world, i + 20, j + 21, k + 3, block);
        this.setBlock(world, i + 20, j + 21, k + 35, block);
        this.setBlock(world, i + 20, j + 22, k + 3, block);
        this.setBlock(world, i + 20, j + 22, k + 35, block);
        this.setBlock(world, i + 20, j + 23, k + 4, block);
        this.setBlock(world, i + 20, j + 23, k + 34, block);
        this.setBlock(world, i + 20, j + 24, k + 5, block);
        this.setBlock(world, i + 20, j + 24, k + 33, block);
        this.setBlock(world, i + 20, j + 25, k + 6, block);
        this.setBlock(world, i + 20, j + 25, k + 32, block);
        this.setBlock(world, i + 20, j + 26, k + 7, block);
        this.setBlock(world, i + 20, j + 26, k + 31, block);
        this.setBlock(world, i + 20, j + 27, k + 8, block);
        this.setBlock(world, i + 20, j + 27, k + 9, block);
        this.setBlock(world, i + 20, j + 27, k + 29, block);
        this.setBlock(world, i + 20, j + 27, k + 30, block);
        this.setBlock(world, i + 20, j + 28, k + 10, block);
        this.setBlock(world, i + 20, j + 28, k + 11, block);
        this.setBlock(world, i + 20, j + 28, k + 27, block);
        this.setBlock(world, i + 20, j + 28, k + 28, block);
        this.setBlock(world, i + 20, j + 29, k + 12, block);
        this.setBlock(world, i + 20, j + 29, k + 13, block);
        this.setBlock(world, i + 20, j + 29, k + 14, block);
        this.setBlock(world, i + 20, j + 29, k + 15, block);
        this.setBlock(world, i + 20, j + 29, k + 23, block);
        this.setBlock(world, i + 20, j + 29, k + 24, block);
        this.setBlock(world, i + 20, j + 29, k + 25, block);
        this.setBlock(world, i + 20, j + 29, k + 26, block);
        this.setBlock(world, i + 20, j + 30, k + 16, block);
        this.setBlock(world, i + 20, j + 30, k + 17, block);
        this.setBlock(world, i + 20, j + 30, k + 18, block);
        this.setBlock(world, i + 20, j + 30, k + 19, block);
        this.setBlock(world, i + 20, j + 30, k + 20, block);
        this.setBlock(world, i + 20, j + 30, k + 21, block);
        this.setBlock(world, i + 20, j + 30, k + 22, block);
        this.setBlock(world, i + 21, j + 1, k + 15, block);
        this.setBlock(world, i + 21, j + 1, k + 16, block);
        this.setBlock(world, i + 21, j + 1, k + 17, block);
        this.setBlock(world, i + 21, j + 1, k + 18, block);
        this.setBlock(world, i + 21, j + 1, k + 19, block);
        this.setBlock(world, i + 21, j + 1, k + 20, block);
        this.setBlock(world, i + 21, j + 1, k + 21, block);
        this.setBlock(world, i + 21, j + 1, k + 22, block);
        this.setBlock(world, i + 21, j + 1, k + 23, block);
        this.setBlock(world, i + 21, j + 2, k + 12, block);
        this.setBlock(world, i + 21, j + 2, k + 13, block);
        this.setBlock(world, i + 21, j + 2, k + 14, block);
        this.setBlock(world, i + 21, j + 2, k + 24, block);
        this.setBlock(world, i + 21, j + 2, k + 25, block);
        this.setBlock(world, i + 21, j + 2, k + 26, block);
        this.setBlock(world, i + 21, j + 3, k + 9, block);
        this.setBlock(world, i + 21, j + 3, k + 10, block);
        this.setBlock(world, i + 21, j + 3, k + 11, block);
        this.setBlock(world, i + 21, j + 3, k + 27, block);
        this.setBlock(world, i + 21, j + 3, k + 28, block);
        this.setBlock(world, i + 21, j + 3, k + 29, block);
        this.setBlock(world, i + 21, j + 4, k + 8, block);
        this.setBlock(world, i + 21, j + 4, k + 30, block);
        this.setBlock(world, i + 21, j + 5, k + 6, block);
        this.setBlock(world, i + 21, j + 5, k + 7, block);
        this.setBlock(world, i + 21, j + 5, k + 31, block);
        this.setBlock(world, i + 21, j + 5, k + 32, block);
        this.setBlock(world, i + 21, j + 6, k + 5, block);
        this.setBlock(world, i + 21, j + 6, k + 33, block);
        this.setBlock(world, i + 21, j + 7, k + 4, block);
        this.setBlock(world, i + 21, j + 7, k + 34, block);
        this.setBlock(world, i + 21, j + 8, k + 4, block);
        this.setBlock(world, i + 21, j + 8, k + 34, block);
        this.setBlock(world, i + 21, j + 9, k + 3, block);
        this.setBlock(world, i + 21, j + 9, k + 35, block);
        this.setBlock(world, i + 21, j + 10, k + 2, block);
        this.setBlock(world, i + 21, j + 10, k + 36, block);
        this.setBlock(world, i + 21, j + 11, k + 2, block);
        this.setBlock(world, i + 21, j + 11, k + 36, block);
        this.setBlock(world, i + 21, j + 12, k + 2, block);
        this.setBlock(world, i + 21, j + 12, k + 36, block);
        this.setBlock(world, i + 21, j + 13, k + 1, block);
        this.setBlock(world, i + 21, j + 13, k + 37, block);
        this.setBlock(world, i + 21, j + 14, k + 1, block);
        this.setBlock(world, i + 21, j + 14, k + 37, block);
        this.setBlock(world, i + 21, j + 15, k + 1, block);
        this.setBlock(world, i + 21, j + 15, k + 37, block);
        this.setBlock(world, i + 21, j + 16, k + 1, block);
        this.setBlock(world, i + 21, j + 16, k + 37, block);
        this.setBlock(world, i + 21, j + 17, k + 1, block);
        this.setBlock(world, i + 21, j + 17, k + 37, block);
        this.setBlock(world, i + 21, j + 18, k + 1, block);
        this.setBlock(world, i + 21, j + 18, k + 37, block);
        this.setBlock(world, i + 21, j + 19, k + 2, block);
        this.setBlock(world, i + 21, j + 19, k + 36, block);
        this.setBlock(world, i + 21, j + 20, k + 2, block);
        this.setBlock(world, i + 21, j + 20, k + 36, block);
        this.setBlock(world, i + 21, j + 21, k + 2, block);
        this.setBlock(world, i + 21, j + 21, k + 36, block);
        this.setBlock(world, i + 21, j + 22, k + 3, block);
        this.setBlock(world, i + 21, j + 22, k + 35, block);
        this.setBlock(world, i + 21, j + 23, k + 4, block);
        this.setBlock(world, i + 21, j + 23, k + 34, block);
        this.setBlock(world, i + 21, j + 24, k + 4, block);
        this.setBlock(world, i + 21, j + 24, k + 34, block);
        this.setBlock(world, i + 21, j + 25, k + 5, block);
        this.setBlock(world, i + 21, j + 25, k + 33, block);
        this.setBlock(world, i + 21, j + 26, k + 6, block);
        this.setBlock(world, i + 21, j + 26, k + 7, block);
        this.setBlock(world, i + 21, j + 26, k + 31, block);
        this.setBlock(world, i + 21, j + 26, k + 32, block);
        this.setBlock(world, i + 21, j + 27, k + 8, block);
        this.setBlock(world, i + 21, j + 27, k + 30, block);
        this.setBlock(world, i + 21, j + 28, k + 9, block);
        this.setBlock(world, i + 21, j + 28, k + 10, block);
        this.setBlock(world, i + 21, j + 28, k + 11, block);
        this.setBlock(world, i + 21, j + 28, k + 27, block);
        this.setBlock(world, i + 21, j + 28, k + 28, block);
        this.setBlock(world, i + 21, j + 28, k + 29, block);
        this.setBlock(world, i + 21, j + 29, k + 12, block);
        this.setBlock(world, i + 21, j + 29, k + 13, block);
        this.setBlock(world, i + 21, j + 29, k + 14, block);
        this.setBlock(world, i + 21, j + 29, k + 24, block);
        this.setBlock(world, i + 21, j + 29, k + 25, block);
        this.setBlock(world, i + 21, j + 29, k + 26, block);
        this.setBlock(world, i + 21, j + 30, k + 15, block);
        this.setBlock(world, i + 21, j + 30, k + 16, block);
        this.setBlock(world, i + 21, j + 30, k + 17, block);
        this.setBlock(world, i + 21, j + 30, k + 18, block);
        this.setBlock(world, i + 21, j + 30, k + 19, block);
        this.setBlock(world, i + 21, j + 30, k + 20, block);
        this.setBlock(world, i + 21, j + 30, k + 21, block);
        this.setBlock(world, i + 21, j + 30, k + 22, block);
        this.setBlock(world, i + 21, j + 30, k + 23, block);
        this.setBlock(world, i + 22, j + 1, k + 15, block);
        this.setBlock(world, i + 22, j + 1, k + 16, block);
        this.setBlock(world, i + 22, j + 1, k + 17, block);
        this.setBlock(world, i + 22, j + 1, k + 18, block);
        this.setBlock(world, i + 22, j + 1, k + 19, block);
        this.setBlock(world, i + 22, j + 1, k + 20, block);
        this.setBlock(world, i + 22, j + 1, k + 21, block);
        this.setBlock(world, i + 22, j + 1, k + 22, block);
        this.setBlock(world, i + 22, j + 1, k + 23, block);
        this.setBlock(world, i + 22, j + 2, k + 11, block);
        this.setBlock(world, i + 22, j + 2, k + 12, block);
        this.setBlock(world, i + 22, j + 2, k + 13, block);
        this.setBlock(world, i + 22, j + 2, k + 14, block);
        this.setBlock(world, i + 22, j + 2, k + 24, block);
        this.setBlock(world, i + 22, j + 2, k + 25, block);
        this.setBlock(world, i + 22, j + 2, k + 26, block);
        this.setBlock(world, i + 22, j + 2, k + 27, block);
        this.setBlock(world, i + 22, j + 3, k + 9, block);
        this.setBlock(world, i + 22, j + 3, k + 10, block);
        this.setBlock(world, i + 22, j + 3, k + 28, block);
        this.setBlock(world, i + 22, j + 3, k + 29, block);
        this.setBlock(world, i + 22, j + 4, k + 8, block);
        this.setBlock(world, i + 22, j + 4, k + 30, block);
        this.setBlock(world, i + 22, j + 5, k + 6, block);
        this.setBlock(world, i + 22, j + 5, k + 7, block);
        this.setBlock(world, i + 22, j + 5, k + 31, block);
        this.setBlock(world, i + 22, j + 5, k + 32, block);
        this.setBlock(world, i + 22, j + 6, k + 5, block);
        this.setBlock(world, i + 22, j + 6, k + 33, block);
        this.setBlock(world, i + 22, j + 7, k + 4, block);
        this.setBlock(world, i + 22, j + 7, k + 34, block);
        this.setBlock(world, i + 22, j + 8, k + 4, block);
        this.setBlock(world, i + 22, j + 8, k + 34, block);
        this.setBlock(world, i + 22, j + 9, k + 3, block);
        this.setBlock(world, i + 22, j + 9, k + 35, block);
        this.setBlock(world, i + 22, j + 10, k + 2, block);
        this.setBlock(world, i + 22, j + 10, k + 36, block);
        this.setBlock(world, i + 22, j + 11, k + 2, block);
        this.setBlock(world, i + 22, j + 11, k + 36, block);
        this.setBlock(world, i + 22, j + 12, k + 2, block);
        this.setBlock(world, i + 22, j + 12, k + 36, block);
        this.setBlock(world, i + 22, j + 13, k + 1, block);
        this.setBlock(world, i + 22, j + 13, k + 37, block);
        this.setBlock(world, i + 22, j + 14, k + 1, block);
        this.setBlock(world, i + 22, j + 14, k + 37, block);
        this.setBlock(world, i + 22, j + 15, k + 1, block);
        this.setBlock(world, i + 22, j + 15, k + 37, block);
        this.setBlock(world, i + 22, j + 16, k + 1, block);
        this.setBlock(world, i + 22, j + 16, k + 37, block);
        this.setBlock(world, i + 22, j + 17, k + 1, block);
        this.setBlock(world, i + 22, j + 17, k + 37, block);
        this.setBlock(world, i + 22, j + 18, k + 1, block);
        this.setBlock(world, i + 22, j + 18, k + 37, block);
        this.setBlock(world, i + 22, j + 19, k + 2, block);
        this.setBlock(world, i + 22, j + 19, k + 36, block);
        this.setBlock(world, i + 22, j + 20, k + 2, block);
        this.setBlock(world, i + 22, j + 20, k + 36, block);
        this.setBlock(world, i + 22, j + 21, k + 2, block);
        this.setBlock(world, i + 22, j + 21, k + 36, block);
        this.setBlock(world, i + 22, j + 22, k + 3, block);
        this.setBlock(world, i + 22, j + 22, k + 35, block);
        this.setBlock(world, i + 22, j + 23, k + 4, block);
        this.setBlock(world, i + 22, j + 23, k + 34, block);
        this.setBlock(world, i + 22, j + 24, k + 4, block);
        this.setBlock(world, i + 22, j + 24, k + 34, block);
        this.setBlock(world, i + 22, j + 25, k + 5, block);
        this.setBlock(world, i + 22, j + 25, k + 33, block);
        this.setBlock(world, i + 22, j + 26, k + 6, block);
        this.setBlock(world, i + 22, j + 26, k + 7, block);
        this.setBlock(world, i + 22, j + 26, k + 31, block);
        this.setBlock(world, i + 22, j + 26, k + 32, block);
        this.setBlock(world, i + 22, j + 27, k + 8, block);
        this.setBlock(world, i + 22, j + 27, k + 30, block);
        this.setBlock(world, i + 22, j + 28, k + 9, block);
        this.setBlock(world, i + 22, j + 28, k + 10, block);
        this.setBlock(world, i + 22, j + 28, k + 28, block);
        this.setBlock(world, i + 22, j + 28, k + 29, block);
        this.setBlock(world, i + 22, j + 29, k + 11, block);
        this.setBlock(world, i + 22, j + 29, k + 12, block);
        this.setBlock(world, i + 22, j + 29, k + 13, block);
        this.setBlock(world, i + 22, j + 29, k + 14, block);
        this.setBlock(world, i + 22, j + 29, k + 24, block);
        this.setBlock(world, i + 22, j + 29, k + 25, block);
        this.setBlock(world, i + 22, j + 29, k + 26, block);
        this.setBlock(world, i + 22, j + 29, k + 27, block);
        this.setBlock(world, i + 22, j + 30, k + 15, block);
        this.setBlock(world, i + 22, j + 30, k + 16, block);
        this.setBlock(world, i + 22, j + 30, k + 17, block);
        this.setBlock(world, i + 22, j + 30, k + 18, block);
        this.setBlock(world, i + 22, j + 30, k + 19, block);
        this.setBlock(world, i + 22, j + 30, k + 20, block);
        this.setBlock(world, i + 22, j + 30, k + 21, block);
        this.setBlock(world, i + 22, j + 30, k + 22, block);
        this.setBlock(world, i + 22, j + 30, k + 23, block);
        this.setBlock(world, i + 23, j + 1, k + 15, block);
        this.setBlock(world, i + 23, j + 1, k + 16, block);
        this.setBlock(world, i + 23, j + 1, k + 17, block);
        this.setBlock(world, i + 23, j + 1, k + 18, block);
        this.setBlock(world, i + 23, j + 1, k + 19, block);
        this.setBlock(world, i + 23, j + 1, k + 20, block);
        this.setBlock(world, i + 23, j + 1, k + 21, block);
        this.setBlock(world, i + 23, j + 1, k + 22, block);
        this.setBlock(world, i + 23, j + 1, k + 23, block);
        this.setBlock(world, i + 23, j + 2, k + 11, block);
        this.setBlock(world, i + 23, j + 2, k + 12, block);
        this.setBlock(world, i + 23, j + 2, k + 13, block);
        this.setBlock(world, i + 23, j + 2, k + 14, block);
        this.setBlock(world, i + 23, j + 2, k + 24, block);
        this.setBlock(world, i + 23, j + 2, k + 25, block);
        this.setBlock(world, i + 23, j + 2, k + 26, block);
        this.setBlock(world, i + 23, j + 2, k + 27, block);
        this.setBlock(world, i + 23, j + 3, k + 9, block);
        this.setBlock(world, i + 23, j + 3, k + 10, block);
        this.setBlock(world, i + 23, j + 3, k + 28, block);
        this.setBlock(world, i + 23, j + 3, k + 29, block);
        this.setBlock(world, i + 23, j + 4, k + 8, block);
        this.setBlock(world, i + 23, j + 4, k + 30, block);
        this.setBlock(world, i + 23, j + 5, k + 6, block);
        this.setBlock(world, i + 23, j + 5, k + 7, block);
        this.setBlock(world, i + 23, j + 5, k + 31, block);
        this.setBlock(world, i + 23, j + 5, k + 32, block);
        this.setBlock(world, i + 23, j + 6, k + 5, block);
        this.setBlock(world, i + 23, j + 6, k + 33, block);
        this.setBlock(world, i + 23, j + 7, k + 4, block);
        this.setBlock(world, i + 23, j + 7, k + 34, block);
        this.setBlock(world, i + 23, j + 8, k + 3, block);
        this.setBlock(world, i + 23, j + 8, k + 35, block);
        this.setBlock(world, i + 23, j + 9, k + 3, block);

        generate2(world, i, j, k, block);
        return true;
    }

    public boolean generate2(World world, int i, int j, int k, Block block) {
        this.setBlock(world, i + 23, j + 9, k + 35, block);
        this.setBlock(world, i + 23, j + 10, k + 2, block);
        this.setBlock(world, i + 23, j + 10, k + 36, block);
        this.setBlock(world, i + 23, j + 11, k + 2, block);
        this.setBlock(world, i + 23, j + 11, k + 36, block);
        this.setBlock(world, i + 23, j + 12, k + 2, block);
        this.setBlock(world, i + 23, j + 12, k + 36, block);
        this.setBlock(world, i + 23, j + 13, k + 1, block);
        this.setBlock(world, i + 23, j + 13, k + 37, block);
        this.setBlock(world, i + 23, j + 14, k + 1, block);
        this.setBlock(world, i + 23, j + 14, k + 37, block);
        this.setBlock(world, i + 23, j + 15, k + 1, block);
        this.setBlock(world, i + 23, j + 15, k + 37, block);
        this.setBlock(world, i + 23, j + 16, k + 1, block);
        this.setBlock(world, i + 23, j + 16, k + 37, block);
        this.setBlock(world, i + 23, j + 17, k + 1, block);
        this.setBlock(world, i + 23, j + 17, k + 37, block);
        this.setBlock(world, i + 23, j + 18, k + 1, block);
        this.setBlock(world, i + 23, j + 18, k + 37, block);
        this.setBlock(world, i + 23, j + 19, k + 2, block);
        this.setBlock(world, i + 23, j + 19, k + 36, block);
        this.setBlock(world, i + 23, j + 20, k + 2, block);
        this.setBlock(world, i + 23, j + 20, k + 36, block);
        this.setBlock(world, i + 23, j + 21, k + 2, block);
        this.setBlock(world, i + 23, j + 21, k + 36, block);
        this.setBlock(world, i + 23, j + 22, k + 3, block);
        this.setBlock(world, i + 23, j + 22, k + 35, block);
        this.setBlock(world, i + 23, j + 23, k + 3, block);
        this.setBlock(world, i + 23, j + 23, k + 35, block);
        this.setBlock(world, i + 23, j + 24, k + 4, block);
        this.setBlock(world, i + 23, j + 24, k + 34, block);
        this.setBlock(world, i + 23, j + 25, k + 5, block);
        this.setBlock(world, i + 23, j + 25, k + 33, block);
        this.setBlock(world, i + 23, j + 26, k + 6, block);
        this.setBlock(world, i + 23, j + 26, k + 7, block);
        this.setBlock(world, i + 23, j + 26, k + 31, block);
        this.setBlock(world, i + 23, j + 26, k + 32, block);
        this.setBlock(world, i + 23, j + 27, k + 8, block);
        this.setBlock(world, i + 23, j + 27, k + 30, block);
        this.setBlock(world, i + 23, j + 28, k + 9, block);
        this.setBlock(world, i + 23, j + 28, k + 10, block);
        this.setBlock(world, i + 23, j + 28, k + 28, block);
        this.setBlock(world, i + 23, j + 28, k + 29, block);
        this.setBlock(world, i + 23, j + 29, k + 11, block);
        this.setBlock(world, i + 23, j + 29, k + 12, block);
        this.setBlock(world, i + 23, j + 29, k + 13, block);
        this.setBlock(world, i + 23, j + 29, k + 14, block);
        this.setBlock(world, i + 23, j + 29, k + 24, block);
        this.setBlock(world, i + 23, j + 29, k + 25, block);
        this.setBlock(world, i + 23, j + 29, k + 26, block);
        this.setBlock(world, i + 23, j + 29, k + 27, block);
        this.setBlock(world, i + 23, j + 30, k + 15, block);
        this.setBlock(world, i + 23, j + 30, k + 16, block);
        this.setBlock(world, i + 23, j + 30, k + 17, block);
        this.setBlock(world, i + 23, j + 30, k + 18, block);
        this.setBlock(world, i + 23, j + 30, k + 19, block);
        this.setBlock(world, i + 23, j + 30, k + 20, block);
        this.setBlock(world, i + 23, j + 30, k + 21, block);
        this.setBlock(world, i + 23, j + 30, k + 22, block);
        this.setBlock(world, i + 23, j + 30, k + 23, block);
        this.setBlock(world, i + 24, j + 1, k + 15, block);
        this.setBlock(world, i + 24, j + 1, k + 16, block);
        this.setBlock(world, i + 24, j + 1, k + 17, block);
        this.setBlock(world, i + 24, j + 1, k + 18, block);
        this.setBlock(world, i + 24, j + 1, k + 19, block);
        this.setBlock(world, i + 24, j + 1, k + 20, block);
        this.setBlock(world, i + 24, j + 1, k + 21, block);
        this.setBlock(world, i + 24, j + 1, k + 22, block);
        this.setBlock(world, i + 24, j + 1, k + 23, block);
        this.setBlock(world, i + 24, j + 2, k + 11, block);
        this.setBlock(world, i + 24, j + 2, k + 12, block);
        this.setBlock(world, i + 24, j + 2, k + 13, block);
        this.setBlock(world, i + 24, j + 2, k + 14, block);
        this.setBlock(world, i + 24, j + 2, k + 24, block);
        this.setBlock(world, i + 24, j + 2, k + 25, block);
        this.setBlock(world, i + 24, j + 2, k + 26, block);
        this.setBlock(world, i + 24, j + 2, k + 27, block);
        this.setBlock(world, i + 24, j + 3, k + 9, block);
        this.setBlock(world, i + 24, j + 3, k + 10, block);
        this.setBlock(world, i + 24, j + 3, k + 28, block);
        this.setBlock(world, i + 24, j + 3, k + 29, block);
        this.setBlock(world, i + 24, j + 4, k + 8, block);
        this.setBlock(world, i + 24, j + 4, k + 30, block);
        this.setBlock(world, i + 24, j + 5, k + 6, block);
        this.setBlock(world, i + 24, j + 5, k + 7, block);
        this.setBlock(world, i + 24, j + 5, k + 31, block);
        this.setBlock(world, i + 24, j + 5, k + 32, block);
        this.setBlock(world, i + 24, j + 6, k + 5, block);
        this.setBlock(world, i + 24, j + 6, k + 33, block);
        this.setBlock(world, i + 24, j + 7, k + 4, block);
        this.setBlock(world, i + 24, j + 7, k + 34, block);
        this.setBlock(world, i + 24, j + 8, k + 4, block);
        this.setBlock(world, i + 24, j + 8, k + 34, block);
        this.setBlock(world, i + 24, j + 9, k + 3, block);
        this.setBlock(world, i + 24, j + 9, k + 35, block);
        this.setBlock(world, i + 24, j + 10, k + 2, block);
        this.setBlock(world, i + 24, j + 10, k + 36, block);
        this.setBlock(world, i + 24, j + 11, k + 2, block);
        this.setBlock(world, i + 24, j + 11, k + 36, block);
        this.setBlock(world, i + 24, j + 12, k + 2, block);
        this.setBlock(world, i + 24, j + 12, k + 36, block);
        this.setBlock(world, i + 24, j + 13, k + 1, block);
        this.setBlock(world, i + 24, j + 13, k + 37, block);
        this.setBlock(world, i + 24, j + 14, k + 1, block);
        this.setBlock(world, i + 24, j + 14, k + 37, block);
        this.setBlock(world, i + 24, j + 15, k + 1, block);
        this.setBlock(world, i + 24, j + 15, k + 37, block);
        this.setBlock(world, i + 24, j + 16, k + 1, block);
        this.setBlock(world, i + 24, j + 16, k + 37, block);
        this.setBlock(world, i + 24, j + 17, k + 1, block);
        this.setBlock(world, i + 24, j + 17, k + 37, block);
        this.setBlock(world, i + 24, j + 18, k + 1, block);
        this.setBlock(world, i + 24, j + 18, k + 37, block);
        this.setBlock(world, i + 24, j + 19, k + 2, block);
        this.setBlock(world, i + 24, j + 19, k + 36, block);
        this.setBlock(world, i + 24, j + 20, k + 2, block);
        this.setBlock(world, i + 24, j + 20, k + 36, block);
        this.setBlock(world, i + 24, j + 21, k + 2, block);
        this.setBlock(world, i + 24, j + 21, k + 36, block);
        this.setBlock(world, i + 24, j + 22, k + 3, block);
        this.setBlock(world, i + 24, j + 22, k + 35, block);
        this.setBlock(world, i + 24, j + 23, k + 4, block);
        this.setBlock(world, i + 24, j + 23, k + 34, block);
        this.setBlock(world, i + 24, j + 24, k + 4, block);
        this.setBlock(world, i + 24, j + 24, k + 34, block);
        this.setBlock(world, i + 24, j + 25, k + 5, block);
        this.setBlock(world, i + 24, j + 25, k + 33, block);
        this.setBlock(world, i + 24, j + 26, k + 6, block);
        this.setBlock(world, i + 24, j + 26, k + 7, block);
        this.setBlock(world, i + 24, j + 26, k + 31, block);
        this.setBlock(world, i + 24, j + 26, k + 32, block);
        this.setBlock(world, i + 24, j + 27, k + 8, block);
        this.setBlock(world, i + 24, j + 27, k + 30, block);
        this.setBlock(world, i + 24, j + 28, k + 9, block);
        this.setBlock(world, i + 24, j + 28, k + 10, block);
        this.setBlock(world, i + 24, j + 28, k + 28, block);
        this.setBlock(world, i + 24, j + 28, k + 29, block);
        this.setBlock(world, i + 24, j + 29, k + 11, block);
        this.setBlock(world, i + 24, j + 29, k + 12, block);
        this.setBlock(world, i + 24, j + 29, k + 13, block);
        this.setBlock(world, i + 24, j + 29, k + 14, block);
