/*
*** MADE BY MRPONYCAPTAIN'S .SCHEMATIC TO .JAVA CONVERTING TOOL v2.0 ***
*/

package georgetsak.opcraft.common.generator.terrain;

import georgetsak.opcraft.common.registry.OPBlocks;
import net.minecraft.block.Block;
import net.minecraft.util.math.BlockPos;
import net.minecraft.world.World;
import net.minecraft.world.gen.feature.WorldGenerator;

import java.util.Random;

public class WorldGenAdamTree extends WorldGenerator {

	public void setBlock(World world, int x, int y, int z, Block block, int metadata)
	{

		world.setBlockState(new BlockPos(x,y,z), block.getDefaultState());
	
	}

	public void generate(World world, Random rand, int i, int j, int k) {
		//check that each corner is one of the valid spawn block
		k = k - 10;
		i = i - 10;

		this.setBlock(world, i + 0, j + 12, k + 5, OPBlocks.BlockAdamTreeLeaves, 0);
		this.setBlock(world, i + 1, j + 11, k + 6, OPBlocks.BlockAdamTreeLeaves, 0);
		this.setBlock(world, i + 1, j + 11, k + 10, OPBlocks.BlockAdamTreeLeaves, 0);
		this.setBlock(world, i + 1, j + 12, k + 5, OPBlocks.BlockAdamTreeLeaves, 0);
		this.setBlock(world, i + 1, j + 12, k + 6, OPBlocks.BlockAdamTreeLeaves, 0);
		this.setBlock(world, i + 2, j + 10, k + 7, OPBlocks.BlockAdamTreeLeaves, 0);
		this.setBlock(world, i + 2, j + 10, k + 10, OPBlocks.BlockAdamTreeLeaves, 0);
		this.setBlock(world, i + 2, j + 11, k + 7, OPBlocks.BlockAdamTreeLeaves, 0);
		this.setBlock(world, i + 2, j + 11, k + 9, OPBlocks.BlockAdamTreeLeaves, 0);
		this.setBlock(world, i + 2, j + 11, k + 10, OPBlocks.BlockAdamTreeLeaves, 0);
		this.setBlock(world, i + 2, j + 12, k + 6, OPBlocks.BlockAdamTreeLeaves, 0);
		this.setBlock(world, i + 2, j + 12, k + 7, OPBlocks.BlockAdamTreeLeaves, 0);
		this.setBlock(world, i + 2, j + 12, k + 9, OPBlocks.BlockAdamTreeLeaves, 0);
		this.setBlock(world, i + 2, j + 13, k + 6, OPBlocks.BlockAdamTreeLeaves, 0);
		this.setBlock(world, i + 2, j + 14, k + 6, OPBlocks.BlockAdamTreeLeaves, 0);
		this.setBlock(world, i + 2, j + 14, k + 16, OPBlocks.BlockAdamTreeLeaves, 0);
		this.setBlock(world, i + 2, j + 15, k + 2, OPBlocks.BlockAdamTreeLeaves, 0);
		this.setBlock(world, i + 2, j + 15, k + 4, OPBlocks.BlockAdamTreeLeaves, 0);
		this.setBlock(world, i + 2, j + 15, k + 6, OPBlocks.BlockAdamTreeLeaves, 0);
		this.setBlock(world, i + 3, j + 9, k + 3, OPBlocks.BlockAdamTreeLeaves, 0);
		this.setBlock(world, i + 3, j + 10, k + 3, OPBlocks.BlockAdamTreeLeaves, 0);
		this.setBlock(world, i + 3, j + 10, k + 7, OPBlocks.BlockAdamTreeLeaves, 0);
		this.setBlock(world, i + 3, j + 10, k + 8, OPBlocks.BlockAdamTreeLeaves, 0);
		this.setBlock(world, i + 3, j + 11, k + 7, OPBlocks.BlockAdamTreeLeaves, 0);
		this.setBlock(world, i + 3, j + 11, k + 8, OPBlocks.BlockAdamTreeLeaves, 0);
		this.setBlock(world, i + 3, j + 11, k + 10, OPBlocks.BlockAdamTreeLeaves, 0);
		this.setBlock(world, i + 3, j + 12, k + 5, OPBlocks.BlockAdamTreeLeaves, 0);
		this.setBlock(world, i + 3, j + 12, k + 8, OPBlocks.BlockAdamTreeLeaves, 0);
		this.setBlock(world, i + 3, j + 12, k + 10, OPBlocks.BlockAdamTreeLeaves, 0);
		this.setBlock(world, i + 3, j + 12, k + 11, OPBlocks.BlockAdamTreeLeaves, 0);
		this.setBlock(world, i + 3, j + 13, k + 5, OPBlocks.BlockAdamTreeLeaves, 0);
		this.setBlock(world, i + 3, j + 13, k + 6, OPBlocks.BlockAdamTreeLeaves, 0);
		this.setBlock(world, i + 3, j + 13, k + 8, OPBlocks.BlockAdamTreeLeaves, 0);
		this.setBlock(world, i + 3, j + 13, k + 16, OPBlocks.BlockAdamTreeLeaves, 0);
		this.setBlock(world, i + 3, j + 14, k + 2, OPBlocks.BlockAdamTreeLeaves, 0);
		this.setBlock(world, i + 3, j + 14, k + 3, OPBlocks.BlockAdamTreeLeaves, 0);
		this.setBlock(world, i + 3, j + 14, k + 5, OPBlocks.BlockAdamTreeLeaves, 0);
		this.setBlock(world, i + 3, j + 14, k + 6, OPBlocks.BlockAdamTreeLeaves, 0);
		this.setBlock(world, i + 3, j + 14, k + 8, OPBlocks.BlockAdamTreeLeaves, 0);
		this.setBlock(world, i + 3, j + 14, k + 15, OPBlocks.BlockAdamTreeLeaves, 0);
		this.setBlock(world, i + 3, j + 14, k + 16, OPBlocks.BlockAdamTreeLeaves, 0);
		this.setBlock(world, i + 3, j + 15, k + 7, OPBlocks.BlockAdamTreeLeaves, 0);
		this.setBlock(world, i + 3, j + 15, k + 8, OPBlocks.BlockAdamTreeLeaves, 0);
		this.setBlock(world, i + 4, j + 9, k + 3, OPBlocks.BlockAdamTreeLeaves, 0);
		this.setBlock(world, i + 4, j + 9, k + 4, OPBlocks.BlockAdamTreeLeaves, 0);
		this.setBlock(world, i + 4, j + 9, k + 10, OPBlocks.BlockAdamTreeLeaves, 0);
		this.setBlock(world, i + 4, j + 10, k + 2, OPBlocks.BlockAdamTreeLeaves, 0);
		this.setBlock(world, i + 4, j + 10, k + 3, OPBlocks.BlockAdamTreeLeaves, 0);
		this.setBlock(world, i + 4, j + 10, k + 4, OPBlocks.BlockAdamTreeLeaves, 0);
		this.setBlock(world, i + 4, j + 10, k + 7, OPBlocks.BlockAdamTreeWood, 0);
		this.setBlock(world, i + 4, j + 10, k + 8, OPBlocks.BlockAdamTreeLeaves, 0);
		this.setBlock(world, i + 4, j + 10, k + 9, OPBlocks.BlockAdamTreeLeaves, 0);
		this.setBlock(world, i + 4, j + 10, k + 10, OPBlocks.BlockAdamTreeLeaves, 0);
		this.setBlock(world, i + 4, j + 11, k + 4, OPBlocks.BlockAdamTreeLeaves, 0);
		this.setBlock(world, i + 4, j + 11, k + 7, OPBlocks.BlockAdamTreeLeaves, 0);
		this.setBlock(world, i + 4, j + 11, k + 8, OPBlocks.BlockAdamTreeLeaves, 0);
		this.setBlock(world, i + 4, j + 11, k + 9, OPBlocks.BlockAdamTreeLeaves, 0);
		this.setBlock(world, i + 4, j + 11, k + 10, OPBlocks.BlockAdamTreeLeaves, 0);
		this.setBlock(world, i + 4, j + 11, k + 12, OPBlocks.BlockAdamTreeLeaves, 0);
		this.setBlock(world, i + 4, j + 12, k + 5, OPBlocks.BlockAdamTreeLeaves, 0);
		this.setBlock(world, i + 4, j + 12, k + 9, OPBlocks.BlockAdamTreeLeaves, 0);
		this.setBlock(world, i + 4, j + 12, k + 10, OPBlocks.BlockAdamTreeLeaves, 0);
		this.setBlock(world, i + 4, j + 12, k + 11, OPBlocks.BlockAdamTreeLeaves, 0);
		this.setBlock(world, i + 4, j + 13, k + 3, OPBlocks.BlockAdamTreeLeaves, 0);
		this.setBlock(world, i + 4, j + 13, k + 4, OPBlocks.BlockAdamTreeLeaves, 0);
		this.setBlock(world, i + 4, j + 13, k + 5, OPBlocks.BlockAdamTreeLeaves, 0);
		this.setBlock(world, i + 4, j + 13, k + 6, OPBlocks.BlockAdamTreeLeaves, 0);
		this.setBlock(world, i + 4, j + 14, k + 3, OPBlocks.BlockAdamTreeLeaves, 0);
		this.setBlock(world, i + 4, j + 14, k + 6, OPBlocks.BlockAdamTreeWood, 0);
		this.setBlock(world, i + 4, j + 14, k + 7, OPBlocks.BlockAdamTreeLeaves, 0);
		this.setBlock(world, i + 4, j + 14, k + 8, OPBlocks.BlockAdamTreeLeaves, 0);
		this.setBlock(world, i + 4, j + 14, k + 9, OPBlocks.BlockAdamTreeLeaves, 0);
		this.setBlock(world, i + 4, j + 14, k + 14, OPBlocks.BlockAdamTreeLeaves, 0);
		this.setBlock(world, i + 4, j + 14, k + 15, OPBlocks.BlockAdamTreeLeaves, 0);
		this.setBlock(world, i + 4, j + 15, k + 6, OPBlocks.BlockAdamTreeLeaves, 0);
		this.setBlock(world, i + 4, j + 15, k + 7, OPBlocks.BlockAdamTreeLeaves, 0);
		this.setBlock(world, i + 4, j + 16, k + 5, OPBlocks.BlockAdamTreeLeaves, 0);
		this.setBlock(world, i + 4, j + 16, k + 6, OPBlocks.BlockAdamTreeLeaves, 0);
		this.setBlock(world, i + 4, j + 17, k + 6, OPBlocks.BlockAdamTreeLeaves, 0);
		this.setBlock(world, i + 5, j + 6, k + 8, OPBlocks.BlockAdamTreeWood, 0);
		this.setBlock(world, i + 5, j + 7, k + 8, OPBlocks.BlockAdamTreeWood, 0);
		this.setBlock(world, i + 5, j + 8, k + 8, OPBlocks.BlockAdamTreeLeaves, 0);
		this.setBlock(world, i + 5, j + 8, k + 9, OPBlocks.BlockAdamTreeLeaves, 0);
		this.setBlock(world, i + 5, j + 8, k + 12, OPBlocks.BlockAdamTreeLeaves, 0);
		this.setBlock(world, i + 5, j + 9, k + 2, OPBlocks.BlockAdamTreeLeaves, 0);
		this.setBlock(world, i + 5, j + 9, k + 3, OPBlocks.BlockAdamTreeLeaves, 0);
		this.setBlock(world, i + 5, j + 9, k + 6, OPBlocks.BlockAdamTreeLeaves, 0);
		this.setBlock(world, i + 5, j + 9, k + 7, OPBlocks.BlockAdamTreeWood, 0);
		this.setBlock(world, i + 5, j + 9, k + 8, OPBlocks.BlockAdamTreeLeaves, 0);
		this.setBlock(world, i + 5, j + 9, k + 9, OPBlocks.BlockAdamTreeLeaves, 0);
		this.setBlock(world, i + 5, j + 9, k + 12, OPBlocks.BlockAdamTreeLeaves, 0);
		this.setBlock(world, i + 5, j + 10, k + 2, OPBlocks.BlockAdamTreeLeaves, 0);
		this.setBlock(world, i + 5, j + 10, k + 3, OPBlocks.BlockAdamTreeLeaves, 0);
		this.setBlock(world, i + 5, j + 10, k + 4, OPBlocks.BlockAdamTreeLeaves, 0);
		this.setBlock(world, i + 5, j + 10, k + 5, OPBlocks.BlockAdamTreeLeaves, 0);
		this.setBlock(world, i + 5, j + 10, k + 6, OPBlocks.BlockAdamTreeLeaves, 0);
		this.setBlock(world, i + 5, j + 10, k + 7, OPBlocks.BlockAdamTreeLeaves, 0);
		this.setBlock(world, i + 5, j + 10, k + 8, OPBlocks.BlockAdamTreeLeaves, 0);
		this.setBlock(world, i + 5, j + 10, k + 9, OPBlocks.BlockAdamTreeLeaves, 0);
		this.setBlock(world, i + 5, j + 10, k + 10, OPBlocks.BlockAdamTreeLeaves, 0);
		this.setBlock(world, i + 5, j + 10, k + 12, OPBlocks.BlockAdamTreeLeaves, 0);
		this.setBlock(world, i + 5, j + 11, k + 1, OPBlocks.BlockAdamTreeLeaves, 0);
		this.setBlock(world, i + 5, j + 11, k + 4, OPBlocks.BlockAdamTreeLeaves, 0);
		this.setBlock(world, i + 5, j + 11, k + 5, OPBlocks.BlockAdamTreeLeaves, 0);
		this.setBlock(world, i + 5, j + 11, k + 6, OPBlocks.BlockAdamTreeLeaves, 0);
		this.setBlock(world, i + 5, j + 11, k + 8, OPBlocks.BlockAdamTreeLeaves, 0);
		this.setBlock(world, i + 5, j + 11, k + 9, OPBlocks.BlockAdamTreeLeaves, 0);
		this.setBlock(world, i + 5, j + 11, k + 10, OPBlocks.BlockAdamTreeLeaves, 0);
		this.setBlock(world, i + 5, j + 11, k + 11, OPBlocks.BlockAdamTreeLeaves, 0);
		this.setBlock(world, i + 5, j + 11, k + 13, OPBlocks.BlockAdamTreeLeaves, 0);
		this.setBlock(world, i + 5, j + 12, k + 6, OPBlocks.BlockAdamTreeLeaves, 0);
		this.setBlock(world, i + 5, j + 12, k + 7, OPBlocks.BlockAdamTreeLeaves, 0);
		this.setBlock(world, i + 5, j + 12, k + 9, OPBlocks.BlockAdamTreeLeaves, 0);
		this.setBlock(world, i + 5, j + 12, k + 10, OPBlocks.BlockAdamTreeLeaves, 0);
		this.setBlock(world, i + 5, j + 12, k + 11, OPBlocks.BlockAdamTreeLeaves, 0);
		this.setBlock(world, i + 5, j + 12, k + 12, OPBlocks.BlockAdamTreeLeaves, 0);
		this.setBlock(world, i + 5, j + 12, k + 13, OPBlocks.BlockAdamTreeLeaves, 0);
		this.setBlock(world, i + 5, j + 13, k + 0, OPBlocks.BlockAdamTreeLeaves, 0);
		this.setBlock(world, i + 5, j + 13, k + 4, OPBlocks.BlockAdamTreeLeaves, 0);
		this.setBlock(world, i + 5, j + 13, k + 5, OPBlocks.BlockAdamTreeLeaves, 0);
		this.setBlock(world, i + 5, j + 13, k + 6, OPBlocks.BlockAdamTreeLeaves, 0);
		this.setBlock(world, i + 5, j + 13, k + 7, OPBlocks.BlockAdamTreeLeaves, 0);
		this.setBlock(world, i + 5, j + 13, k + 8, OPBlocks.BlockAdamTreeLeaves, 0);
		this.setBlock(world, i + 5, j + 13, k + 9, OPBlocks.BlockAdamTreeLeaves, 0);
		this.setBlock(world, i + 5, j + 13, k + 10, OPBlocks.BlockAdamTreeLeaves, 0);
		this.setBlock(world, i + 5, j + 13, k + 12, OPBlocks.BlockAdamTreeLeaves, 0);
		this.setBlock(world, i + 5, j + 14, k + 0, OPBlocks.BlockAdamTreeLeaves, 0);
		this.setBlock(world, i + 5, j + 14, k + 1, OPBlocks.BlockAdamTreeLeaves, 0);
		this.setBlock(world, i + 5, j + 14, k + 4, OPBlocks.BlockAdamTreeLeaves, 0);
		this.setBlock(world, i + 5, j + 14, k + 6, OPBlocks.BlockAdamTreeLeaves, 0);
		this.setBlock(world, i + 5, j + 14, k + 7, OPBlocks.BlockAdamTreeLeaves, 0);
		this.setBlock(world, i + 5, j + 14, k + 8, OPBlocks.BlockAdamTreeLeaves, 0);
		this.setBlock(world, i + 5, j + 14, k + 10, OPBlocks.BlockAdamTreeLeaves, 0);
		this.setBlock(world, i + 5, j + 14, k + 11, OPBlocks.BlockAdamTreeLeaves, 0);
		this.setBlock(world, i + 5, j + 14, k + 13, OPBlocks.BlockAdamTreeLeaves, 0);
		this.setBlock(world, i + 5, j + 14, k + 14, OPBlocks.BlockAdamTreeLeaves, 0);
		this.setBlock(world, i + 5, j + 15, k + 4, OPBlocks.BlockAdamTreeLeaves, 0);
		this.setBlock(world, i + 5, j + 15, k + 5, OPBlocks.BlockAdamTreeLeaves, 0);
		this.setBlock(world, i + 5, j + 15, k + 6, OPBlocks.BlockAdamTreeLeaves, 0);
		this.setBlock(world, i + 5, j + 15, k + 7, OPBlocks.BlockAdamTreeLeaves, 0);
		this.setBlock(world, i + 5, j + 15, k + 8, OPBlocks.BlockAdamTreeLeaves, 0);
		this.setBlock(world, i + 5, j + 17, k + 6, OPBlocks.BlockAdamTreeLeaves, 0);
		this.setBlock(world, i + 6, j + 0, k + 6, OPBlocks.BlockAdamTreeWood, 0);
		this.setBlock(world, i + 6, j + 0, k + 7, OPBlocks.BlockAdamTreeWood, 0);
		this.setBlock(world, i + 6, j + 1, k + 6, OPBlocks.BlockAdamTreeWood, 0);
		this.setBlock(world, i + 6, j + 7, k + 7, OPBlocks.BlockAdamTreeWood, 0);
		this.setBlock(world, i + 6, j + 8, k + 7, OPBlocks.BlockAdamTreeWood, 0);
		this.setBlock(world, i + 6, j + 8, k + 12, OPBlocks.BlockAdamTreeLeaves, 0);
		this.setBlock(world, i + 6, j + 9, k + 4, OPBlocks.BlockAdamTreeLeaves, 0);
		this.setBlock(world, i + 6, j + 9, k + 5, OPBlocks.BlockAdamTreeWood, 0);
		this.setBlock(world, i + 6, j + 9, k + 6, OPBlocks.BlockAdamTreeWood, 0);
		this.setBlock(world, i + 6, j + 9, k + 7, OPBlocks.BlockAdamTreeWood, 0);
		this.setBlock(world, i + 6, j + 9, k + 8, OPBlocks.BlockAdamTreeLeaves, 0);
		this.setBlock(world, i + 6, j + 9, k + 9, OPBlocks.BlockAdamTreeLeaves, 0);
		this.setBlock(world, i + 6, j + 9, k + 12, OPBlocks.BlockAdamTreeLeaves, 0);
		this.setBlock(world, i + 6, j + 10, k + 1, OPBlocks.BlockAdamTreeLeaves, 0);
		this.setBlock(world, i + 6, j + 10, k + 2, OPBlocks.BlockAdamTreeLeaves, 0);
		this.setBlock(world, i + 6, j + 10, k + 3, OPBlocks.BlockAdamTreeLeaves, 0);
		this.setBlock(world, i + 6, j + 10, k + 4, OPBlocks.BlockAdamTreeLeaves, 0);
		this.setBlock(world, i + 6, j + 10, k + 5, OPBlocks.BlockAdamTreeLeaves, 0);
		this.setBlock(world, i + 6, j + 10, k + 6, OPBlocks.BlockAdamTreeLeaves, 0);
		this.setBlock(world, i + 6, j + 10, k + 7, OPBlocks.BlockAdamTreeLeaves, 0);
		this.setBlock(world, i + 6, j + 10, k + 8, OPBlocks.BlockAdamTreeWood, 0);
		this.setBlock(world, i + 6, j + 10, k + 9, OPBlocks.BlockAdamTreeWood, 0);
		this.setBlock(world, i + 6, j + 10, k + 10, OPBlocks.BlockAdamTreeLeaves, 0);
		this.setBlock(world, i + 6, j + 10, k + 12, OPBlocks.BlockAdamTreeLeaves, 0);
		this.setBlock(world, i + 6, j + 11, k + 1, OPBlocks.BlockAdamTreeLeaves, 0);
		this.setBlock(world, i + 6, j + 11, k + 2, OPBlocks.BlockAdamTreeLeaves, 0);
		this.setBlock(world, i + 6, j + 11, k + 3, OPBlocks.BlockAdamTreeLeaves, 0);
		this.setBlock(world, i + 6, j + 11, k + 4, OPBlocks.BlockAdamTreeLeaves, 0);
		this.setBlock(world, i + 6, j + 11, k + 5, OPBlocks.BlockAdamTreeLeaves, 0);
		this.setBlock(world, i + 6, j + 11, k + 6, OPBlocks.BlockAdamTreeLeaves, 0);
		this.setBlock(world, i + 6, j + 11, k + 7, OPBlocks.BlockAdamTreeLeaves, 0);
		this.setBlock(world, i + 6, j + 11, k + 8, OPBlocks.BlockAdamTreeLeaves, 0);
		this.setBlock(world, i + 6, j + 11, k + 9, OPBlocks.BlockAdamTreeLeaves, 0);
		this.setBlock(world, i + 6, j + 11, k + 10, OPBlocks.BlockAdamTreeLeaves, 0);
		this.setBlock(world, i + 6, j + 11, k + 11, OPBlocks.BlockAdamTreeLeaves, 0);
		this.setBlock(world, i + 6, j + 11, k + 15, OPBlocks.BlockAdamTreeLeaves, 0);
		this.setBlock(world, i + 6, j + 12, k + 2, OPBlocks.BlockAdamTreeLeaves, 0);
		this.setBlock(world, i + 6, j + 12, k + 3, OPBlocks.BlockAdamTreeLeaves, 0);
		this.setBlock(world, i + 6, j + 12, k + 4, OPBlocks.BlockAdamTreeLeaves, 0);
		this.setBlock(world, i + 6, j + 12, k + 5, OPBlocks.BlockAdamTreeLeaves, 0);
		this.setBlock(world, i + 6, j + 12, k + 6, OPBlocks.BlockAdamTreeLeaves, 0);
		this.setBlock(world, i + 6, j + 12, k + 7, OPBlocks.BlockAdamTreeLeaves, 0);
		this.setBlock(world, i + 6, j + 12, k + 8, OPBlocks.BlockAdamTreeWood, 0);
		this.setBlock(world, i + 6, j + 12, k + 9, OPBlocks.BlockAdamTreeLeaves, 0);
		this.setBlock(world, i + 6, j + 12, k + 10, OPBlocks.BlockAdamTreeLeaves, 0);
		this.setBlock(world, i + 6, j + 12, k + 11, OPBlocks.BlockAdamTreeLeaves, 0);
		this.setBlock(world, i + 6, j + 12, k + 13, OPBlocks.BlockAdamTreeLeaves, 0);
		this.setBlock(world, i + 6, j + 12, k + 14, OPBlocks.BlockAdamTreeLeaves, 0);
		this.setBlock(world, i + 6, j + 12, k + 15, OPBlocks.BlockAdamTreeLeaves, 0);
		this.setBlock(world, i + 6, j + 12, k + 16, OPBlocks.BlockAdamTreeLeaves, 0);
		this.setBlock(world, i + 6, j + 13, k + 0, OPBlocks.BlockAdamTreeLeaves, 0);
		this.setBlock(world, i + 6, j + 13, k + 1, OPBlocks.BlockAdamTreeLeaves, 0);
		this.setBlock(world, i + 6, j + 13, k + 2, OPBlocks.BlockAdamTreeLeaves, 0);
		this.setBlock(world, i + 6, j + 13, k + 3, OPBlocks.BlockAdamTreeLeaves, 0);
		this.setBlock(world, i + 6, j + 13, k + 4, OPBlocks.BlockAdamTreeLeaves, 0);
		this.setBlock(world, i + 6, j + 13, k + 5, OPBlocks.BlockAdamTreeLeaves, 0);
		this.setBlock(world, i + 6, j + 13, k + 6, OPBlocks.BlockAdamTreeLeaves, 0);
		this.setBlock(world, i + 6, j + 13, k + 7, OPBlocks.BlockAdamTreeLeaves, 0);
		this.setBlock(world, i + 6, j + 13, k + 8, OPBlocks.BlockAdamTreeLeaves, 0);
		this.setBlock(world, i + 6, j + 13, k + 9, OPBlocks.BlockAdamTreeLeaves, 0);
		this.setBlock(world, i + 6, j + 13, k + 10, OPBlocks.BlockAdamTreeLeaves, 0);
		this.setBlock(world, i + 6, j + 13, k + 11, OPBlocks.BlockAdamTreeLeaves, 0);
		this.setBlock(world, i + 6, j + 13, k + 12, OPBlocks.BlockAdamTreeLeaves, 0);
		this.setBlock(world, i + 6, j + 13, k + 15, OPBlocks.BlockAdamTreeLeaves, 0);
		this.setBlock(world, i + 6, j + 13, k + 16, OPBlocks.BlockAdamTreeLeaves, 0);
		this.setBlock(world, i + 6, j + 13, k + 17, OPBlocks.BlockAdamTreeLeaves, 0);
		this.setBlock(world, i + 6, j + 14, k + 1, OPBlocks.BlockAdamTreeLeaves, 0);
		this.setBlock(world, i + 6, j + 14, k + 2, OPBlocks.BlockAdamTreeLeaves, 0);
		this.setBlock(world, i + 6, j + 14, k + 3, OPBlocks.BlockAdamTreeLeaves, 0);
		this.setBlock(world, i + 6, j + 14, k + 4, OPBlocks.BlockAdamTreeLeaves, 0);
		this.setBlock(world, i + 6, j + 14, k + 5, OPBlocks.BlockAdamTreeLeaves, 0);
		this.setBlock(world, i + 6, j + 14, k + 6, OPBlocks.BlockAdamTreeLeaves, 0);
		this.setBlock(world, i + 6, j + 14, k + 7, OPBlocks.BlockAdamTreeWood, 0);
		this.setBlock(world, i + 6, j + 14, k + 8, OPBlocks.BlockAdamTreeLeaves, 0);
		this.setBlock(world, i + 6, j + 14, k + 9, OPBlocks.BlockAdamTreeLeaves, 0);
		this.setBlock(world, i + 6, j + 14, k + 10, OPBlocks.BlockAdamTreeLeaves, 0);
		this.setBlock(world, i + 6, j + 14, k + 11, OPBlocks.BlockAdamTreeLeaves, 0);
		this.setBlock(world, i + 6, j + 15, k + 2, OPBlocks.BlockAdamTreeLeaves, 0);
		this.setBlock(world, i + 6, j + 15, k + 4, OPBlocks.BlockAdamTreeLeaves, 0);
		this.setBlock(world, i + 6, j + 15, k + 5, OPBlocks.BlockAdamTreeLeaves, 0);
		this.setBlock(world, i + 6, j + 15, k + 6, OPBlocks.BlockAdamTreeLeaves, 0);
		this.setBlock(world, i + 6, j + 15, k + 7, OPBlocks.BlockAdamTreeLeaves, 0);
		this.setBlock(world, i + 6, j + 15, k + 8, OPBlocks.BlockAdamTreeLeaves, 0);
		this.setBlock(world, i + 6, j + 15, k + 9, OPBlocks.BlockAdamTreeLeaves, 0);
		this.setBlock(world, i + 6, j + 16, k + 4, OPBlocks.BlockAdamTreeLeaves, 0);
		this.setBlock(world, i + 6, j + 16, k + 5, OPBlocks.BlockAdamTreeLeaves, 0);
		this.setBlock(world, i + 6, j + 16, k + 7, OPBlocks.BlockAdamTreeLeaves, 0);
		this.setBlock(world, i + 6, j + 17, k + 4, OPBlocks.BlockAdamTreeLeaves, 0);
		this.setBlock(world, i + 6, j + 17, k + 6, OPBlocks.BlockAdamTreeLeaves, 0);
		this.setBlock(world, i + 6, j + 17, k + 7, OPBlocks.BlockAdamTreeLeaves, 0);
		this.setBlock(world, i + 6, j + 18, k + 7, OPBlocks.BlockAdamTreeLeaves, 0);
		this.setBlock(world, i + 6, j + 18, k + 8, OPBlocks.BlockAdamTreeLeaves, 0);
		this.setBlock(world, i + 7, j + 0, k + 4, OPBlocks.BlockAdamTreeWood, 0);
		this.setBlock(world, i + 7, j + 0, k + 5, OPBlocks.BlockAdamTreeWood, 0);
		this.setBlock(world, i + 7, j + 0, k + 6, OPBlocks.BlockAdamTreeWood, 0);
		this.setBlock(world, i + 7, j + 0, k + 7, OPBlocks.BlockAdamTreeWood, 0);
		this.setBlock(world, i + 7, j + 1, k + 4, OPBlocks.BlockAdamTreeWood, 0);
		this.setBlock(world, i + 7, j + 1, k + 6, OPBlocks.BlockAdamTreeWood, 0);
		this.setBlock(world, i + 7, j + 2, k + 6, OPBlocks.BlockAdamTreeWood, 0);
		this.setBlock(world, i + 7, j + 3, k + 6, OPBlocks.BlockAdamTreeWood, 0);
		this.setBlock(world, i + 7, j + 4, k + 6, OPBlocks.BlockAdamTreeWood, 0);
		this.setBlock(world, i + 7, j + 5, k + 6, OPBlocks.BlockAdamTreeWood, 0);
		this.setBlock(world, i + 7, j + 6, k + 6, OPBlocks.BlockAdamTreeWood, 0);
		this.setBlock(world, i + 7, j + 7, k + 6, OPBlocks.BlockAdamTreeWood, 0);
		this.setBlock(world, i + 7, j + 7, k + 8, OPBlocks.BlockAdamTreeWood, 0);
		this.setBlock(world, i + 7, j + 8, k + 5, OPBlocks.BlockAdamTreeWood, 0);
		this.setBlock(world, i + 7, j + 8, k + 6, OPBlocks.BlockAdamTreeWood, 0);
		this.setBlock(world, i + 7, j + 8, k + 7, OPBlocks.BlockAdamTreeWood, 0);
		this.setBlock(world, i + 7, j + 8, k + 8, OPBlocks.BlockAdamTreeLeaves, 0);
		this.setBlock(world, i + 7, j + 8, k + 10, OPBlocks.BlockAdamTreeLeaves, 0);
		this.setBlock(world, i + 7, j + 9, k + 4, OPBlocks.BlockAdamTreeLeaves, 0);
		this.setBlock(world, i + 7, j + 9, k + 5, OPBlocks.BlockAdamTreeWood, 0);
		this.setBlock(world, i + 7, j + 9, k + 6, OPBlocks.BlockAdamTreeWood, 0);
		this.setBlock(world, i + 7, j + 9, k + 7, OPBlocks.BlockAdamTreeWood, 0);
		this.setBlock(world, i + 7, j + 9, k + 8, OPBlocks.BlockAdamTreeWood, 0);
		this.setBlock(world, i + 7, j + 9, k + 9, OPBlocks.BlockAdamTreeLeaves, 0);
		this.setBlock(world, i + 7, j + 9, k + 10, OPBlocks.BlockAdamTreeLeaves, 0);
		this.setBlock(world, i + 7, j + 9, k + 11, OPBlocks.BlockAdamTreeLeaves, 0);
		this.setBlock(world, i + 7, j + 10, k + 2, OPBlocks.BlockAdamTreeLeaves, 0);
		this.setBlock(world, i + 7, j + 10, k + 4, OPBlocks.BlockAdamTreeLeaves, 0);
		this.setBlock(world, i + 7, j + 10, k + 5, OPBlocks.BlockAdamTreeWood, 0);
		this.setBlock(world, i + 7, j + 10, k + 6, OPBlocks.BlockAdamTreeWood, 0);
		this.setBlock(world, i + 7, j + 10, k + 7, OPBlocks.BlockAdamTreeLeaves, 0);
		this.setBlock(world, i + 7, j + 10, k + 8, OPBlocks.BlockAdamTreeWood, 0);
		this.setBlock(world, i + 7, j + 10, k + 9, OPBlocks.BlockAdamTreeLeaves, 0);
		this.setBlock(world, i + 7, j + 10, k + 10, OPBlocks.BlockAdamTreeLeaves, 0);
		this.setBlock(world, i + 7, j + 10, k + 11, OPBlocks.BlockAdamTreeLeaves, 0);
		this.setBlock(world, i + 7, j + 11, k + 1, OPBlocks.BlockAdamTreeLeaves, 0);
		this.setBlock(world, i + 7, j + 11, k + 2, OPBlocks.BlockAdamTreeLeaves, 0);
		this.setBlock(world, i + 7, j + 11, k + 3, OPBlocks.BlockAdamTreeLeaves, 0);
		this.setBlock(world, i + 7, j + 11, k + 4, OPBlocks.BlockAdamTreeLeaves, 0);
		this.setBlock(world, i + 7, j + 11, k + 5, OPBlocks.BlockAdamTreeWood, 0);
		this.setBlock(world, i + 7, j + 11, k + 6, OPBlocks.BlockAdamTreeLeaves, 0);
		this.setBlock(world, i + 7, j + 11, k + 7, OPBlocks.BlockAdamTreeWood, 0);
		this.setBlock(world, i + 7, j + 11, k + 8, OPBlocks.BlockAdamTreeLeaves, 0);
		this.setBlock(world, i + 7, j + 11, k + 9, OPBlocks.BlockAdamTreeLeaves, 0);
		this.setBlock(world, i + 7, j + 11, k + 10, OPBlocks.BlockAdamTreeLeaves, 0);
		this.setBlock(world, i + 7, j + 11, k + 11, OPBlocks.BlockAdamTreeLeaves, 0);
		this.setBlock(world, i + 7, j + 11, k + 12, OPBlocks.BlockAdamTreeLeaves, 0);
		this.setBlock(world, i + 7, j + 12, k + 2, OPBlocks.BlockAdamTreeLeaves, 0);
		this.setBlock(world, i + 7, j + 12, k + 3, OPBlocks.BlockAdamTreeLeaves, 0);
		this.setBlock(world, i + 7, j + 12, k + 4, OPBlocks.BlockAdamTreeWood, 0);
		this.setBlock(world, i + 7, j + 12, k + 5, OPBlocks.BlockAdamTreeLeaves, 0);
		this.setBlock(world, i + 7, j + 12, k + 6, OPBlocks.BlockAdamTreeLeaves, 0);
		this.setBlock(world, i + 7, j + 12, k + 7, OPBlocks.BlockAdamTreeWood, 0);
		this.setBlock(world, i + 7, j + 12, k + 8, OPBlocks.BlockAdamTreeLeaves, 0);
		this.setBlock(world, i + 7, j + 12, k + 9, OPBlocks.BlockAdamTreeWood, 0);
		this.setBlock(world, i + 7, j + 12, k + 10, OPBlocks.BlockAdamTreeWood, 0);
		this.setBlock(world, i + 7, j + 12, k + 11, OPBlocks.BlockAdamTreeLeaves, 0);
		this.setBlock(world, i + 7, j + 12, k + 12, OPBlocks.BlockAdamTreeLeaves, 0);
		this.setBlock(world, i + 7, j + 12, k + 13, OPBlocks.BlockAdamTreeLeaves, 0);
		this.setBlock(world, i + 7, j + 13, k + 2, OPBlocks.BlockAdamTreeLeaves, 0);
		this.setBlock(world, i + 7, j + 13, k + 3, OPBlocks.BlockAdamTreeLeaves, 0);
		this.setBlock(world, i + 7, j + 13, k + 4, OPBlocks.BlockAdamTreeLeaves, 0);
		this.setBlock(world, i + 7, j + 13, k + 5, OPBlocks.BlockAdamTreeWood, 0);
		this.setBlock(world, i + 7, j + 13, k + 6, OPBlocks.BlockAdamTreeLeaves, 0);
		this.setBlock(world, i + 7, j + 13, k + 7, OPBlocks.BlockAdamTreeLeaves, 0);
		this.setBlock(world, i + 7, j + 13, k + 8, OPBlocks.BlockAdamTreeLeaves, 0);
		this.setBlock(world, i + 7, j + 13, k + 9, OPBlocks.BlockAdamTreeWood, 0);
		this.setBlock(world, i + 7, j + 13, k + 10, OPBlocks.BlockAdamTreeLeaves, 0);
		this.setBlock(world, i + 7, j + 13, k + 13, OPBlocks.BlockAdamTreeLeaves, 0);
		this.setBlock(world, i + 7, j + 13, k + 14, OPBlocks.BlockAdamTreeLeaves, 0);
		this.setBlock(world, i + 7, j + 14, k + 2, OPBlocks.BlockAdamTreeLeaves, 0);
		this.setBlock(world, i + 7, j + 14, k + 4, OPBlocks.BlockAdamTreeLeaves, 0);
		this.setBlock(world, i + 7, j + 14, k + 5, OPBlocks.BlockAdamTreeLeaves, 0);
		this.setBlock(world, i + 7, j + 14, k + 6, OPBlocks.BlockAdamTreeWood, 0);
		this.setBlock(world, i + 7, j + 14, k + 7, OPBlocks.BlockAdamTreeLeaves, 0);
		this.setBlock(world, i + 7, j + 14, k + 8, OPBlocks.BlockAdamTreeLeaves, 0);
		this.setBlock(world, i + 7, j + 14, k + 9, OPBlocks.BlockAdamTreeLeaves, 0);
		this.setBlock(world, i + 7, j + 14, k + 10, OPBlocks.BlockAdamTreeLeaves, 0);
		this.setBlock(world, i + 7, j + 14, k + 11, OPBlocks.BlockAdamTreeLeaves, 0);
		this.setBlock(world, i + 7, j + 14, k + 13, OPBlocks.BlockAdamTreeLeaves, 0);
		this.setBlock(world, i + 7, j + 14, k + 14, OPBlocks.BlockAdamTreeLeaves, 0);
		this.setBlock(world, i + 7, j + 15, k + 4, OPBlocks.BlockAdamTreeLeaves, 0);
		this.setBlock(world, i + 7, j + 15, k + 5, OPBlocks.BlockAdamTreeLeaves, 0);
		this.setBlock(world, i + 7, j + 15, k + 6, OPBlocks.BlockAdamTreeLeaves, 0);
		this.setBlock(world, i + 7, j + 15, k + 7, OPBlocks.BlockAdamTreeLeaves, 0);
		this.setBlock(world, i + 7, j + 15, k + 8, OPBlocks.BlockAdamTreeLeaves, 0);
		this.setBlock(world, i + 7, j + 15, k + 9, OPBlocks.BlockAdamTreeLeaves, 0);
		this.setBlock(world, i + 7, j + 16, k + 5, OPBlocks.BlockAdamTreeLeaves, 0);
		this.setBlock(world, i + 7, j + 16, k + 6, OPBlocks.BlockAdamTreeLeaves, 0);
		this.setBlock(world, i + 7, j + 16, k + 7, OPBlocks.BlockAdamTreeLeaves, 0);
		this.setBlock(world, i + 7, j + 16, k + 8, OPBlocks.BlockAdamTreeLeaves, 0);
		this.setBlock(world, i + 7, j + 16, k + 9, OPBlocks.BlockAdamTreeLeaves, 0);
		this.setBlock(world, i + 7, j + 17, k + 6, OPBlocks.BlockAdamTreeLeaves, 0);
		this.setBlock(world, i + 7, j + 17, k + 7, OPBlocks.BlockAdamTreeWood, 0);
		this.setBlock(world, i + 7, j + 17, k + 8, OPBlocks.BlockAdamTreeLeaves, 0);
		this.setBlock(world, i + 7, j + 17, k + 9, OPBlocks.BlockAdamTreeLeaves, 0);
		this.setBlock(world, i + 7, j + 18, k + 5, OPBlocks.BlockAdamTreeLeaves, 0);
		this.setBlock(world, i + 7, j + 18, k + 6, OPBlocks.BlockAdamTreeLeaves, 0);
		this.setBlock(world, i + 7, j + 18, k + 7, OPBlocks.BlockAdamTreeLeaves, 0);
		this.setBlock(world, i + 7, j + 18, k + 8, OPBlocks.BlockAdamTreeLeaves, 0);
		this.setBlock(world, i + 8, j + 0, k + 5, OPBlocks.BlockAdamTreeWood, 0);
		this.setBlock(world, i + 8, j + 0, k + 6, OPBlocks.BlockAdamTreeWood, 0);
		this.setBlock(world, i + 8, j + 0, k + 7, OPBlocks.BlockAdamTreeWood, 0);
		this.setBlock(world, i + 8, j + 1, k + 4, OPBlocks.BlockAdamTreeWood, 0);
		this.setBlock(world, i + 8, j + 1, k + 5, OPBlocks.BlockAdamTreeWood, 0);
		this.setBlock(world, i + 8, j + 1, k + 6, OPBlocks.BlockAdamTreeWood, 0);
		this.setBlock(world, i + 8, j + 1, k + 7, OPBlocks.BlockAdamTreeWood, 0);
		this.setBlock(world, i + 8, j + 2, k + 5, OPBlocks.BlockAdamTreeWood, 0);
		this.setBlock(world, i + 8, j + 2, k + 6, OPBlocks.BlockAdamTreeWood, 0);
		this.setBlock(world, i + 8, j + 2, k + 7, OPBlocks.BlockAdamTreeWood, 0);
		this.setBlock(world, i + 8, j + 3, k + 5, OPBlocks.BlockAdamTreeWood, 0);
		this.setBlock(world, i + 8, j + 3, k + 6, OPBlocks.BlockAdamTreeWood, 0);
		this.setBlock(world, i + 8, j + 3, k + 7, OPBlocks.BlockAdamTreeWood, 0);
		this.setBlock(world, i + 8, j + 4, k + 5, OPBlocks.BlockAdamTreeWood, 0);
		this.setBlock(world, i + 8, j + 4, k + 6, OPBlocks.BlockAdamTreeWood, 0);
		this.setBlock(world, i + 8, j + 4, k + 7, OPBlocks.BlockAdamTreeWood, 0);
		this.setBlock(world, i + 8, j + 5, k + 5, OPBlocks.BlockAdamTreeWood, 0);
		this.setBlock(world, i + 8, j + 5, k + 6, OPBlocks.BlockAdamTreeWood, 0);
		this.setBlock(world, i + 8, j + 5, k + 7, OPBlocks.BlockAdamTreeWood, 0);
		this.setBlock(world, i + 8, j + 6, k + 5, OPBlocks.BlockAdamTreeWood, 0);
		this.setBlock(world, i + 8, j + 6, k + 6, OPBlocks.BlockAdamTreeWood, 0);
		this.setBlock(world, i + 8, j + 6, k + 7, OPBlocks.BlockAdamTreeWood, 0);
		this.setBlock(world, i + 8, j + 7, k + 5, OPBlocks.BlockAdamTreeWood, 0);
		this.setBlock(world, i + 8, j + 7, k + 6, OPBlocks.BlockAdamTreeWood, 0);
		this.setBlock(world, i + 8, j + 7, k + 7, OPBlocks.BlockAdamTreeWood, 0);
		this.setBlock(world, i + 8, j + 7, k + 8, OPBlocks.BlockAdamTreeWood, 0);
		this.setBlock(world, i + 8, j + 8, k + 4, OPBlocks.BlockAdamTreeWood, 0);
		this.setBlock(world, i + 8, j + 8, k + 5, OPBlocks.BlockAdamTreeWood, 0);
		this.setBlock(world, i + 8, j + 8, k + 6, OPBlocks.BlockAdamTreeWood, 0);
		this.setBlock(world, i + 8, j + 8, k + 7, OPBlocks.BlockAdamTreeWood, 0);
		this.setBlock(world, i + 8, j + 8, k + 8, OPBlocks.BlockAdamTreeWood, 0);
		this.setBlock(world, i + 8, j + 8, k + 9, OPBlocks.BlockAdamTreeLeaves, 0);
		this.setBlock(world, i + 8, j + 9, k + 4, OPBlocks.BlockAdamTreeLeaves, 0);
		this.setBlock(world, i + 8, j + 9, k + 5, OPBlocks.BlockAdamTreeWood, 0);
		this.setBlock(world, i + 8, j + 9, k + 6, OPBlocks.BlockAdamTreeWood, 0);
		this.setBlock(world, i + 8, j + 9, k + 7, OPBlocks.BlockAdamTreeWood, 0);
		this.setBlock(world, i + 8, j + 9, k + 8, OPBlocks.BlockAdamTreeWood, 0);
		this.setBlock(world, i + 8, j + 9, k + 9, OPBlocks.BlockAdamTreeLeaves, 0);
		this.setBlock(world, i + 8, j + 9, k + 10, OPBlocks.BlockAdamTreeLeaves, 0);
		this.setBlock(world, i + 8, j + 10, k + 0, OPBlocks.BlockAdamTreeLeaves, 0);
		this.setBlock(world, i + 8, j + 10, k + 3, OPBlocks.BlockAdamTreeLeaves, 0);
		this.setBlock(world, i + 8, j + 10, k + 4, OPBlocks.BlockAdamTreeWood, 0);
		this.setBlock(world, i + 8, j + 10, k + 5, OPBlocks.BlockAdamTreeWood, 0);
		this.setBlock(world, i + 8, j + 10, k + 6, OPBlocks.BlockAdamTreeWood, 0);
		this.setBlock(world, i + 8, j + 10, k + 7, OPBlocks.BlockAdamTreeWood, 0);
		this.setBlock(world, i + 8, j + 10, k + 8, OPBlocks.BlockAdamTreeWood, 0);
		this.setBlock(world, i + 8, j + 10, k + 9, OPBlocks.BlockAdamTreeLeaves, 0);
		this.setBlock(world, i + 8, j + 10, k + 12, OPBlocks.BlockAdamTreeLeaves, 0);
		this.setBlock(world, i + 8, j + 11, k + 2, OPBlocks.BlockAdamTreeLeaves, 0);
		this.setBlock(world, i + 8, j + 11, k + 3, OPBlocks.BlockAdamTreeLeaves, 0);
		this.setBlock(world, i + 8, j + 11, k + 4, OPBlocks.BlockAdamTreeWood, 0);
		this.setBlock(world, i + 8, j + 11, k + 5, OPBlocks.BlockAdamTreeWood, 0);
		this.setBlock(world, i + 8, j + 11, k + 6, OPBlocks.BlockAdamTreeWood, 0);
		this.setBlock(world, i + 8, j + 11, k + 7, OPBlocks.BlockAdamTreeWood, 0);
		this.setBlock(world, i + 8, j + 11, k + 8, OPBlocks.BlockAdamTreeLeaves, 0);
		this.setBlock(world, i + 8, j + 11, k + 9, OPBlocks.BlockAdamTreeLeaves, 0);
		this.setBlock(world, i + 8, j + 11, k + 10, OPBlocks.BlockAdamTreeLeaves, 0);
		this.setBlock(world, i + 8, j + 11, k + 12, OPBlocks.BlockAdamTreeLeaves, 0);
		this.setBlock(world, i + 8, j + 12, k + 2, OPBlocks.BlockAdamTreeLeaves, 0);
		this.setBlock(world, i + 8, j + 12, k + 3, OPBlocks.BlockAdamTreeLeaves, 0);
		this.setBlock(world, i + 8, j + 12, k + 4, OPBlocks.BlockAdamTreeLeaves, 0);
		this.setBlock(world, i + 8, j + 12, k + 5, OPBlocks.BlockAdamTreeWood, 0);
		this.setBlock(world, i + 8, j + 12, k + 6, OPBlocks.BlockAdamTreeWood, 0);
		this.setBlock(world, i + 8, j + 12, k + 7, OPBlocks.BlockAdamTreeWood, 0);
		this.setBlock(world, i + 8, j + 12, k + 8, OPBlocks.BlockAdamTreeWood, 0);
		this.setBlock(world, i + 8, j + 12, k + 9, OPBlocks.BlockAdamTreeLeaves, 0);
		this.setBlock(world, i + 8, j + 12, k + 10, OPBlocks.BlockAdamTreeLeaves, 0);
		this.setBlock(world, i + 8, j + 12, k + 11, OPBlocks.BlockAdamTreeLeaves, 0);
		this.setBlock(world, i + 8, j + 12, k + 12, OPBlocks.BlockAdamTreeLeaves, 0);
		this.setBlock(world, i + 8, j + 12, k + 13, OPBlocks.BlockAdamTreeLeaves, 0);
		this.setBlock(world, i + 8, j + 12, k + 14, OPBlocks.BlockAdamTreeLeaves, 0);
		this.setBlock(world, i + 8, j + 13, k + 3, OPBlocks.BlockAdamTreeLeaves, 0);
		this.setBlock(world, i + 8, j + 13, k + 4, OPBlocks.BlockAdamTreeLeaves, 0);
		this.setBlock(world, i + 8, j + 13, k + 5, OPBlocks.BlockAdamTreeWood, 0);
		this.setBlock(world, i + 8, j + 13, k + 6, OPBlocks.BlockAdamTreeWood, 0);
		this.setBlock(world, i + 8, j + 13, k + 7, OPBlocks.BlockAdamTreeWood, 0);
		this.setBlock(world, i + 8, j + 13, k + 8, OPBlocks.BlockAdamTreeLeaves, 0);
		this.setBlock(world, i + 8, j + 13, k + 9, OPBlocks.BlockAdamTreeLeaves, 0);
		this.setBlock(world, i + 8, j + 13, k + 10, OPBlocks.BlockAdamTreeLeaves, 0);
		this.setBlock(world, i + 8, j + 13, k + 11, OPBlocks.BlockAdamTreeLeaves, 0);
		this.setBlock(world, i + 8, j + 13, k + 13, OPBlocks.BlockAdamTreeLeaves, 0);
		this.setBlock(world, i + 8, j + 14, k + 3, OPBlocks.BlockAdamTreeLeaves, 0);
		this.setBlock(world, i + 8, j + 14, k + 4, OPBlocks.BlockAdamTreeLeaves, 0);
		this.setBlock(world, i + 8, j + 14, k + 5, OPBlocks.BlockAdamTreeLeaves, 0);
		this.setBlock(world, i + 8, j + 14, k + 6, OPBlocks.BlockAdamTreeWood, 0);
		this.setBlock(world, i + 8, j + 14, k + 7, OPBlocks.BlockAdamTreeWood, 0);
		this.setBlock(world, i + 8, j + 14, k + 8, OPBlocks.BlockAdamTreeLeaves, 0);
		this.setBlock(world, i + 8, j + 14, k + 9, OPBlocks.BlockAdamTreeLeaves, 0);
		this.setBlock(world, i + 8, j + 14, k + 10, OPBlocks.BlockAdamTreeWood, 0);
		this.setBlock(world, i + 8, j + 14, k + 11, OPBlocks.BlockAdamTreeLeaves, 0);
		this.setBlock(world, i + 8, j + 14, k + 12, OPBlocks.BlockAdamTreeLeaves, 0);
		this.setBlock(world, i + 8, j + 15, k + 1, OPBlocks.BlockAdamTreeLeaves, 0);
		this.setBlock(world, i + 8, j + 15, k + 4, OPBlocks.BlockAdamTreeLeaves, 0);
		this.setBlock(world, i + 8, j + 15, k + 5, OPBlocks.BlockAdamTreeWood, 0);
		this.setBlock(world, i + 8, j + 15, k + 6, OPBlocks.BlockAdamTreeWood, 0);
		this.setBlock(world, i + 8, j + 15, k + 7, OPBlocks.BlockAdamTreeLeaves, 0);
		this.setBlock(world, i + 8, j + 15, k + 8, OPBlocks.BlockAdamTreeLeaves, 0);
		this.setBlock(world, i + 8, j + 15, k + 9, OPBlocks.BlockAdamTreeLeaves, 0);
		this.setBlock(world, i + 8, j + 15, k + 10, OPBlocks.BlockAdamTreeLeaves, 0);
		this.setBlock(world, i + 8, j + 16, k + 4, OPBlocks.BlockAdamTreeLeaves, 0);
		this.setBlock(world, i + 8, j + 16, k + 5, OPBlocks.BlockAdamTreeLeaves, 0);
		this.setBlock(world, i + 8, j + 16, k + 6, OPBlocks.BlockAdamTreeLeaves, 0);
		this.setBlock(world, i + 8, j + 16, k + 7, OPBlocks.BlockAdamTreeLeaves, 0);
		this.setBlock(world, i + 8, j + 16, k + 8, OPBlocks.BlockAdamTreeLeaves, 0);
		this.setBlock(world, i + 8, j + 16, k + 9, OPBlocks.BlockAdamTreeLeaves, 0);
		this.setBlock(world, i + 8, j + 16, k + 10, OPBlocks.BlockAdamTreeLeaves, 0);
		this.setBlock(world, i + 8, j + 17, k + 5, OPBlocks.BlockAdamTreeLeaves, 0);
		this.setBlock(world, i + 8, j + 17, k + 6, OPBlocks.BlockAdamTreeLeaves, 0);
		this.setBlock(world, i + 8, j + 17, k + 7, OPBlocks.BlockAdamTreeLeaves, 0);
		this.setBlock(world, i + 8, j + 17, k + 8, OPBlocks.BlockAdamTreeLeaves, 0);
		this.setBlock(world, i + 8, j + 18, k + 5, OPBlocks.BlockAdamTreeLeaves, 0);
		this.setBlock(world, i + 9, j + 0, k + 3, OPBlocks.BlockAdamTreeWood, 0);
		this.setBlock(world, i + 9, j + 0, k + 4, OPBlocks.BlockAdamTreeWood, 0);
		this.setBlock(world, i + 9, j + 0, k + 5, OPBlocks.BlockAdamTreeWood, 0);
		this.setBlock(world, i + 9, j + 0, k + 6, OPBlocks.BlockAdamTreeWood, 0);
		this.setBlock(world, i + 9, j + 0, k + 7, OPBlocks.BlockAdamTreeWood, 0);
		this.setBlock(world, i + 9, j + 0, k + 8, OPBlocks.BlockAdamTreeWood, 0);
		this.setBlock(world, i + 9, j + 1, k + 3, OPBlocks.BlockAdamTreeWood, 0);
		this.setBlock(world, i + 9, j + 1, k + 4, OPBlocks.BlockAdamTreeWood, 0);
		this.setBlock(world, i + 9, j + 1, k + 5, OPBlocks.BlockAdamTreeWood, 0);
		this.setBlock(world, i + 9, j + 1, k + 6, OPBlocks.BlockAdamTreeWood, 0);
		this.setBlock(world, i + 9, j + 1, k + 7, OPBlocks.BlockAdamTreeWood, 0);
		this.setBlock(world, i + 9, j + 2, k + 5, OPBlocks.BlockAdamTreeWood, 0);
		this.setBlock(world, i + 9, j + 2, k + 6, OPBlocks.BlockAdamTreeWood, 0);
		this.setBlock(world, i + 9, j + 2, k + 7, OPBlocks.BlockAdamTreeWood, 0);
		this.setBlock(world, i + 9, j + 3, k + 6, OPBlocks.BlockAdamTreeWood, 0);
		this.setBlock(world, i + 9, j + 4, k + 6, OPBlocks.BlockAdamTreeWood, 0);
		this.setBlock(world, i + 9, j + 5, k + 6, OPBlocks.BlockAdamTreeWood, 0);
		this.setBlock(world, i + 9, j + 6, k + 6, OPBlocks.BlockAdamTreeWood, 0);
		this.setBlock(world, i + 9, j + 7, k + 5, OPBlocks.BlockAdamTreeWood, 0);
		this.setBlock(world, i + 9, j + 7, k + 6, OPBlocks.BlockAdamTreeWood, 0);
		this.setBlock(world, i + 9, j + 8, k + 3, OPBlocks.BlockAdamTreeWood, 0);
		this.setBlock(world, i + 9, j + 8, k + 5, OPBlocks.BlockAdamTreeWood, 0);
		this.setBlock(world, i + 9, j + 8, k + 6, OPBlocks.BlockAdamTreeWood, 0);
		this.setBlock(world, i + 9, j + 8, k + 7, OPBlocks.BlockAdamTreeLeaves, 0);
		this.setBlock(world, i + 9, j + 8, k + 9, OPBlocks.BlockAdamTreeLeaves, 0);
		this.setBlock(world, i + 9, j + 8, k + 10, OPBlocks.BlockAdamTreeLeaves, 0);
		this.setBlock(world, i + 9, j + 9, k + 0, OPBlocks.BlockAdamTreeLeaves, 0);
		this.setBlock(world, i + 9, j + 9, k + 2, OPBlocks.BlockAdamTreeWood, 0);
		this.setBlock(world, i + 9, j + 9, k + 3, OPBlocks.BlockAdamTreeWood, 0);
		this.setBlock(world, i + 9, j + 9, k + 4, OPBlocks.BlockAdamTreeLeaves, 0);
		this.setBlock(world, i + 9, j + 9, k + 5, OPBlocks.BlockAdamTreeLeaves, 0);
		this.setBlock(world, i + 9, j + 9, k + 6, OPBlocks.BlockAdamTreeWood, 0);
		this.setBlock(world, i + 9, j + 9, k + 7, OPBlocks.BlockAdamTreeWood, 0);
		this.setBlock(world, i + 9, j + 9, k + 8, OPBlocks.BlockAdamTreeLeaves, 0);
		this.setBlock(world, i + 9, j + 9, k + 9, OPBlocks.BlockAdamTreeLeaves, 0);
		this.setBlock(world, i + 9, j + 9, k + 10, OPBlocks.BlockAdamTreeLeaves, 0);
		this.setBlock(world, i + 9, j + 9, k + 11, OPBlocks.BlockAdamTreeLeaves, 0);
		this.setBlock(world, i + 9, j + 10, k + 0, OPBlocks.BlockAdamTreeLeaves, 0);
		this.setBlock(world, i + 9, j + 10, k + 2, OPBlocks.BlockAdamTreeLeaves, 0);
		this.setBlock(world, i + 9, j + 10, k + 3, OPBlocks.BlockAdamTreeLeaves, 0);
		this.setBlock(world, i + 9, j + 10, k + 4, OPBlocks.BlockAdamTreeWood, 0);
		this.setBlock(world, i + 9, j + 10, k + 5, OPBlocks.BlockAdamTreeWood, 0);
		this.setBlock(world, i + 9, j + 10, k + 6, OPBlocks.BlockAdamTreeWood, 0);
		this.setBlock(world, i + 9, j + 10, k + 7, OPBlocks.BlockAdamTreeWood, 0);
		this.setBlock(world, i + 9, j + 10, k + 8, OPBlocks.BlockAdamTreeWood, 0);
		this.setBlock(world, i + 9, j + 10, k + 9, OPBlocks.BlockAdamTreeLeaves, 0);
		this.setBlock(world, i + 9, j + 10, k + 10, OPBlocks.BlockAdamTreeLeaves, 0);
		this.setBlock(world, i + 9, j + 10, k + 11, OPBlocks.BlockAdamTreeLeaves, 0);
		this.setBlock(world, i + 9, j + 11, k + 3, OPBlocks.BlockAdamTreeLeaves, 0);
		this.setBlock(world, i + 9, j + 11, k + 4, OPBlocks.BlockAdamTreeLeaves, 0);
		this.setBlock(world, i + 9, j + 11, k + 5, OPBlocks.BlockAdamTreeLeaves, 0);
		this.setBlock(world, i + 9, j + 11, k + 6, OPBlocks.BlockAdamTreeWood, 0);
		this.setBlock(world, i + 9, j + 11, k + 7, OPBlocks.BlockAdamTreeWood, 0);
		this.setBlock(world, i + 9, j + 11, k + 8, OPBlocks.BlockAdamTreeWood, 0);
		this.setBlock(world, i + 9, j + 11, k + 9, OPBlocks.BlockAdamTreeLeaves, 0);
		this.setBlock(world, i + 9, j + 11, k + 10, OPBlocks.BlockAdamTreeLeaves, 0);
		this.setBlock(world, i + 9, j + 11, k + 11, OPBlocks.BlockAdamTreeLeaves, 0);
		this.setBlock(world, i + 9, j + 11, k + 12, OPBlocks.BlockAdamTreeLeaves, 0);
		this.setBlock(world, i + 9, j + 12, k + 3, OPBlocks.BlockAdamTreeLeaves, 0);
		this.setBlock(world, i + 9, j + 12, k + 4, OPBlocks.BlockAdamTreeLeaves, 0);
		this.setBlock(world, i + 9, j + 12, k + 5, OPBlocks.BlockAdamTreeLeaves, 0);
		this.setBlock(world, i + 9, j + 12, k + 6, OPBlocks.BlockAdamTreeWood, 0);
		this.setBlock(world, i + 9, j + 12, k + 7, OPBlocks.BlockAdamTreeWood, 0);
		this.setBlock(world, i + 9, j + 12, k + 8, OPBlocks.BlockAdamTreeLeaves, 0);
		this.setBlock(world, i + 9, j + 12, k + 9, OPBlocks.BlockAdamTreeLeaves, 0);
		this.setBlock(world, i + 9, j + 12, k + 10, OPBlocks.BlockAdamTreeLeaves, 0);
		this.setBlock(world, i + 9, j + 12, k + 12, OPBlocks.BlockAdamTreeWood, 0);
		this.setBlock(world, i + 9, j + 12, k + 13, OPBlocks.BlockAdamTreeLeaves, 0);
		this.setBlock(world, i + 9, j + 13, k + 3, OPBlocks.BlockAdamTreeLeaves, 0);
		this.setBlock(world, i + 9, j + 13, k + 4, OPBlocks.BlockAdamTreeLeaves, 0);
		this.setBlock(world, i + 9, j + 13, k + 5, OPBlocks.BlockAdamTreeLeaves, 0);
		this.setBlock(world, i + 9, j + 13, k + 6, OPBlocks.BlockAdamTreeWood, 0);
		this.setBlock(world, i + 9, j + 13, k + 7, OPBlocks.BlockAdamTreeWood, 0);
		this.setBlock(world, i + 9, j + 13, k + 8, OPBlocks.BlockAdamTreeLeaves, 0);
		this.setBlock(world, i + 9, j + 13, k + 9, OPBlocks.BlockAdamTreeLeaves, 0);
		this.setBlock(world, i + 9, j + 13, k + 10, OPBlocks.BlockAdamTreeLeaves, 0);
		this.setBlock(world, i + 9, j + 13, k + 11, OPBlocks.BlockAdamTreeLeaves, 0);
		this.setBlock(world, i + 9, j + 13, k + 12, OPBlocks.BlockAdamTreeLeaves, 0);
		this.setBlock(world, i + 9, j + 14, k + 2, OPBlocks.BlockAdamTreeLeaves, 0);
		this.setBlock(world, i + 9, j + 14, k + 3, OPBlocks.BlockAdamTreeLeaves, 0);
		this.setBlock(world, i + 9, j + 14, k + 4, OPBlocks.BlockAdamTreeWood, 0);
		this.setBlock(world, i + 9, j + 14, k + 5, OPBlocks.BlockAdamTreeLeaves, 0);
		this.setBlock(world, i + 9, j + 14, k + 6, OPBlocks.BlockAdamTreeWood, 0);
		this.setBlock(world, i + 9, j + 14, k + 7, OPBlocks.BlockAdamTreeLeaves, 0);
		this.setBlock(world, i + 9, j + 14, k + 8, OPBlocks.BlockAdamTreeWood, 0);
		this.setBlock(world, i + 9, j + 14, k + 9, OPBlocks.BlockAdamTreeWood, 0);
		this.setBlock(world, i + 9, j + 14, k + 10, OPBlocks.BlockAdamTreeLeaves, 0);
		this.setBlock(world, i + 9, j + 15, k + 3, OPBlocks.BlockAdamTreeLeaves, 0);
		this.setBlock(world, i + 9, j + 15, k + 4, OPBlocks.BlockAdamTreeLeaves, 0);
		this.setBlock(world, i + 9, j + 15, k + 5, OPBlocks.BlockAdamTreeLeaves, 0);
		this.setBlock(world, i + 9, j + 15, k + 6, OPBlocks.BlockAdamTreeWood, 0);
		this.setBlock(world, i + 9, j + 15, k + 7, OPBlocks.BlockAdamTreeLeaves, 0);
		this.setBlock(world, i + 9, j + 15, k + 8, OPBlocks.BlockAdamTreeLeaves, 0);
		this.setBlock(world, i + 9, j + 15, k + 10, OPBlocks.BlockAdamTreeLeaves, 0);
		this.setBlock(world, i + 9, j + 15, k + 11, OPBlocks.BlockAdamTreeLeaves, 0);
		this.setBlock(world, i + 9, j + 16, k + 5, OPBlocks.BlockAdamTreeLeaves, 0);
		this.setBlock(world, i + 9, j + 16, k + 6, OPBlocks.BlockAdamTreeLeaves, 0);
		this.setBlock(world, i + 9, j + 16, k + 7, OPBlocks.BlockAdamTreeLeaves, 0);
		this.setBlock(world, i + 9, j + 16, k + 8, OPBlocks.BlockAdamTreeLeaves, 0);
		this.setBlock(world, i + 9, j + 16, k + 9, OPBlocks.BlockAdamTreeLeaves, 0);
		this.setBlock(world, i + 9, j + 17, k + 5, OPBlocks.BlockAdamTreeLeaves, 0);
		this.setBlock(world, i + 9, j + 17, k + 7, OPBlocks.BlockAdamTreeLeaves, 0);
		this.setBlock(world, i + 9, j + 17, k + 8, OPBlocks.BlockAdamTreeLeaves, 0);
		this.setBlock(world, i + 9, j + 17, k + 9, OPBlocks.BlockAdamTreeLeaves, 0);
		this.setBlock(world, i + 9, j + 18, k + 4, OPBlocks.BlockAdamTreeLeaves, 0);
		this.setBlock(world, i + 9, j + 18, k + 9, OPBlocks.BlockAdamTreeLeaves, 0);
		this.setBlock(world, i + 9, j + 19, k + 9, OPBlocks.BlockAdamTreeLeaves, 0);
		this.setBlock(world, i + 10, j + 0, k + 4, OPBlocks.BlockAdamTreeWood, 0);
		this.setBlock(world, i + 10, j + 0, k + 5, OPBlocks.BlockAdamTreeWood, 0);
		this.setBlock(world, i + 10, j + 0, k + 6, OPBlocks.BlockAdamTreeWood, 0);
		this.setBlock(world, i + 10, j + 0, k + 7, OPBlocks.BlockAdamTreeWood, 0);
		this.setBlock(world, i + 10, j + 7, k + 5, OPBlocks.BlockAdamTreeWood, 0);
		this.setBlock(world, i + 10, j + 8, k + 5, OPBlocks.BlockAdamTreeWood, 0);
		this.setBlock(world, i + 10, j + 8, k + 11, OPBlocks.BlockAdamTreeLeaves, 0);
		this.setBlock(world, i + 10, j + 8, k + 12, OPBlocks.BlockAdamTreeLeaves, 0);
		this.setBlock(world, i + 10, j + 9, k + 5, OPBlocks.BlockAdamTreeLeaves, 0);
		this.setBlock(world, i + 10, j + 9, k + 6, OPBlocks.BlockAdamTreeWood, 0);
		this.setBlock(world, i + 10, j + 9, k + 7, OPBlocks.BlockAdamTreeWood, 0);
		this.setBlock(world, i + 10, j + 9, k + 8, OPBlocks.BlockAdamTreeLeaves, 0);
		this.setBlock(world, i + 10, j + 9, k + 9, OPBlocks.BlockAdamTreeLeaves, 0);
		this.setBlock(world, i + 10, j + 9, k + 10, OPBlocks.BlockAdamTreeLeaves, 0);
		this.setBlock(world, i + 10, j + 9, k + 11, OPBlocks.BlockAdamTreeLeaves, 0);
		this.setBlock(world, i + 10, j + 9, k + 12, OPBlocks.BlockAdamTreeLeaves, 0);
		this.setBlock(world, i + 10, j + 10, k + 1, OPBlocks.BlockAdamTreeLeaves, 0);
		this.setBlock(world, i + 10, j + 10, k + 2, OPBlocks.BlockAdamTreeLeaves, 0);
		this.setBlock(world, i + 10, j + 10, k + 3, OPBlocks.BlockAdamTreeLeaves, 0);
		this.setBlock(world, i + 10, j + 10, k + 4, OPBlocks.BlockAdamTreeLeaves, 0);
		this.setBlock(world, i + 10, j + 10, k + 5, OPBlocks.BlockAdamTreeLeaves, 0);
		this.setBlock(world, i + 10, j + 10, k + 6, OPBlocks.BlockAdamTreeLeaves, 0);
		this.setBlock(world, i + 10, j + 10, k + 7, OPBlocks.BlockAdamTreeWood, 0);
		this.setBlock(world, i + 10, j + 10, k + 8, OPBlocks.BlockAdamTreeWood, 0);
		this.setBlock(world, i + 10, j + 10, k + 9, OPBlocks.BlockAdamTreeLeaves, 0);
		this.setBlock(world, i + 10, j + 10, k + 10, OPBlocks.BlockAdamTreeLeaves, 0);
		this.setBlock(world, i + 10, j + 11, k + 1, OPBlocks.BlockAdamTreeLeaves, 0);
		this.setBlock(world, i + 10, j + 11, k + 2, OPBlocks.BlockAdamTreeLeaves, 0);
		this.setBlock(world, i + 10, j + 11, k + 3, OPBlocks.BlockAdamTreeLeaves, 0);
		this.setBlock(world, i + 10, j + 11, k + 4, OPBlocks.BlockAdamTreeLeaves, 0);
		this.setBlock(world, i + 10, j + 11, k + 5, OPBlocks.BlockAdamTreeLeaves, 0);
		this.setBlock(world, i + 10, j + 11, k + 6, OPBlocks.BlockAdamTreeWood, 0);
		this.setBlock(world, i + 10, j + 11, k + 7, OPBlocks.BlockAdamTreeLeaves, 0);
		this.setBlock(world, i + 10, j + 11, k + 8, OPBlocks.BlockAdamTreeLeaves, 0);
		this.setBlock(world, i + 10, j + 11, k + 9, OPBlocks.BlockAdamTreeLeaves, 0);
		this.setBlock(world, i + 10, j + 11, k + 10, OPBlocks.BlockAdamTreeLeaves, 0);
		this.setBlock(world, i + 10, j + 11, k + 11, OPBlocks.BlockAdamTreeLeaves, 0);
		this.setBlock(world, i + 10, j + 11, k + 12, OPBlocks.BlockAdamTreeLeaves, 0);
		this.setBlock(world, i + 10, j + 12, k + 2, OPBlocks.BlockAdamTreeLeaves, 0);
		this.setBlock(world, i + 10, j + 12, k + 3, OPBlocks.BlockAdamTreeLeaves, 0);
		this.setBlock(world, i + 10, j + 12, k + 4, OPBlocks.BlockAdamTreeLeaves, 0);
		this.setBlock(world, i + 10, j + 12, k + 5, OPBlocks.BlockAdamTreeLeaves, 0);
		this.setBlock(world, i + 10, j + 12, k + 6, OPBlocks.BlockAdamTreeWood, 0);
		this.setBlock(world, i + 10, j + 12, k + 7, OPBlocks.BlockAdamTreeLeaves, 0);
		this.setBlock(world, i + 10, j + 12, k + 8, OPBlocks.BlockAdamTreeWood, 0);
		this.setBlock(world, i + 10, j + 12, k + 9, OPBlocks.BlockAdamTreeLeaves, 0);
		this.setBlock(world, i + 10, j + 12, k + 11, OPBlocks.BlockAdamTreeLeaves, 0);
		this.setBlock(world, i + 10, j + 12, k + 12, OPBlocks.BlockAdamTreeLeaves, 0);
		this.setBlock(world, i + 10, j + 12, k + 13, OPBlocks.BlockAdamTreeLeaves, 0);
		this.setBlock(world, i + 10, j + 13, k + 2, OPBlocks.BlockAdamTreeLeaves, 0);
		this.setBlock(world, i + 10, j + 13, k + 3, OPBlocks.BlockAdamTreeLeaves, 0);
		this.setBlock(world, i + 10, j + 13, k + 4, OPBlocks.BlockAdamTreeLeaves, 0);
		this.setBlock(world, i + 10, j + 13, k + 5, OPBlocks.BlockAdamTreeLeaves, 0);
		this.setBlock(world, i + 10, j + 13, k + 6, OPBlocks.BlockAdamTreeLeaves, 0);
		this.setBlock(world, i + 10, j + 13, k + 7, OPBlocks.BlockAdamTreeLeaves, 0);
		this.setBlock(world, i + 10, j + 13, k + 8, OPBlocks.BlockAdamTreeLeaves, 0);
		this.setBlock(world, i + 10, j + 13, k + 9, OPBlocks.BlockAdamTreeLeaves, 0);
		this.setBlock(world, i + 10, j + 13, k + 11, OPBlocks.BlockAdamTreeLeaves, 0);
		this.setBlock(world, i + 10, j + 14, k + 4, OPBlocks.BlockAdamTreeLeaves, 0);
		this.setBlock(world, i + 10, j + 14, k + 5, OPBlocks.BlockAdamTreeLeaves, 0);
		this.setBlock(world, i + 10, j + 14, k + 6, OPBlocks.BlockAdamTreeLeaves, 0);
		this.setBlock(world, i + 10, j + 14, k + 7, OPBlocks.BlockAdamTreeLeaves, 0);
		this.setBlock(world, i + 10, j + 14, k + 8, OPBlocks.BlockAdamTreeLeaves, 0);
		this.setBlock(world, i + 10, j + 14, k + 9, OPBlocks.BlockAdamTreeLeaves, 0);
		this.setBlock(world, i + 10, j + 14, k + 10, OPBlocks.BlockAdamTreeLeaves, 0);
		this.setBlock(world, i + 10, j + 15, k + 4, OPBlocks.BlockAdamTreeLeaves, 0);
		this.setBlock(world, i + 10, j + 15, k + 6, OPBlocks.BlockAdamTreeLeaves, 0);
		this.setBlock(world, i + 10, j + 15, k + 7, OPBlocks.BlockAdamTreeLeaves, 0);
		this.setBlock(world, i + 10, j + 15, k + 8, OPBlocks.BlockAdamTreeLeaves, 0);
		this.setBlock(world, i + 10, j + 15, k + 9, OPBlocks.BlockAdamTreeLeaves, 0);
		this.setBlock(world, i + 10, j + 15, k + 11, OPBlocks.BlockAdamTreeLeaves, 0);
		this.setBlock(world, i + 10, j + 15, k + 13, OPBlocks.BlockAdamTreeLeaves, 0);
		this.setBlock(world, i + 10, j + 16, k + 4, OPBlocks.BlockAdamTreeLeaves, 0);
		this.setBlock(world, i + 10, j + 16, k + 6, OPBlocks.BlockAdamTreeLeaves, 0);
		this.setBlock(world, i + 10, j + 16, k + 7, OPBlocks.BlockAdamTreeLeaves, 0);
		this.setBlock(world, i + 10, j + 16, k + 8, OPBlocks.BlockAdamTreeWood, 0);
		this.setBlock(world, i + 10, j + 16, k + 9, OPBlocks.BlockAdamTreeLeaves, 0);
		this.setBlock(world, i + 10, j + 16, k + 10, OPBlocks.BlockAdamTreeLeaves, 0);
		this.setBlock(world, i + 10, j + 17, k + 5, OPBlocks.BlockAdamTreeLeaves, 0);
		this.setBlock(world, i + 10, j + 17, k + 6, OPBlocks.BlockAdamTreeLeaves, 0);
		this.setBlock(world, i + 10, j + 17, k + 8, OPBlocks.BlockAdamTreeLeaves, 0);
		this.setBlock(world, i + 10, j + 17, k + 9, OPBlocks.BlockAdamTreeLeaves, 0);
		this.setBlock(world, i + 10, j + 17, k + 10, OPBlocks.BlockAdamTreeLeaves, 0);
		this.setBlock(world, i + 10, j + 17, k + 11, OPBlocks.BlockAdamTreeLeaves, 0);
		this.setBlock(world, i + 10, j + 18, k + 5, OPBlocks.BlockAdamTreeLeaves, 0);
		this.setBlock(world, i + 10, j + 18, k + 11, OPBlocks.BlockAdamTreeLeaves, 0);
		this.setBlock(world, i + 11, j + 9, k + 5, OPBlocks.BlockAdamTreeLeaves, 0);
		this.setBlock(world, i + 11, j + 9, k + 9, OPBlocks.BlockAdamTreeLeaves, 0);
		this.setBlock(world, i + 11, j + 10, k + 5, OPBlocks.BlockAdamTreeLeaves, 0);
		this.setBlock(world, i + 11, j + 10, k + 7, OPBlocks.BlockAdamTreeLeaves, 0);
		this.setBlock(world, i + 11, j + 10, k + 8, OPBlocks.BlockAdamTreeLeaves, 0);
		this.setBlock(world, i + 11, j + 10, k + 9, OPBlocks.BlockAdamTreeWood, 0);
		this.setBlock(world, i + 11, j + 10, k + 10, OPBlocks.BlockAdamTreeLeaves, 0);
		this.setBlock(world, i + 11, j + 11, k + 3, OPBlocks.BlockAdamTreeLeaves, 0);
		this.setBlock(world, i + 11, j + 11, k + 4, OPBlocks.BlockAdamTreeLeaves, 0);
		this.setBlock(world, i + 11, j + 11, k + 5, OPBlocks.BlockAdamTreeLeaves, 0);
		this.setBlock(world, i + 11, j + 11, k + 6, OPBlocks.BlockAdamTreeLeaves, 0);
		this.setBlock(world, i + 11, j + 11, k + 7, OPBlocks.BlockAdamTreeLeaves, 0);
		this.setBlock(world, i + 11, j + 11, k + 8, OPBlocks.BlockAdamTreeLeaves, 0);
		this.setBlock(world, i + 11, j + 11, k + 9, OPBlocks.BlockAdamTreeLeaves, 0);
		this.setBlock(world, i + 11, j + 11, k + 10, OPBlocks.BlockAdamTreeLeaves, 0);
		this.setBlock(world, i + 11, j + 12, k + 5, OPBlocks.BlockAdamTreeLeaves, 0);
		this.setBlock(world, i + 11, j + 12, k + 6, OPBlocks.BlockAdamTreeWood, 0);
		this.setBlock(world, i + 11, j + 12, k + 7, OPBlocks.BlockAdamTreeLeaves, 0);
		this.setBlock(world, i + 11, j + 12, k + 8, OPBlocks.BlockAdamTreeLeaves, 0);
		this.setBlock(world, i + 11, j + 12, k + 9, OPBlocks.BlockAdamTreeLeaves, 0);
		this.setBlock(world, i + 11, j + 13, k + 2, OPBlocks.BlockAdamTreeLeaves, 0);
		this.setBlock(world, i + 11, j + 13, k + 3, OPBlocks.BlockAdamTreeLeaves, 0);
		this.setBlock(world, i + 11, j + 13, k + 4, OPBlocks.BlockAdamTreeLeaves, 0);
		this.setBlock(world, i + 11, j + 13, k + 5, OPBlocks.BlockAdamTreeLeaves, 0);
		this.setBlock(world, i + 11, j + 13, k + 6, OPBlocks.BlockAdamTreeLeaves, 0);
		this.setBlock(world, i + 11, j + 13, k + 7, OPBlocks.BlockAdamTreeLeaves, 0);
		this.setBlock(world, i + 11, j + 13, k + 8, OPBlocks.BlockAdamTreeLeaves, 0);
		this.setBlock(world, i + 11, j + 13, k + 9, OPBlocks.BlockAdamTreeLeaves, 0);
		this.setBlock(world, i + 11, j + 13, k + 10, OPBlocks.BlockAdamTreeLeaves, 0);
		this.setBlock(world, i + 11, j + 14, k + 3, OPBlocks.BlockAdamTreeLeaves, 0);
		this.setBlock(world, i + 11, j + 14, k + 4, OPBlocks.BlockAdamTreeLeaves, 0);
		this.setBlock(world, i + 11, j + 14, k + 5, OPBlocks.BlockAdamTreeLeaves, 0);
		this.setBlock(world, i + 11, j + 14, k + 6, OPBlocks.BlockAdamTreeLeaves, 0);
		this.setBlock(world, i + 11, j + 14, k + 7, OPBlocks.BlockAdamTreeLeaves, 0);
		this.setBlock(world, i + 11, j + 14, k + 8, OPBlocks.BlockAdamTreeLeaves, 0);
		this.setBlock(world, i + 11, j + 14, k + 9, OPBlocks.BlockAdamTreeLeaves, 0);
		this.setBlock(world, i + 11, j + 14, k + 10, OPBlocks.BlockAdamTreeLeaves, 0);
		this.setBlock(world, i + 11, j + 14, k + 12, OPBlocks.BlockAdamTreeLeaves, 0);
		this.setBlock(world, i + 11, j + 14, k + 13, OPBlocks.BlockAdamTreeLeaves, 0);
		this.setBlock(world, i + 11, j + 15, k + 6, OPBlocks.BlockAdamTreeLeaves, 0);
		this.setBlock(world, i + 11, j + 15, k + 7, OPBlocks.BlockAdamTreeLeaves, 0);
		this.setBlock(world, i + 11, j + 15, k + 8, OPBlocks.BlockAdamTreeLeaves, 0);
		this.setBlock(world, i + 11, j + 15, k + 9, OPBlocks.BlockAdamTreeLeaves, 0);
		this.setBlock(world, i + 11, j + 15, k + 11, OPBlocks.BlockAdamTreeLeaves, 0);
		this.setBlock(world, i + 11, j + 15, k + 13, OPBlocks.BlockAdamTreeLeaves, 0);
		this.setBlock(world, i + 11, j + 16, k + 8, OPBlocks.BlockAdamTreeLeaves, 0);
		this.setBlock(world, i + 11, j + 17, k + 4, OPBlocks.BlockAdamTreeLeaves, 0);
		this.setBlock(world, i + 11, j + 17, k + 7, OPBlocks.BlockAdamTreeLeaves, 0);
		this.setBlock(world, i + 11, j + 17, k + 8, OPBlocks.BlockAdamTreeLeaves, 0);
		this.setBlock(world, i + 11, j + 17, k + 9, OPBlocks.BlockAdamTreeLeaves, 0);
		this.setBlock(world, i + 11, j + 17, k + 10, OPBlocks.BlockAdamTreeLeaves, 0);
		this.setBlock(world, i + 11, j + 17, k + 11, OPBlocks.BlockAdamTreeLeaves, 0);
		this.setBlock(world, i + 11, j + 18, k + 8, OPBlocks.BlockAdamTreeLeaves, 0);
		this.setBlock(world, i + 12, j + 9, k + 5, OPBlocks.BlockAdamTreeLeaves, 0);
		this.setBlock(world, i + 12, j + 10, k + 2, OPBlocks.BlockAdamTreeLeaves, 0);
		this.setBlock(world, i + 12, j + 10, k + 7, OPBlocks.BlockAdamTreeLeaves, 0);
		this.setBlock(world, i + 12, j + 10, k + 9, OPBlocks.BlockAdamTreeLeaves, 0);
		this.setBlock(world, i + 12, j + 11, k + 1, OPBlocks.BlockAdamTreeLeaves, 0);
		this.setBlock(world, i + 12, j + 11, k + 2, OPBlocks.BlockAdamTreeLeaves, 0);
		this.setBlock(world, i + 12, j + 11, k + 3, OPBlocks.BlockAdamTreeLeaves, 0);
		this.setBlock(world, i + 12, j + 11, k + 4, OPBlocks.BlockAdamTreeLeaves, 0);
		this.setBlock(world, i + 12, j + 11, k + 8, OPBlocks.BlockAdamTreeLeaves, 0);
		this.setBlock(world, i + 12, j + 11, k + 9, OPBlocks.BlockAdamTreeLeaves, 0);
		this.setBlock(world, i + 12, j + 11, k + 10, OPBlocks.BlockAdamTreeLeaves, 0);
		this.setBlock(world, i + 12, j + 11, k + 11, OPBlocks.BlockAdamTreeLeaves, 0);
		this.setBlock(world, i + 12, j + 12, k + 4, OPBlocks.BlockAdamTreeLeaves, 0);
		this.setBlock(world, i + 12, j + 12, k + 6, OPBlocks.BlockAdamTreeLeaves, 0);
		this.setBlock(world, i + 12, j + 12, k + 7, OPBlocks.BlockAdamTreeLeaves, 0);
		this.setBlock(world, i + 12, j + 12, k + 8, OPBlocks.BlockAdamTreeLeaves, 0);
		this.setBlock(world, i + 12, j + 12, k + 9, OPBlocks.BlockAdamTreeLeaves, 0);
		this.setBlock(world, i + 12, j + 12, k + 10, OPBlocks.BlockAdamTreeLeaves, 0);
		this.setBlock(world, i + 12, j + 12, k + 11, OPBlocks.BlockAdamTreeLeaves, 0);
		this.setBlock(world, i + 12, j + 13, k + 2, OPBlocks.BlockAdamTreeLeaves, 0);
		this.setBlock(world, i + 12, j + 13, k + 3, OPBlocks.BlockAdamTreeLeaves, 0);
		this.setBlock(world, i + 12, j + 13, k + 5, OPBlocks.BlockAdamTreeLeaves, 0);
		this.setBlock(world, i + 12, j + 13, k + 7, OPBlocks.BlockAdamTreeLeaves, 0);
		this.setBlock(world, i + 12, j + 13, k + 8, OPBlocks.BlockAdamTreeLeaves, 0);
		this.setBlock(world, i + 12, j + 13, k + 9, OPBlocks.BlockAdamTreeLeaves, 0);
		this.setBlock(world, i + 12, j + 14, k + 2, OPBlocks.BlockAdamTreeLeaves, 0);
		this.setBlock(world, i + 12, j + 14, k + 3, OPBlocks.BlockAdamTreeLeaves, 0);
		this.setBlock(world, i + 12, j + 14, k + 5, OPBlocks.BlockAdamTreeLeaves, 0);
		this.setBlock(world, i + 12, j + 14, k + 6, OPBlocks.BlockAdamTreeLeaves, 0);
		this.setBlock(world, i + 12, j + 14, k + 8, OPBlocks.BlockAdamTreeLeaves, 0);
		this.setBlock(world, i + 12, j + 14, k + 9, OPBlocks.BlockAdamTreeLeaves, 0);
		this.setBlock(world, i + 12, j + 14, k + 10, OPBlocks.BlockAdamTreeLeaves, 0);
		this.setBlock(world, i + 12, j + 14, k + 11, OPBlocks.BlockAdamTreeLeaves, 0);
		this.setBlock(world, i + 12, j + 14, k + 12, OPBlocks.BlockAdamTreeLeaves, 0);
		this.setBlock(world, i + 12, j + 15, k + 5, OPBlocks.BlockAdamTreeLeaves, 0);
		this.setBlock(world, i + 12, j + 15, k + 6, OPBlocks.BlockAdamTreeLeaves, 0);
		this.setBlock(world, i + 12, j + 15, k + 8, OPBlocks.BlockAdamTreeLeaves, 0);
		this.setBlock(world, i + 12, j + 16, k + 7, OPBlocks.BlockAdamTreeLeaves, 0);
		this.setBlock(world, i + 12, j + 16, k + 8, OPBlocks.BlockAdamTreeLeaves, 0);
		this.setBlock(world, i + 12, j + 16, k + 9, OPBlocks.BlockAdamTreeLeaves, 0);
		this.setBlock(world, i + 12, j + 17, k + 4, OPBlocks.BlockAdamTreeLeaves, 0);
		this.setBlock(world, i + 12, j + 17, k + 5, OPBlocks.BlockAdamTreeLeaves, 0);
		this.setBlock(world, i + 12, j + 17, k + 6, OPBlocks.BlockAdamTreeLeaves, 0);
		this.setBlock(world, i + 12, j + 17, k + 7, OPBlocks.BlockAdamTreeLeaves, 0);
		this.setBlock(world, i + 12, j + 17, k + 8, OPBlocks.BlockAdamTreeLeaves, 0);
		this.setBlock(world, i + 12, j + 18, k + 4, OPBlocks.BlockAdamTreeLeaves, 0);
		this.setBlock(world, i + 12, j + 18, k + 5, OPBlocks.BlockAdamTreeLeaves, 0);
		this.setBlock(world, i + 13, j + 9, k + 8, OPBlocks.BlockAdamTreeLeaves, 0);
		this.setBlock(world, i + 13, j + 9, k + 9, OPBlocks.BlockAdamTreeLeaves, 0);
		this.setBlock(world, i + 13, j + 10, k + 7, OPBlocks.BlockAdamTreeLeaves, 0);
		this.setBlock(world, i + 13, j + 10, k + 8, OPBlocks.BlockAdamTreeLeaves, 0);
		this.setBlock(world, i + 13, j + 10, k + 9, OPBlocks.BlockAdamTreeLeaves, 0);
		this.setBlock(world, i + 13, j + 10, k + 10, OPBlocks.BlockAdamTreeLeaves, 0);
		this.setBlock(world, i + 13, j + 10, k + 11, OPBlocks.BlockAdamTreeLeaves, 0);
		this.setBlock(world, i + 13, j + 10, k + 12, OPBlocks.BlockAdamTreeLeaves, 0);
		this.setBlock(world, i + 13, j + 11, k + 3, OPBlocks.BlockAdamTreeLeaves, 0);
		this.setBlock(world, i + 13, j + 11, k + 8, OPBlocks.BlockAdamTreeLeaves, 0);
		this.setBlock(world, i + 13, j + 11, k + 9, OPBlocks.BlockAdamTreeLeaves, 0);
		this.setBlock(world, i + 13, j + 11, k + 10, OPBlocks.BlockAdamTreeLeaves, 0);
		this.setBlock(world, i + 13, j + 11, k + 11, OPBlocks.BlockAdamTreeLeaves, 0);
		this.setBlock(world, i + 13, j + 11, k + 12, OPBlocks.BlockAdamTreeLeaves, 0);
		this.setBlock(world, i + 13, j + 12, k + 9, OPBlocks.BlockAdamTreeLeaves, 0);
		this.setBlock(world, i + 13, j + 12, k + 10, OPBlocks.BlockAdamTreeLeaves, 0);
		this.setBlock(world, i + 13, j + 12, k + 11, OPBlocks.BlockAdamTreeLeaves, 0);
		this.setBlock(world, i + 13, j + 13, k + 3, OPBlocks.BlockAdamTreeLeaves, 0);
		this.setBlock(world, i + 13, j + 13, k + 4, OPBlocks.BlockAdamTreeLeaves, 0);
		this.setBlock(world, i + 13, j + 13, k + 7, OPBlocks.BlockAdamTreeLeaves, 0);
		this.setBlock(world, i + 13, j + 13, k + 9, OPBlocks.BlockAdamTreeLeaves, 0);
		this.setBlock(world, i + 13, j + 13, k + 10, OPBlocks.BlockAdamTreeLeaves, 0);
		this.setBlock(world, i + 13, j + 13, k + 11, OPBlocks.BlockAdamTreeLeaves, 0);
		this.setBlock(world, i + 13, j + 13, k + 12, OPBlocks.BlockAdamTreeLeaves, 0);
		this.setBlock(world, i + 13, j + 14, k + 4, OPBlocks.BlockAdamTreeLeaves, 0);
		this.setBlock(world, i + 13, j + 14, k + 5, OPBlocks.BlockAdamTreeLeaves, 0);
		this.setBlock(world, i + 13, j + 14, k + 8, OPBlocks.BlockAdamTreeLeaves, 0);
		this.setBlock(world, i + 13, j + 14, k + 9, OPBlocks.BlockAdamTreeLeaves, 0);
		this.setBlock(world, i + 13, j + 14, k + 10, OPBlocks.BlockAdamTreeLeaves, 0);
		this.setBlock(world, i + 13, j + 14, k + 11, OPBlocks.BlockAdamTreeLeaves, 0);
		this.setBlock(world, i + 13, j + 15, k + 8, OPBlocks.BlockAdamTreeLeaves, 0);
		this.setBlock(world, i + 13, j + 15, k + 9, OPBlocks.BlockAdamTreeLeaves, 0);
		this.setBlock(world, i + 14, j + 9, k + 11, OPBlocks.BlockAdamTreeLeaves, 0);
		this.setBlock(world, i + 14, j + 10, k + 9, OPBlocks.BlockAdamTreeLeaves, 0);
		this.setBlock(world, i + 14, j + 10, k + 11, OPBlocks.BlockAdamTreeLeaves, 0);
		this.setBlock(world, i + 14, j + 11, k + 9, OPBlocks.BlockAdamTreeLeaves, 0);
		this.setBlock(world, i + 14, j + 13, k + 7, OPBlocks.BlockAdamTreeLeaves, 0);
		this.setBlock(world, i + 14, j + 13, k + 8, OPBlocks.BlockAdamTreeLeaves, 0);
		this.setBlock(world, i + 14, j + 13, k + 9, OPBlocks.BlockAdamTreeLeaves, 0);
		this.setBlock(world, i + 14, j + 14, k + 8, OPBlocks.BlockAdamTreeLeaves, 0);
		this.setBlock(world, i + 14, j + 14, k + 9, OPBlocks.BlockAdamTreeLeaves, 0);
		this.setBlock(world, i + 14, j + 15, k + 4, OPBlocks.BlockAdamTreeLeaves, 0);
		this.setBlock(world, i + 15, j + 11, k + 9, OPBlocks.BlockAdamTreeLeaves, 0);
		this.setBlock(world, i + 15, j + 14, k + 8, OPBlocks.BlockAdamTreeLeaves, 0);
		this.setBlock(world, i + 15, j + 14, k + 9, OPBlocks.BlockAdamTreeLeaves, 0);
		this.setBlock(world, i + 15, j + 15, k + 4, OPBlocks.BlockAdamTreeLeaves, 0);
	}

	@Override
	public boolean generate(World worldIn, Random rand, BlockPos position) {
		generate(worldIn, rand, position.getX(), position.getY(), position.getZ());
		return true;
	}
}